[2022-05-24 02:52:17,053] {taskinstance.py:1159} INFO - Dependencies all met for <TaskInstance: TRAVELOKA_V1.crawl_data manual__2022-05-24T02:52:08.173537+00:00 [queued]>
[2022-05-24 02:52:17,070] {taskinstance.py:1159} INFO - Dependencies all met for <TaskInstance: TRAVELOKA_V1.crawl_data manual__2022-05-24T02:52:08.173537+00:00 [queued]>
[2022-05-24 02:52:17,070] {taskinstance.py:1356} INFO - 
--------------------------------------------------------------------------------
[2022-05-24 02:52:17,070] {taskinstance.py:1357} INFO - Starting attempt 1 of 1
[2022-05-24 02:52:17,070] {taskinstance.py:1358} INFO - 
--------------------------------------------------------------------------------
[2022-05-24 02:52:17,813] {taskinstance.py:1377} INFO - Executing <Task(BashOperator): crawl_data> on 2022-05-24 02:52:08.173537+00:00
[2022-05-24 02:52:17,823] {standard_task_runner.py:52} INFO - Started process 175 to run task
[2022-05-24 02:52:17,832] {standard_task_runner.py:79} INFO - Running: ['***', 'tasks', 'run', 'TRAVELOKA_V1', 'crawl_data', 'manual__2022-05-24T02:52:08.173537+00:00', '--job-id', '49', '--raw', '--subdir', 'DAGS_FOLDER/test/test.py', '--cfg-path', '/tmp/tmpdqlh2_pt', '--error-file', '/tmp/tmp7uhsbqcm']
[2022-05-24 02:52:17,834] {standard_task_runner.py:80} INFO - Job 49: Subtask crawl_data
[2022-05-24 02:52:19,239] {task_command.py:369} INFO - Running <TaskInstance: TRAVELOKA_V1.crawl_data manual__2022-05-24T02:52:08.173537+00:00 [running]> on host 5a7d71e6bba6
[2022-05-24 02:52:23,410] {taskinstance.py:1571} INFO - Exporting the following env vars:
AIRFLOW_CTX_DAG_OWNER=TRAVELOKA_V1
AIRFLOW_CTX_DAG_ID=TRAVELOKA_V1
AIRFLOW_CTX_TASK_ID=crawl_data
AIRFLOW_CTX_EXECUTION_DATE=2022-05-24T02:52:08.173537+00:00
AIRFLOW_CTX_TRY_NUMBER=1
AIRFLOW_CTX_DAG_RUN_ID=manual__2022-05-24T02:52:08.173537+00:00
[2022-05-24 02:52:23,411] {subprocess.py:62} INFO - Tmp dir root location: 
 /tmp
[2022-05-24 02:52:23,412] {subprocess.py:74} INFO - Running command: ['bash', '-c', 'cd /opt/***/dags/test && scrapy crawl hotel']
[2022-05-24 02:52:23,421] {subprocess.py:85} INFO - Output:
[2022-05-24 02:52:46,518] {subprocess.py:92} INFO - /opt/***/dags/test/hotel/items.py:5: ScrapyDeprecationWarning: scrapy.loader.processors.TakeFirst is deprecated, instantiate itemloaders.processors.TakeFirst instead.
[2022-05-24 02:52:46,518] {subprocess.py:92} INFO -   hotel_name = scrapy.Field(output_processor=TakeFirst())
[2022-05-24 02:52:46,519] {subprocess.py:92} INFO - /opt/***/dags/test/hotel/items.py:6: ScrapyDeprecationWarning: scrapy.loader.processors.TakeFirst is deprecated, instantiate itemloaders.processors.TakeFirst instead.
[2022-05-24 02:52:46,519] {subprocess.py:92} INFO -   hotel_rating = scrapy.Field(output_processor=TakeFirst())
[2022-05-24 02:52:46,519] {subprocess.py:92} INFO - /opt/***/dags/test/hotel/items.py:7: ScrapyDeprecationWarning: scrapy.loader.processors.TakeFirst is deprecated, instantiate itemloaders.processors.TakeFirst instead.
[2022-05-24 02:52:46,519] {subprocess.py:92} INFO -   hotel_address = scrapy.Field(output_processor=TakeFirst())
[2022-05-24 02:52:46,519] {subprocess.py:92} INFO - /opt/***/dags/test/hotel/items.py:8: ScrapyDeprecationWarning: scrapy.loader.processors.TakeFirst is deprecated, instantiate itemloaders.processors.TakeFirst instead.
[2022-05-24 02:52:46,519] {subprocess.py:92} INFO -   hotel_point_review = scrapy.Field(output_processor=TakeFirst())
[2022-05-24 02:52:46,519] {subprocess.py:92} INFO - /opt/***/dags/test/hotel/items.py:9: ScrapyDeprecationWarning: scrapy.loader.processors.TakeFirst is deprecated, instantiate itemloaders.processors.TakeFirst instead.
[2022-05-24 02:52:46,519] {subprocess.py:92} INFO -   hotel_sum_review = scrapy.Field(output_processor=TakeFirst())
[2022-05-24 02:52:46,519] {subprocess.py:92} INFO - /opt/***/dags/test/hotel/items.py:10: ScrapyDeprecationWarning: scrapy.loader.processors.TakeFirst is deprecated, instantiate itemloaders.processors.TakeFirst instead.
[2022-05-24 02:52:46,519] {subprocess.py:92} INFO -   hotel_url = scrapy.Field(output_processor=TakeFirst())
[2022-05-24 02:52:46,519] {subprocess.py:92} INFO - 2022-05-24 02:52:46 [scrapy.utils.log] INFO: Scrapy 2.6.1 started (bot: hotel)
[2022-05-24 02:52:46,524] {subprocess.py:92} INFO - 2022-05-24 02:52:46 [scrapy.utils.log] INFO: Versions: lxml 4.8.0.0, libxml2 2.9.12, cssselect 1.1.0, parsel 1.6.0, w3lib 1.22.0, Twisted 22.4.0, Python 3.7.13 (default, Apr 20 2022, 06:19:04) - [GCC 10.2.1 20210110], pyOpenSSL 21.0.0 (OpenSSL 1.1.1n  15 Mar 2022), cryptography 36.0.2, Platform Linux-5.4.0-110-generic-x86_64-with-debian-11.3
[2022-05-24 02:52:46,530] {subprocess.py:92} INFO - 2022-05-24 02:52:46 [scrapy.crawler] INFO: Overridden settings:
[2022-05-24 02:52:46,530] {subprocess.py:92} INFO - {'BOT_NAME': 'hotel',
[2022-05-24 02:52:46,530] {subprocess.py:92} INFO -  'DOWNLOAD_DELAY': 5,
[2022-05-24 02:52:46,530] {subprocess.py:92} INFO -  'FEED_EXPORT_ENCODING': 'utf-8',
[2022-05-24 02:52:46,531] {subprocess.py:92} INFO -  'NEWSPIDER_MODULE': 'hotel.spiders',
[2022-05-24 02:52:46,531] {subprocess.py:92} INFO -  'SPIDER_MODULES': ['hotel.spiders']}
[2022-05-24 02:52:46,568] {subprocess.py:92} INFO - 2022-05-24 02:52:46 [scrapy.utils.log] DEBUG: Using reactor: twisted.internet.epollreactor.EPollReactor
[2022-05-24 02:52:46,660] {subprocess.py:92} INFO - 2022-05-24 02:52:46 [scrapy.extensions.telnet] INFO: Telnet Password: 002905dc4570473f
[2022-05-24 02:52:46,716] {subprocess.py:92} INFO - 2022-05-24 02:52:46 [scrapy.middleware] INFO: Enabled extensions:
[2022-05-24 02:52:46,716] {subprocess.py:92} INFO - ['scrapy.extensions.corestats.CoreStats',
[2022-05-24 02:52:46,716] {subprocess.py:92} INFO -  'scrapy.extensions.telnet.TelnetConsole',
[2022-05-24 02:52:46,716] {subprocess.py:92} INFO -  'scrapy.extensions.memusage.MemoryUsage',
[2022-05-24 02:52:46,716] {subprocess.py:92} INFO -  'scrapy.extensions.logstats.LogStats']
[2022-05-24 02:52:46,947] {subprocess.py:92} INFO - 2022-05-24 02:52:46 [scrapy.middleware] INFO: Enabled downloader middlewares:
[2022-05-24 02:52:46,947] {subprocess.py:92} INFO - ['scrapy.downloadermiddlewares.httpauth.HttpAuthMiddleware',
[2022-05-24 02:52:46,947] {subprocess.py:92} INFO -  'scrapy.downloadermiddlewares.downloadtimeout.DownloadTimeoutMiddleware',
[2022-05-24 02:52:46,947] {subprocess.py:92} INFO -  'scrapy.downloadermiddlewares.defaultheaders.DefaultHeadersMiddleware',
[2022-05-24 02:52:46,947] {subprocess.py:92} INFO -  'scrapy.downloadermiddlewares.useragent.UserAgentMiddleware',
[2022-05-24 02:52:46,947] {subprocess.py:92} INFO -  'scrapy.downloadermiddlewares.retry.RetryMiddleware',
[2022-05-24 02:52:46,947] {subprocess.py:92} INFO -  'scrapy.downloadermiddlewares.redirect.MetaRefreshMiddleware',
[2022-05-24 02:52:46,947] {subprocess.py:92} INFO -  'scrapy.downloadermiddlewares.httpcompression.HttpCompressionMiddleware',
[2022-05-24 02:52:46,948] {subprocess.py:92} INFO -  'scrapy.downloadermiddlewares.redirect.RedirectMiddleware',
[2022-05-24 02:52:46,948] {subprocess.py:92} INFO -  'scrapy.downloadermiddlewares.cookies.CookiesMiddleware',
[2022-05-24 02:52:46,948] {subprocess.py:92} INFO -  'scrapy.downloadermiddlewares.httpproxy.HttpProxyMiddleware',
[2022-05-24 02:52:46,948] {subprocess.py:92} INFO -  'scrapy.downloadermiddlewares.stats.DownloaderStats']
[2022-05-24 02:52:46,950] {subprocess.py:92} INFO - 2022-05-24 02:52:46 [scrapy.middleware] INFO: Enabled spider middlewares:
[2022-05-24 02:52:46,950] {subprocess.py:92} INFO - ['scrapy.spidermiddlewares.httperror.HttpErrorMiddleware',
[2022-05-24 02:52:46,951] {subprocess.py:92} INFO -  'scrapy.spidermiddlewares.offsite.OffsiteMiddleware',
[2022-05-24 02:52:46,951] {subprocess.py:92} INFO -  'scrapy.spidermiddlewares.referer.RefererMiddleware',
[2022-05-24 02:52:46,951] {subprocess.py:92} INFO -  'scrapy.spidermiddlewares.urllength.UrlLengthMiddleware',
[2022-05-24 02:52:46,951] {subprocess.py:92} INFO -  'scrapy.spidermiddlewares.depth.DepthMiddleware']
[2022-05-24 02:52:47,182] {subprocess.py:92} INFO - 2022-05-24 02:52:47 [root] ERROR: (2003, "Can't connect to MySQL server on '127.20.0.1:3306' (111)")
[2022-05-24 02:52:47,182] {subprocess.py:92} INFO - 2022-05-24 02:52:47 [root] ERROR: (2003, "Can't connect to MySQL server on '127.20.0.1:3306' (111)")
[2022-05-24 02:52:47,182] {subprocess.py:92} INFO - 2022-05-24 02:52:47 [root] ERROR: (2003, "Can't connect to MySQL server on '127.20.0.1:3306' (111)")
[2022-05-24 02:52:47,182] {subprocess.py:92} INFO - 2022-05-24 02:52:47 [root] ERROR: (2003, "Can't connect to MySQL server on '127.20.0.1:3306' (111)")
[2022-05-24 02:52:47,183] {subprocess.py:92} INFO - 2022-05-24 02:52:47 [root] ERROR: (2003, "Can't connect to MySQL server on '127.20.0.1:3306' (111)")
[2022-05-24 02:52:47,183] {subprocess.py:92} INFO - 2022-05-24 02:52:47 [root] ERROR: (2003, "Can't connect to MySQL server on '127.20.0.1:3306' (111)")
[2022-05-24 02:52:47,183] {subprocess.py:92} INFO - 2022-05-24 02:52:47 [root] ERROR: (2003, "Can't connect to MySQL server on '127.20.0.1:3306' (111)")
[2022-05-24 02:52:47,184] {subprocess.py:92} INFO - 2022-05-24 02:52:47 [root] ERROR: (2003, "Can't connect to MySQL server on '127.20.0.1:3306' (111)")
[2022-05-24 02:52:47,184] {subprocess.py:92} INFO - 2022-05-24 02:52:47 [root] ERROR: (2003, "Can't connect to MySQL server on '127.20.0.1:3306' (111)")
[2022-05-24 02:52:47,184] {subprocess.py:92} INFO - 2022-05-24 02:52:47 [root] ERROR: (2003, "Can't connect to MySQL server on '127.20.0.1:3306' (111)")
[2022-05-24 02:52:47,184] {subprocess.py:92} INFO - 2022-05-24 02:52:47 [root] ERROR: (2003, "Can't connect to MySQL server on '127.20.0.1:3306' (111)")
[2022-05-24 02:52:47,185] {subprocess.py:92} INFO - 2022-05-24 02:52:47 [root] ERROR: (2003, "Can't connect to MySQL server on '127.20.0.1:3306' (111)")
[2022-05-24 02:52:47,185] {subprocess.py:92} INFO - 2022-05-24 02:52:47 [root] ERROR: (2003, "Can't connect to MySQL server on '127.20.0.1:3306' (111)")
[2022-05-24 02:52:47,185] {subprocess.py:92} INFO - 2022-05-24 02:52:47 [root] ERROR: (2003, "Can't connect to MySQL server on '127.20.0.1:3306' (111)")
[2022-05-24 02:52:47,186] {subprocess.py:92} INFO - 2022-05-24 02:52:47 [root] ERROR: (2003, "Can't connect to MySQL server on '127.20.0.1:3306' (111)")
[2022-05-24 02:52:47,186] {subprocess.py:92} INFO - 2022-05-24 02:52:47 [root] ERROR: (2003, "Can't connect to MySQL server on '127.20.0.1:3306' (111)")
[2022-05-24 02:52:47,186] {subprocess.py:92} INFO - 2022-05-24 02:52:47 [root] ERROR: (2003, "Can't connect to MySQL server on '127.20.0.1:3306' (111)")
[2022-05-24 02:52:47,186] {subprocess.py:92} INFO - 2022-05-24 02:52:47 [root] ERROR: (2003, "Can't connect to MySQL server on '127.20.0.1:3306' (111)")
[2022-05-24 02:52:47,186] {subprocess.py:92} INFO - 2022-05-24 02:52:47 [root] ERROR: (2003, "Can't connect to MySQL server on '127.20.0.1:3306' (111)")
[2022-05-24 02:52:47,187] {subprocess.py:92} INFO - 2022-05-24 02:52:47 [root] ERROR: (2003, "Can't connect to MySQL server on '127.20.0.1:3306' (111)")
[2022-05-24 02:52:47,187] {subprocess.py:92} INFO - 2022-05-24 02:52:47 [root] ERROR: (2003, "Can't connect to MySQL server on '127.20.0.1:3306' (111)")
[2022-05-24 02:52:47,187] {subprocess.py:92} INFO - 2022-05-24 02:52:47 [root] ERROR: (2003, "Can't connect to MySQL server on '127.20.0.1:3306' (111)")
[2022-05-24 02:52:47,187] {subprocess.py:92} INFO - 2022-05-24 02:52:47 [root] ERROR: (2003, "Can't connect to MySQL server on '127.20.0.1:3306' (111)")
[2022-05-24 02:52:47,188] {subprocess.py:92} INFO - 2022-05-24 02:52:47 [root] ERROR: (2003, "Can't connect to MySQL server on '127.20.0.1:3306' (111)")
[2022-05-24 02:52:47,188] {subprocess.py:92} INFO - 2022-05-24 02:52:47 [root] ERROR: (2003, "Can't connect to MySQL server on '127.20.0.1:3306' (111)")
[2022-05-24 02:52:47,188] {subprocess.py:92} INFO - 2022-05-24 02:52:47 [root] ERROR: (2003, "Can't connect to MySQL server on '127.20.0.1:3306' (111)")
[2022-05-24 02:52:47,188] {subprocess.py:92} INFO - 2022-05-24 02:52:47 [root] ERROR: (2003, "Can't connect to MySQL server on '127.20.0.1:3306' (111)")
[2022-05-24 02:52:47,188] {subprocess.py:92} INFO - 2022-05-24 02:52:47 [root] ERROR: (2003, "Can't connect to MySQL server on '127.20.0.1:3306' (111)")
[2022-05-24 02:52:47,189] {subprocess.py:92} INFO - 2022-05-24 02:52:47 [root] ERROR: (2003, "Can't connect to MySQL server on '127.20.0.1:3306' (111)")
[2022-05-24 02:52:47,189] {subprocess.py:92} INFO - 2022-05-24 02:52:47 [root] ERROR: (2003, "Can't connect to MySQL server on '127.20.0.1:3306' (111)")
[2022-05-24 02:52:47,189] {subprocess.py:92} INFO - 2022-05-24 02:52:47 [root] ERROR: (2003, "Can't connect to MySQL server on '127.20.0.1:3306' (111)")
[2022-05-24 02:52:47,189] {subprocess.py:92} INFO - 2022-05-24 02:52:47 [root] ERROR: (2003, "Can't connect to MySQL server on '127.20.0.1:3306' (111)")
[2022-05-24 02:52:47,189] {subprocess.py:92} INFO - 2022-05-24 02:52:47 [root] ERROR: (2003, "Can't connect to MySQL server on '127.20.0.1:3306' (111)")
[2022-05-24 02:52:47,190] {subprocess.py:92} INFO - 2022-05-24 02:52:47 [root] ERROR: (2003, "Can't connect to MySQL server on '127.20.0.1:3306' (111)")
[2022-05-24 02:52:47,190] {subprocess.py:92} INFO - 2022-05-24 02:52:47 [root] ERROR: (2003, "Can't connect to MySQL server on '127.20.0.1:3306' (111)")
[2022-05-24 02:52:47,190] {subprocess.py:92} INFO - 2022-05-24 02:52:47 [root] ERROR: (2003, "Can't connect to MySQL server on '127.20.0.1:3306' (111)")
[2022-05-24 02:52:47,190] {subprocess.py:92} INFO - 2022-05-24 02:52:47 [root] ERROR: (2003, "Can't connect to MySQL server on '127.20.0.1:3306' (111)")
[2022-05-24 02:52:47,191] {subprocess.py:92} INFO - 2022-05-24 02:52:47 [root] ERROR: (2003, "Can't connect to MySQL server on '127.20.0.1:3306' (111)")
[2022-05-24 02:52:47,191] {subprocess.py:92} INFO - 2022-05-24 02:52:47 [root] ERROR: (2003, "Can't connect to MySQL server on '127.20.0.1:3306' (111)")
[2022-05-24 02:52:47,191] {subprocess.py:92} INFO - 2022-05-24 02:52:47 [root] ERROR: (2003, "Can't connect to MySQL server on '127.20.0.1:3306' (111)")
[2022-05-24 02:52:47,191] {subprocess.py:92} INFO - 2022-05-24 02:52:47 [root] ERROR: (2003, "Can't connect to MySQL server on '127.20.0.1:3306' (111)")
[2022-05-24 02:52:47,191] {subprocess.py:92} INFO - 2022-05-24 02:52:47 [root] ERROR: (2003, "Can't connect to MySQL server on '127.20.0.1:3306' (111)")
[2022-05-24 02:52:47,192] {subprocess.py:92} INFO - 2022-05-24 02:52:47 [root] ERROR: (2003, "Can't connect to MySQL server on '127.20.0.1:3306' (111)")
[2022-05-24 02:52:47,192] {subprocess.py:92} INFO - 2022-05-24 02:52:47 [root] ERROR: (2003, "Can't connect to MySQL server on '127.20.0.1:3306' (111)")
[2022-05-24 02:52:47,192] {subprocess.py:92} INFO - 2022-05-24 02:52:47 [root] ERROR: (2003, "Can't connect to MySQL server on '127.20.0.1:3306' (111)")
[2022-05-24 02:52:47,192] {subprocess.py:92} INFO - 2022-05-24 02:52:47 [root] ERROR: (2003, "Can't connect to MySQL server on '127.20.0.1:3306' (111)")
[2022-05-24 02:52:47,192] {subprocess.py:92} INFO - 2022-05-24 02:52:47 [root] ERROR: (2003, "Can't connect to MySQL server on '127.20.0.1:3306' (111)")
[2022-05-24 02:52:47,193] {subprocess.py:92} INFO - 2022-05-24 02:52:47 [root] ERROR: (2003, "Can't connect to MySQL server on '127.20.0.1:3306' (111)")
[2022-05-24 02:52:47,193] {subprocess.py:92} INFO - 2022-05-24 02:52:47 [root] ERROR: (2003, "Can't connect to MySQL server on '127.20.0.1:3306' (111)")
[2022-05-24 02:52:47,193] {subprocess.py:92} INFO - 2022-05-24 02:52:47 [root] ERROR: (2003, "Can't connect to MySQL server on '127.20.0.1:3306' (111)")
[2022-05-24 02:52:47,193] {subprocess.py:92} INFO - 2022-05-24 02:52:47 [scrapy.middleware] INFO: Enabled item pipelines:
[2022-05-24 02:52:47,193] {subprocess.py:92} INFO - ['hotel.pipelines.QuotesSpiderPipeline']
[2022-05-24 02:52:47,193] {subprocess.py:92} INFO - 2022-05-24 02:52:47 [scrapy.core.engine] INFO: Spider opened
[2022-05-24 02:52:47,340] {subprocess.py:92} INFO - 2022-05-24 02:52:47 [scrapy.extensions.logstats] INFO: Crawled 0 pages (at 0 pages/min), scraped 0 items (at 0 items/min)
[2022-05-24 02:52:47,341] {subprocess.py:92} INFO - 2022-05-24 02:52:47 [scrapy.extensions.telnet] INFO: Telnet console listening on 127.0.0.1:6023
[2022-05-24 02:52:48,414] {subprocess.py:92} INFO - 2022-05-24 02:52:48 [scrapy.downloadermiddlewares.redirect] DEBUG: Redirecting (308) to <GET https://www.traveloka.com/vi-vn/hotel> from <GET https://www.traveloka.com/vi-vn/hotel/>
[2022-05-24 02:52:53,116] {subprocess.py:92} INFO - 2022-05-24 02:52:53 [scrapy.core.engine] DEBUG: Crawled (200) <GET https://www.traveloka.com/vi-vn/hotel> (referer: None)
[2022-05-24 02:53:00,062] {subprocess.py:92} INFO - 2022-05-24 02:53:00 [tldextract.cache] WARNING: unable to cache publicsuffix.org-tlds.{'urls': ('https://publicsuffix.org/list/public_suffix_list.dat', 'https://raw.githubusercontent.com/publicsuffix/list/master/public_suffix_list.dat'), 'fallback_to_snapshot': True} in /home/***/.cache/python-tldextract/3.7.13.final__local__ecb11d__tldextract-3.3.0/publicsuffix.org-tlds/de84b5ca2167d4c83e38fb162f2e8738.tldextract.json. This could refresh the Public Suffix List over HTTP every app startup. Construct your `TLDExtract` with a writable `cache_dir` or set `cache_dir=None` to silence this warning. [Errno 13] Permission denied: '/home/***/.cache/python-tldextract'
[2022-05-24 02:53:00,074] {subprocess.py:92} INFO - 2022-05-24 02:53:00 [urllib3.connectionpool] DEBUG: Starting new HTTPS connection (1): publicsuffix.org:443
[2022-05-24 02:53:01,857] {subprocess.py:92} INFO - 2022-05-24 02:53:01 [urllib3.connectionpool] DEBUG: https://publicsuffix.org:443 "GET /list/public_suffix_list.dat HTTP/1.1" 200 None
[2022-05-24 02:53:01,918] {subprocess.py:92} INFO - 2022-05-24 02:53:01 [scrapy.downloadermiddlewares.redirect] DEBUG: Redirecting (301) to <GET https://www.traveloka.com/vi-vn/hotel/vietnam/region/da-nang-10010083> from <GET https://www.traveloka.com/vi-vn/hotel/vietnam/region/da-nang-city-10010083>
[2022-05-24 02:53:06,406] {subprocess.py:92} INFO - 2022-05-24 02:53:06 [scrapy.core.engine] DEBUG: Crawled (200) <GET https://www.traveloka.com/vi-vn/hotel/vietnam/city/ha-long-city-30010278> (referer: https://www.traveloka.com/vi-vn/hotel)
[2022-05-24 02:53:11,612] {subprocess.py:92} INFO - 2022-05-24 02:53:11 [scrapy.core.engine] DEBUG: Crawled (200) <GET https://www.traveloka.com/vi-vn/hotel/vietnam/region/ho-chi-minh-city-10009794> (referer: https://www.traveloka.com/vi-vn/hotel)
[2022-05-24 02:53:11,770] {subprocess.py:92} INFO - 2022-05-24 02:53:11 [scrapy.dupefilters] DEBUG: Filtered duplicate request: <GET https://www.traveloka.com/vi-vn/hotel/vietnam/region/da-nang-10010083> - no more duplicates will be shown (see DUPEFILTER_DEBUG to show all duplicates)
[2022-05-24 02:53:18,074] {subprocess.py:92} INFO - 2022-05-24 02:53:18 [scrapy.core.engine] DEBUG: Crawled (200) <GET https://www.traveloka.com/vi-vn/hotel/vietnam/city/hue-city-10010311> (referer: https://www.traveloka.com/vi-vn/hotel)
[2022-05-24 02:53:24,249] {subprocess.py:92} INFO - 2022-05-24 02:53:24 [scrapy.core.engine] DEBUG: Crawled (200) <GET https://www.traveloka.com/vi-vn/hotel/vietnam/city/quy-nhon-city-10009975> (referer: https://www.traveloka.com/vi-vn/hotel)
[2022-05-24 02:53:30,665] {subprocess.py:92} INFO - 2022-05-24 02:53:30 [scrapy.core.engine] DEBUG: Crawled (200) <GET https://www.traveloka.com/vi-vn/hotel/vietnam/city/phan-thiet-10010286> (referer: https://www.traveloka.com/vi-vn/hotel)
[2022-05-24 02:53:36,503] {subprocess.py:92} INFO - 2022-05-24 02:53:36 [scrapy.downloadermiddlewares.redirect] DEBUG: Redirecting (301) to <GET https://www.traveloka.com/vi-vn/hotel/vietnam/city/hoi-an-10010308> from <GET https://www.traveloka.com/vi-vn/hotel/vietnam/city/hoi-an-ancient-town-10010308>
[2022-05-24 02:53:43,800] {subprocess.py:92} INFO - 2022-05-24 02:53:43 [scrapy.downloadermiddlewares.redirect] DEBUG: Redirecting (301) to <GET https://www.traveloka.com/vi-vn/hotel/vietnam/city/da-lat-10010169> from <GET https://www.traveloka.com/vi-vn/hotel/vietnam/city/da-lat-city-10010169>
[2022-05-24 02:53:47,341] {subprocess.py:92} INFO - 2022-05-24 02:53:47 [scrapy.extensions.logstats] INFO: Crawled 6 pages (at 6 pages/min), scraped 0 items (at 0 items/min)
[2022-05-24 02:53:48,685] {subprocess.py:92} INFO - 2022-05-24 02:53:48 [scrapy.downloadermiddlewares.redirect] DEBUG: Redirecting (301) to <GET https://www.traveloka.com/vi-vn/hotel/vietnam/region/hanoi-10009843> from <GET https://www.traveloka.com/vi-vn/hotel/vietnam/region/ha-noi-city-10009843>
[2022-05-24 02:53:55,394] {subprocess.py:92} INFO - 2022-05-24 02:53:55 [scrapy.core.engine] DEBUG: Crawled (200) <GET https://www.traveloka.com/vi-vn/hotel/vietnam/city/vung-tau-city-10009888> (referer: https://www.traveloka.com/vi-vn/hotel)
[2022-05-24 02:54:02,249] {subprocess.py:92} INFO - 2022-05-24 02:54:02 [scrapy.core.engine] DEBUG: Crawled (200) <GET https://www.traveloka.com/vi-vn/hotel/vietnam/city/phu-quoc-10011570> (referer: https://www.traveloka.com/vi-vn/hotel)
[2022-05-24 02:54:09,358] {subprocess.py:92} INFO - 2022-05-24 02:54:09 [scrapy.core.engine] DEBUG: Crawled (200) <GET https://www.traveloka.com/vi-vn/hotel/vietnam/city/nha-trang-10010498> (referer: https://www.traveloka.com/vi-vn/hotel)
[2022-05-24 02:54:15,588] {subprocess.py:92} INFO - 2022-05-24 02:54:15 [scrapy.core.engine] DEBUG: Crawled (200) <GET https://www.traveloka.com/vi-vn/hotel/vietnam/region/da-nang-10010083> (referer: https://www.traveloka.com/vi-vn/hotel)
[2022-05-24 02:54:23,255] {subprocess.py:92} INFO - 2022-05-24 02:54:23 [scrapy.core.engine] DEBUG: Crawled (200) <GET https://www.traveloka.com/vi-vn/hotel/vietnam/city/ha-long-city-30010278/5-star-hotels-in-ha-long-city> (referer: https://www.traveloka.com/vi-vn/hotel/vietnam/city/ha-long-city-30010278)
[2022-05-24 02:54:23,438] {subprocess.py:92} INFO - 2022-05-24 02:54:23 [scrapy.core.scraper] DEBUG: Scraped from <200 https://www.traveloka.com/vi-vn/hotel/vietnam/city/ha-long-city-30010278/5-star-hotels-in-ha-long-city>
[2022-05-24 02:54:23,438] {subprocess.py:92} INFO - {'hotel_address': 'Số 12 Đường Hạ Long, Phường Bãi Cháy, phường Bãi Cháy, '
[2022-05-24 02:54:23,438] {subprocess.py:92} INFO -                   'Thành phố Hạ Long, Tỉnh Quảng Ninh, Việt Nam, 200000',
[2022-05-24 02:54:23,439] {subprocess.py:92} INFO -  'hotel_name': 'Wyndham Legend Halong Hotel',
[2022-05-24 02:54:23,439] {subprocess.py:92} INFO -  'hotel_point_review': '8.7',
[2022-05-24 02:54:23,439] {subprocess.py:92} INFO -  'hotel_rating': '5',
[2022-05-24 02:54:23,439] {subprocess.py:92} INFO -  'hotel_sum_review': '159',
[2022-05-24 02:54:23,439] {subprocess.py:92} INFO -  'hotel_url': 'https://www.traveloka.com/vi-vn/hotel/vietnam/wyndham-legend-halong-hotel-1000000620395'}
[2022-05-24 02:54:23,440] {subprocess.py:92} INFO - 2022-05-24 02:54:23 [scrapy.core.scraper] DEBUG: Scraped from <200 https://www.traveloka.com/vi-vn/hotel/vietnam/city/ha-long-city-30010278/5-star-hotels-in-ha-long-city>
[2022-05-24 02:54:23,440] {subprocess.py:92} INFO - {'hotel_address': 'Tổ 1, Khu 2, phường Bãi Cháy, phường Bãi Cháy, Thành phố Hạ '
[2022-05-24 02:54:23,440] {subprocess.py:92} INFO -                   'Long, Tỉnh Quảng Ninh, Việt Nam, 200000',
[2022-05-24 02:54:23,440] {subprocess.py:92} INFO -  'hotel_name': 'Khách sạn Mường Thanh Luxury Quảng Ninh',
[2022-05-24 02:54:23,440] {subprocess.py:92} INFO -  'hotel_point_review': '8.6',
[2022-05-24 02:54:23,440] {subprocess.py:92} INFO -  'hotel_rating': '5',
[2022-05-24 02:54:23,440] {subprocess.py:92} INFO -  'hotel_sum_review': '245',
[2022-05-24 02:54:23,440] {subprocess.py:92} INFO -  'hotel_url': 'https://www.traveloka.com/vi-vn/hotel/vietnam/muong-thanh-luxury-quang-ninh-hotel-1000000456656'}
[2022-05-24 02:54:23,441] {subprocess.py:92} INFO - 2022-05-24 02:54:23 [scrapy.core.scraper] DEBUG: Scraped from <200 https://www.traveloka.com/vi-vn/hotel/vietnam/city/ha-long-city-30010278/5-star-hotels-in-ha-long-city>
[2022-05-24 02:54:23,441] {subprocess.py:92} INFO - {'hotel_address': 'Đảo Rều, Bãi Cháy , Thành phố Hạ Long, Tỉnh Quảng Ninh, '
[2022-05-24 02:54:23,441] {subprocess.py:92} INFO -                   'Việt Nam, 20000',
[2022-05-24 02:54:23,442] {subprocess.py:92} INFO -  'hotel_name': 'Vinpearl Resort & Spa Ha Long',
[2022-05-24 02:54:23,442] {subprocess.py:92} INFO -  'hotel_point_review': '8.7',
[2022-05-24 02:54:23,442] {subprocess.py:92} INFO -  'hotel_rating': '5',
[2022-05-24 02:54:23,442] {subprocess.py:92} INFO -  'hotel_sum_review': '56',
[2022-05-24 02:54:23,442] {subprocess.py:92} INFO -  'hotel_url': 'https://www.traveloka.com/vi-vn/hotel/vietnam/vinpearl-resort--spa-ha-long-3000020000164'}
[2022-05-24 02:54:23,472] {subprocess.py:92} INFO - 2022-05-24 02:54:23 [scrapy.core.scraper] DEBUG: Scraped from <200 https://www.traveloka.com/vi-vn/hotel/vietnam/city/ha-long-city-30010278/5-star-hotels-in-ha-long-city>
[2022-05-24 02:54:23,472] {subprocess.py:92} INFO - {'hotel_address': 'FLC Hạ Long, Nguyễn Văn Cừ, phường Hà Trung, Thành phố Hạ '
[2022-05-24 02:54:23,472] {subprocess.py:92} INFO -                   'Long, Tỉnh Quảng Ninh, Việt Nam, 200000',
[2022-05-24 02:54:23,472] {subprocess.py:92} INFO -  'hotel_name': 'FLC Halong Bay Golf Club & Luxury Resort',
[2022-05-24 02:54:23,473] {subprocess.py:92} INFO -  'hotel_point_review': '8.5',
[2022-05-24 02:54:23,473] {subprocess.py:92} INFO -  'hotel_rating': '5',
[2022-05-24 02:54:23,473] {subprocess.py:92} INFO -  'hotel_sum_review': '79',
[2022-05-24 02:54:23,473] {subprocess.py:92} INFO -  'hotel_url': 'https://www.traveloka.com/vi-vn/hotel/vietnam/flc-halong-bay-golf-club--luxury-resort-3000020019359'}
[2022-05-24 02:54:23,473] {subprocess.py:92} INFO - 2022-05-24 02:54:23 [root] ERROR: [Failure instance: Traceback: <class 'MySQLdb._exceptions.OperationalError'>: (2003, "Can't connect to MySQL server on '127.20.0.1:3306' (111)")
[2022-05-24 02:54:23,473] {subprocess.py:92} INFO - /usr/local/lib/python3.7/threading.py:926:_bootstrap_inner
[2022-05-24 02:54:23,473] {subprocess.py:92} INFO - /usr/local/lib/python3.7/threading.py:870:run
[2022-05-24 02:54:23,473] {subprocess.py:92} INFO - /home/***/.local/lib/python3.7/site-packages/twisted/_threads/_threadworker.py:47:work
[2022-05-24 02:54:23,473] {subprocess.py:92} INFO - /home/***/.local/lib/python3.7/site-packages/twisted/_threads/_team.py:182:doWork
[2022-05-24 02:54:23,473] {subprocess.py:92} INFO - --- <exception caught here> ---
[2022-05-24 02:54:23,473] {subprocess.py:92} INFO - /home/***/.local/lib/python3.7/site-packages/twisted/python/threadpool.py:244:inContext
[2022-05-24 02:54:23,474] {subprocess.py:92} INFO - /home/***/.local/lib/python3.7/site-packages/twisted/python/threadpool.py:261:<lambda>
[2022-05-24 02:54:23,474] {subprocess.py:92} INFO - /home/***/.local/lib/python3.7/site-packages/twisted/python/context.py:117:callWithContext
[2022-05-24 02:54:23,474] {subprocess.py:92} INFO - /home/***/.local/lib/python3.7/site-packages/twisted/python/context.py:82:callWithContext
[2022-05-24 02:54:23,474] {subprocess.py:92} INFO - /home/***/.local/lib/python3.7/site-packages/twisted/enterprise/adbapi.py:440:_runInteraction
[2022-05-24 02:54:23,474] {subprocess.py:92} INFO - /home/***/.local/lib/python3.7/site-packages/twisted/enterprise/adbapi.py:34:__init__
[2022-05-24 02:54:23,474] {subprocess.py:92} INFO - /home/***/.local/lib/python3.7/site-packages/twisted/enterprise/adbapi.py:71:reconnect
[2022-05-24 02:54:23,474] {subprocess.py:92} INFO - /home/***/.local/lib/python3.7/site-packages/twisted/enterprise/adbapi.py:410:connect
[2022-05-24 02:54:23,474] {subprocess.py:92} INFO - /home/***/.local/lib/python3.7/site-packages/MySQLdb/__init__.py:123:Connect
[2022-05-24 02:54:23,474] {subprocess.py:92} INFO - /home/***/.local/lib/python3.7/site-packages/MySQLdb/connections.py:185:__init__
[2022-05-24 02:54:23,474] {subprocess.py:92} INFO - ]
[2022-05-24 02:54:23,474] {subprocess.py:92} INFO - 2022-05-24 02:54:23 [root] ERROR: [Failure instance: Traceback: <class 'MySQLdb._exceptions.OperationalError'>: (2003, "Can't connect to MySQL server on '127.20.0.1:3306' (111)")
[2022-05-24 02:54:23,474] {subprocess.py:92} INFO - /usr/local/lib/python3.7/threading.py:926:_bootstrap_inner
[2022-05-24 02:54:23,475] {subprocess.py:92} INFO - /usr/local/lib/python3.7/threading.py:870:run
[2022-05-24 02:54:23,475] {subprocess.py:92} INFO - /home/***/.local/lib/python3.7/site-packages/twisted/_threads/_threadworker.py:47:work
[2022-05-24 02:54:23,475] {subprocess.py:92} INFO - /home/***/.local/lib/python3.7/site-packages/twisted/_threads/_team.py:182:doWork
[2022-05-24 02:54:23,475] {subprocess.py:92} INFO - --- <exception caught here> ---
[2022-05-24 02:54:23,475] {subprocess.py:92} INFO - /home/***/.local/lib/python3.7/site-packages/twisted/python/threadpool.py:244:inContext
[2022-05-24 02:54:23,475] {subprocess.py:92} INFO - /home/***/.local/lib/python3.7/site-packages/twisted/python/threadpool.py:261:<lambda>
[2022-05-24 02:54:23,475] {subprocess.py:92} INFO - /home/***/.local/lib/python3.7/site-packages/twisted/python/context.py:117:callWithContext
[2022-05-24 02:54:23,475] {subprocess.py:92} INFO - /home/***/.local/lib/python3.7/site-packages/twisted/python/context.py:82:callWithContext
[2022-05-24 02:54:23,475] {subprocess.py:92} INFO - /home/***/.local/lib/python3.7/site-packages/twisted/enterprise/adbapi.py:440:_runInteraction
[2022-05-24 02:54:23,475] {subprocess.py:92} INFO - /home/***/.local/lib/python3.7/site-packages/twisted/enterprise/adbapi.py:34:__init__
[2022-05-24 02:54:23,475] {subprocess.py:92} INFO - /home/***/.local/lib/python3.7/site-packages/twisted/enterprise/adbapi.py:71:reconnect
[2022-05-24 02:54:23,475] {subprocess.py:92} INFO - /home/***/.local/lib/python3.7/site-packages/twisted/enterprise/adbapi.py:410:connect
[2022-05-24 02:54:23,475] {subprocess.py:92} INFO - /home/***/.local/lib/python3.7/site-packages/MySQLdb/__init__.py:123:Connect
[2022-05-24 02:54:23,476] {subprocess.py:92} INFO - /home/***/.local/lib/python3.7/site-packages/MySQLdb/connections.py:185:__init__
[2022-05-24 02:54:23,476] {subprocess.py:92} INFO - ]
[2022-05-24 02:54:23,478] {subprocess.py:92} INFO - 2022-05-24 02:54:23 [scrapy.core.scraper] DEBUG: Scraped from <200 https://www.traveloka.com/vi-vn/hotel/vietnam/city/ha-long-city-30010278/5-star-hotels-in-ha-long-city>
[2022-05-24 02:54:23,478] {subprocess.py:92} INFO - {'hotel_address': 'Dock Number 16, Tuan Chau Island, , phường Bãi Cháy, Thành '
[2022-05-24 02:54:23,478] {subprocess.py:92} INFO -                   'phố Hạ Long, Tỉnh Quảng Ninh, Việt Nam, 200000',
[2022-05-24 02:54:23,478] {subprocess.py:92} INFO -  'hotel_name': 'Du thuyền Alisa',
[2022-05-24 02:54:23,478] {subprocess.py:92} INFO -  'hotel_point_review': '8.7',
[2022-05-24 02:54:23,478] {subprocess.py:92} INFO -  'hotel_rating': '5',
[2022-05-24 02:54:23,478] {subprocess.py:92} INFO -  'hotel_sum_review': '7',
[2022-05-24 02:54:23,478] {subprocess.py:92} INFO -  'hotel_url': 'https://www.traveloka.com/vi-vn/hotel/vietnam/alisa-cruises-3000010025002'}
[2022-05-24 02:54:23,480] {subprocess.py:92} INFO - 2022-05-24 02:54:23 [scrapy.core.scraper] DEBUG: Scraped from <200 https://www.traveloka.com/vi-vn/hotel/vietnam/city/ha-long-city-30010278/5-star-hotels-in-ha-long-city>
[2022-05-24 02:54:23,480] {subprocess.py:92} INFO - {'hotel_address': 'Cảng Tuần Chấu, phường Tuần Châu, Thành phố Hạ Long, Tỉnh '
[2022-05-24 02:54:23,480] {subprocess.py:92} INFO -                   'Quảng Ninh, Việt Nam, 202911',
[2022-05-24 02:54:23,480] {subprocess.py:92} INFO -  'hotel_name': 'Orchid Ha Long Cruise',
[2022-05-24 02:54:23,480] {subprocess.py:92} INFO -  'hotel_point_review': '8.6',
[2022-05-24 02:54:23,480] {subprocess.py:92} INFO -  'hotel_rating': '5',
[2022-05-24 02:54:23,481] {subprocess.py:92} INFO -  'hotel_sum_review': '5',
[2022-05-24 02:54:23,481] {subprocess.py:92} INFO -  'hotel_url': 'https://www.traveloka.com/vi-vn/hotel/vietnam/orchid-ha-long-cruise-1000000619196'}
[2022-05-24 02:54:23,482] {subprocess.py:92} INFO - 2022-05-24 02:54:23 [scrapy.core.scraper] DEBUG: Scraped from <200 https://www.traveloka.com/vi-vn/hotel/vietnam/city/ha-long-city-30010278/5-star-hotels-in-ha-long-city>
[2022-05-24 02:54:23,482] {subprocess.py:92} INFO - {'hotel_address': '06A Lê Thánh Tông, Cảng Hòn Gai - Vinashin, phường Hồng '
[2022-05-24 02:54:23,482] {subprocess.py:92} INFO -                   'Gai, Thành phố Hạ Long, Tỉnh Quảng Ninh, Việt Nam, 200000',
[2022-05-24 02:54:23,482] {subprocess.py:92} INFO -  'hotel_name': 'Du thuyền Royal Wings',
[2022-05-24 02:54:23,482] {subprocess.py:92} INFO -  'hotel_point_review': '9.3',
[2022-05-24 02:54:23,482] {subprocess.py:92} INFO -  'hotel_rating': '5',
[2022-05-24 02:54:23,482] {subprocess.py:92} INFO -  'hotel_sum_review': '16',
[2022-05-24 02:54:23,483] {subprocess.py:92} INFO -  'hotel_url': 'https://www.traveloka.com/vi-vn/hotel/vietnam/royal-wings-cruise-1000000561089'}
[2022-05-24 02:54:23,483] {subprocess.py:92} INFO - 2022-05-24 02:54:23 [scrapy.core.scraper] DEBUG: Scraped from <200 https://www.traveloka.com/vi-vn/hotel/vietnam/city/ha-long-city-30010278/5-star-hotels-in-ha-long-city>
[2022-05-24 02:54:23,484] {subprocess.py:92} INFO - {'hotel_address': 'Đảo Tuần Châu, phường Tuần Châu, Thành phố Hạ Long, Tỉnh '
[2022-05-24 02:54:23,484] {subprocess.py:92} INFO -                   'Quảng Ninh, Việt Nam',
[2022-05-24 02:54:23,484] {subprocess.py:92} INFO -  'hotel_name': 'Paradise Luxury Cruise',
[2022-05-24 02:54:23,484] {subprocess.py:92} INFO -  'hotel_point_review': '8.9',
[2022-05-24 02:54:23,484] {subprocess.py:92} INFO -  'hotel_rating': '5',
[2022-05-24 02:54:23,484] {subprocess.py:92} INFO -  'hotel_sum_review': '8',
[2022-05-24 02:54:23,484] {subprocess.py:92} INFO -  'hotel_url': 'https://www.traveloka.com/vi-vn/hotel/vietnam/paradise-luxury-cruise-1000000426786'}
[2022-05-24 02:54:23,484] {subprocess.py:92} INFO - 2022-05-24 02:54:23 [root] ERROR: [Failure instance: Traceback: <class 'MySQLdb._exceptions.OperationalError'>: (2003, "Can't connect to MySQL server on '127.20.0.1:3306' (111)")
[2022-05-24 02:54:23,484] {subprocess.py:92} INFO - /usr/local/lib/python3.7/threading.py:926:_bootstrap_inner
[2022-05-24 02:54:23,484] {subprocess.py:92} INFO - /usr/local/lib/python3.7/threading.py:870:run
[2022-05-24 02:54:23,484] {subprocess.py:92} INFO - /home/***/.local/lib/python3.7/site-packages/twisted/_threads/_threadworker.py:47:work
[2022-05-24 02:54:23,484] {subprocess.py:92} INFO - /home/***/.local/lib/python3.7/site-packages/twisted/_threads/_team.py:182:doWork
[2022-05-24 02:54:23,485] {subprocess.py:92} INFO - --- <exception caught here> ---
[2022-05-24 02:54:23,485] {subprocess.py:92} INFO - /home/***/.local/lib/python3.7/site-packages/twisted/python/threadpool.py:244:inContext
[2022-05-24 02:54:23,485] {subprocess.py:92} INFO - /home/***/.local/lib/python3.7/site-packages/twisted/python/threadpool.py:261:<lambda>
[2022-05-24 02:54:23,485] {subprocess.py:92} INFO - /home/***/.local/lib/python3.7/site-packages/twisted/python/context.py:117:callWithContext
[2022-05-24 02:54:23,485] {subprocess.py:92} INFO - /home/***/.local/lib/python3.7/site-packages/twisted/python/context.py:82:callWithContext
[2022-05-24 02:54:23,485] {subprocess.py:92} INFO - /home/***/.local/lib/python3.7/site-packages/twisted/enterprise/adbapi.py:440:_runInteraction
[2022-05-24 02:54:23,485] {subprocess.py:92} INFO - /home/***/.local/lib/python3.7/site-packages/twisted/enterprise/adbapi.py:34:__init__
[2022-05-24 02:54:23,485] {subprocess.py:92} INFO - /home/***/.local/lib/python3.7/site-packages/twisted/enterprise/adbapi.py:71:reconnect
[2022-05-24 02:54:23,485] {subprocess.py:92} INFO - /home/***/.local/lib/python3.7/site-packages/twisted/enterprise/adbapi.py:410:connect
[2022-05-24 02:54:23,485] {subprocess.py:92} INFO - /home/***/.local/lib/python3.7/site-packages/MySQLdb/__init__.py:123:Connect
[2022-05-24 02:54:23,485] {subprocess.py:92} INFO - /home/***/.local/lib/python3.7/site-packages/MySQLdb/connections.py:185:__init__
[2022-05-24 02:54:23,485] {subprocess.py:92} INFO - ]
[2022-05-24 02:54:23,486] {subprocess.py:92} INFO - 2022-05-24 02:54:23 [root] ERROR: [Failure instance: Traceback: <class 'MySQLdb._exceptions.OperationalError'>: (2003, "Can't connect to MySQL server on '127.20.0.1:3306' (111)")
[2022-05-24 02:54:23,486] {subprocess.py:92} INFO - /usr/local/lib/python3.7/threading.py:926:_bootstrap_inner
[2022-05-24 02:54:23,486] {subprocess.py:92} INFO - /usr/local/lib/python3.7/threading.py:870:run
[2022-05-24 02:54:23,486] {subprocess.py:92} INFO - /home/***/.local/lib/python3.7/site-packages/twisted/_threads/_threadworker.py:47:work
[2022-05-24 02:54:23,486] {subprocess.py:92} INFO - /home/***/.local/lib/python3.7/site-packages/twisted/_threads/_team.py:182:doWork
[2022-05-24 02:54:23,486] {subprocess.py:92} INFO - --- <exception caught here> ---
[2022-05-24 02:54:23,486] {subprocess.py:92} INFO - /home/***/.local/lib/python3.7/site-packages/twisted/python/threadpool.py:244:inContext
[2022-05-24 02:54:23,486] {subprocess.py:92} INFO - /home/***/.local/lib/python3.7/site-packages/twisted/python/threadpool.py:261:<lambda>
[2022-05-24 02:54:23,486] {subprocess.py:92} INFO - /home/***/.local/lib/python3.7/site-packages/twisted/python/context.py:117:callWithContext
[2022-05-24 02:54:23,486] {subprocess.py:92} INFO - /home/***/.local/lib/python3.7/site-packages/twisted/python/context.py:82:callWithContext
[2022-05-24 02:54:23,486] {subprocess.py:92} INFO - /home/***/.local/lib/python3.7/site-packages/twisted/enterprise/adbapi.py:440:_runInteraction
[2022-05-24 02:54:23,486] {subprocess.py:92} INFO - /home/***/.local/lib/python3.7/site-packages/twisted/enterprise/adbapi.py:34:__init__
[2022-05-24 02:54:23,487] {subprocess.py:92} INFO - /home/***/.local/lib/python3.7/site-packages/twisted/enterprise/adbapi.py:71:reconnect
[2022-05-24 02:54:23,487] {subprocess.py:92} INFO - /home/***/.local/lib/python3.7/site-packages/twisted/enterprise/adbapi.py:410:connect
[2022-05-24 02:54:23,487] {subprocess.py:92} INFO - /home/***/.local/lib/python3.7/site-packages/MySQLdb/__init__.py:123:Connect
[2022-05-24 02:54:23,487] {subprocess.py:92} INFO - /home/***/.local/lib/python3.7/site-packages/MySQLdb/connections.py:185:__init__
[2022-05-24 02:54:23,487] {subprocess.py:92} INFO - ]
[2022-05-24 02:54:23,487] {subprocess.py:92} INFO - 2022-05-24 02:54:23 [root] ERROR: [Failure instance: Traceback: <class 'MySQLdb._exceptions.OperationalError'>: (2003, "Can't connect to MySQL server on '127.20.0.1:3306' (111)")
[2022-05-24 02:54:23,487] {subprocess.py:92} INFO - /usr/local/lib/python3.7/threading.py:926:_bootstrap_inner
[2022-05-24 02:54:23,487] {subprocess.py:92} INFO - /usr/local/lib/python3.7/threading.py:870:run
[2022-05-24 02:54:23,487] {subprocess.py:92} INFO - /home/***/.local/lib/python3.7/site-packages/twisted/_threads/_threadworker.py:47:work
[2022-05-24 02:54:23,487] {subprocess.py:92} INFO - /home/***/.local/lib/python3.7/site-packages/twisted/_threads/_team.py:182:doWork
[2022-05-24 02:54:23,487] {subprocess.py:92} INFO - --- <exception caught here> ---
[2022-05-24 02:54:23,487] {subprocess.py:92} INFO - /home/***/.local/lib/python3.7/site-packages/twisted/python/threadpool.py:244:inContext
[2022-05-24 02:54:23,488] {subprocess.py:92} INFO - /home/***/.local/lib/python3.7/site-packages/twisted/python/threadpool.py:261:<lambda>
[2022-05-24 02:54:23,488] {subprocess.py:92} INFO - /home/***/.local/lib/python3.7/site-packages/twisted/python/context.py:117:callWithContext
[2022-05-24 02:54:23,488] {subprocess.py:92} INFO - /home/***/.local/lib/python3.7/site-packages/twisted/python/context.py:82:callWithContext
[2022-05-24 02:54:23,488] {subprocess.py:92} INFO - /home/***/.local/lib/python3.7/site-packages/twisted/enterprise/adbapi.py:440:_runInteraction
[2022-05-24 02:54:23,488] {subprocess.py:92} INFO - /home/***/.local/lib/python3.7/site-packages/twisted/enterprise/adbapi.py:34:__init__
[2022-05-24 02:54:23,488] {subprocess.py:92} INFO - /home/***/.local/lib/python3.7/site-packages/twisted/enterprise/adbapi.py:71:reconnect
[2022-05-24 02:54:23,488] {subprocess.py:92} INFO - /home/***/.local/lib/python3.7/site-packages/twisted/enterprise/adbapi.py:410:connect
[2022-05-24 02:54:23,488] {subprocess.py:92} INFO - /home/***/.local/lib/python3.7/site-packages/MySQLdb/__init__.py:123:Connect
[2022-05-24 02:54:23,488] {subprocess.py:92} INFO - /home/***/.local/lib/python3.7/site-packages/MySQLdb/connections.py:185:__init__
[2022-05-24 02:54:23,488] {subprocess.py:92} INFO - ]
[2022-05-24 02:54:23,488] {subprocess.py:92} INFO - 2022-05-24 02:54:23 [root] ERROR: [Failure instance: Traceback: <class 'MySQLdb._exceptions.OperationalError'>: (2003, "Can't connect to MySQL server on '127.20.0.1:3306' (111)")
[2022-05-24 02:54:23,489] {subprocess.py:92} INFO - /usr/local/lib/python3.7/threading.py:926:_bootstrap_inner
[2022-05-24 02:54:23,489] {subprocess.py:92} INFO - /usr/local/lib/python3.7/threading.py:870:run
[2022-05-24 02:54:23,489] {subprocess.py:92} INFO - /home/***/.local/lib/python3.7/site-packages/twisted/_threads/_threadworker.py:47:work
[2022-05-24 02:54:23,489] {subprocess.py:92} INFO - /home/***/.local/lib/python3.7/site-packages/twisted/_threads/_team.py:182:doWork
[2022-05-24 02:54:23,489] {subprocess.py:92} INFO - --- <exception caught here> ---
[2022-05-24 02:54:23,489] {subprocess.py:92} INFO - /home/***/.local/lib/python3.7/site-packages/twisted/python/threadpool.py:244:inContext
[2022-05-24 02:54:23,489] {subprocess.py:92} INFO - /home/***/.local/lib/python3.7/site-packages/twisted/python/threadpool.py:261:<lambda>
[2022-05-24 02:54:23,489] {subprocess.py:92} INFO - /home/***/.local/lib/python3.7/site-packages/twisted/python/context.py:117:callWithContext
[2022-05-24 02:54:23,489] {subprocess.py:92} INFO - /home/***/.local/lib/python3.7/site-packages/twisted/python/context.py:82:callWithContext
[2022-05-24 02:54:23,489] {subprocess.py:92} INFO - /home/***/.local/lib/python3.7/site-packages/twisted/enterprise/adbapi.py:440:_runInteraction
[2022-05-24 02:54:23,489] {subprocess.py:92} INFO - /home/***/.local/lib/python3.7/site-packages/twisted/enterprise/adbapi.py:34:__init__
[2022-05-24 02:54:23,489] {subprocess.py:92} INFO - /home/***/.local/lib/python3.7/site-packages/twisted/enterprise/adbapi.py:71:reconnect
[2022-05-24 02:54:23,489] {subprocess.py:92} INFO - /home/***/.local/lib/python3.7/site-packages/twisted/enterprise/adbapi.py:410:connect
[2022-05-24 02:54:23,490] {subprocess.py:92} INFO - /home/***/.local/lib/python3.7/site-packages/MySQLdb/__init__.py:123:Connect
[2022-05-24 02:54:23,490] {subprocess.py:92} INFO - /home/***/.local/lib/python3.7/site-packages/MySQLdb/connections.py:185:__init__
[2022-05-24 02:54:23,490] {subprocess.py:92} INFO - ]
[2022-05-24 02:54:23,490] {subprocess.py:92} INFO - 2022-05-24 02:54:23 [root] ERROR: [Failure instance: Traceback: <class 'MySQLdb._exceptions.OperationalError'>: (2003, "Can't connect to MySQL server on '127.20.0.1:3306' (111)")
[2022-05-24 02:54:23,490] {subprocess.py:92} INFO - /usr/local/lib/python3.7/threading.py:926:_bootstrap_inner
[2022-05-24 02:54:23,490] {subprocess.py:92} INFO - /usr/local/lib/python3.7/threading.py:870:run
[2022-05-24 02:54:23,490] {subprocess.py:92} INFO - /home/***/.local/lib/python3.7/site-packages/twisted/_threads/_threadworker.py:47:work
[2022-05-24 02:54:23,490] {subprocess.py:92} INFO - /home/***/.local/lib/python3.7/site-packages/twisted/_threads/_team.py:182:doWork
[2022-05-24 02:54:23,490] {subprocess.py:92} INFO - --- <exception caught here> ---
[2022-05-24 02:54:23,490] {subprocess.py:92} INFO - /home/***/.local/lib/python3.7/site-packages/twisted/python/threadpool.py:244:inContext
[2022-05-24 02:54:23,490] {subprocess.py:92} INFO - /home/***/.local/lib/python3.7/site-packages/twisted/python/threadpool.py:261:<lambda>
[2022-05-24 02:54:23,490] {subprocess.py:92} INFO - /home/***/.local/lib/python3.7/site-packages/twisted/python/context.py:117:callWithContext
[2022-05-24 02:54:23,490] {subprocess.py:92} INFO - /home/***/.local/lib/python3.7/site-packages/twisted/python/context.py:82:callWithContext
[2022-05-24 02:54:23,491] {subprocess.py:92} INFO - /home/***/.local/lib/python3.7/site-packages/twisted/enterprise/adbapi.py:440:_runInteraction
[2022-05-24 02:54:23,491] {subprocess.py:92} INFO - /home/***/.local/lib/python3.7/site-packages/twisted/enterprise/adbapi.py:34:__init__
[2022-05-24 02:54:23,491] {subprocess.py:92} INFO - /home/***/.local/lib/python3.7/site-packages/twisted/enterprise/adbapi.py:71:reconnect
[2022-05-24 02:54:23,491] {subprocess.py:92} INFO - /home/***/.local/lib/python3.7/site-packages/twisted/enterprise/adbapi.py:410:connect
[2022-05-24 02:54:23,491] {subprocess.py:92} INFO - /home/***/.local/lib/python3.7/site-packages/MySQLdb/__init__.py:123:Connect
[2022-05-24 02:54:23,491] {subprocess.py:92} INFO - /home/***/.local/lib/python3.7/site-packages/MySQLdb/connections.py:185:__init__
[2022-05-24 02:54:23,491] {subprocess.py:92} INFO - ]
[2022-05-24 02:54:23,491] {subprocess.py:92} INFO - 2022-05-24 02:54:23 [root] ERROR: [Failure instance: Traceback: <class 'MySQLdb._exceptions.OperationalError'>: (2003, "Can't connect to MySQL server on '127.20.0.1:3306' (111)")
[2022-05-24 02:54:23,491] {subprocess.py:92} INFO - /usr/local/lib/python3.7/threading.py:926:_bootstrap_inner
[2022-05-24 02:54:23,491] {subprocess.py:92} INFO - /usr/local/lib/python3.7/threading.py:870:run
[2022-05-24 02:54:23,491] {subprocess.py:92} INFO - /home/***/.local/lib/python3.7/site-packages/twisted/_threads/_threadworker.py:47:work
[2022-05-24 02:54:23,491] {subprocess.py:92} INFO - /home/***/.local/lib/python3.7/site-packages/twisted/_threads/_team.py:182:doWork
[2022-05-24 02:54:23,492] {subprocess.py:92} INFO - --- <exception caught here> ---
[2022-05-24 02:54:23,492] {subprocess.py:92} INFO - /home/***/.local/lib/python3.7/site-packages/twisted/python/threadpool.py:244:inContext
[2022-05-24 02:54:23,492] {subprocess.py:92} INFO - /home/***/.local/lib/python3.7/site-packages/twisted/python/threadpool.py:261:<lambda>
[2022-05-24 02:54:23,492] {subprocess.py:92} INFO - /home/***/.local/lib/python3.7/site-packages/twisted/python/context.py:117:callWithContext
[2022-05-24 02:54:23,492] {subprocess.py:92} INFO - /home/***/.local/lib/python3.7/site-packages/twisted/python/context.py:82:callWithContext
[2022-05-24 02:54:23,492] {subprocess.py:92} INFO - /home/***/.local/lib/python3.7/site-packages/twisted/enterprise/adbapi.py:440:_runInteraction
[2022-05-24 02:54:23,492] {subprocess.py:92} INFO - /home/***/.local/lib/python3.7/site-packages/twisted/enterprise/adbapi.py:34:__init__
[2022-05-24 02:54:23,492] {subprocess.py:92} INFO - /home/***/.local/lib/python3.7/site-packages/twisted/enterprise/adbapi.py:71:reconnect
[2022-05-24 02:54:23,492] {subprocess.py:92} INFO - /home/***/.local/lib/python3.7/site-packages/twisted/enterprise/adbapi.py:410:connect
[2022-05-24 02:54:23,492] {subprocess.py:92} INFO - /home/***/.local/lib/python3.7/site-packages/MySQLdb/__init__.py:123:Connect
[2022-05-24 02:54:23,492] {subprocess.py:92} INFO - /home/***/.local/lib/python3.7/site-packages/MySQLdb/connections.py:185:__init__
[2022-05-24 02:54:23,492] {subprocess.py:92} INFO - ]
[2022-05-24 02:54:28,625] {subprocess.py:92} INFO - 2022-05-24 02:54:28 [scrapy.core.engine] DEBUG: Crawled (200) <GET https://www.traveloka.com/vi-vn/hotel/vietnam/landmark/bai-chay-lighthouse-91566910108689> (referer: https://www.traveloka.com/vi-vn/hotel/vietnam/city/ha-long-city-30010278)
[2022-05-24 02:54:28,782] {subprocess.py:92} INFO - 2022-05-24 02:54:28 [scrapy.core.scraper] DEBUG: Scraped from <200 https://www.traveloka.com/vi-vn/hotel/vietnam/landmark/bai-chay-lighthouse-91566910108689>
[2022-05-24 02:54:28,782] {subprocess.py:92} INFO - {'hotel_address': '2 Hạ Long, Bãi Cháy, phường Bãi Cháy, Thành phố Hạ Long, '
[2022-05-24 02:54:28,782] {subprocess.py:92} INFO -                   'Tỉnh Quảng Ninh, Việt Nam, 200000',
[2022-05-24 02:54:28,783] {subprocess.py:92} INFO -  'hotel_name': 'Du thuyền Annam Junk 1',
[2022-05-24 02:54:28,783] {subprocess.py:92} INFO -  'hotel_point_review': '8.7',
[2022-05-24 02:54:28,783] {subprocess.py:92} INFO -  'hotel_rating': '3',
[2022-05-24 02:54:28,783] {subprocess.py:92} INFO -  'hotel_sum_review': '159',
[2022-05-24 02:54:28,783] {subprocess.py:92} INFO -  'hotel_url': 'https://www.traveloka.com/vi-vn/hotel/vietnam/an-nam-junk-1-cruise-1000000309555'}
[2022-05-24 02:54:28,784] {subprocess.py:92} INFO - 2022-05-24 02:54:28 [scrapy.core.scraper] DEBUG: Scraped from <200 https://www.traveloka.com/vi-vn/hotel/vietnam/landmark/bai-chay-lighthouse-91566910108689>
[2022-05-24 02:54:28,784] {subprocess.py:92} INFO - {'hotel_address': '2 Hạ Long, Bãi Cháy, phường Bãi Cháy, Thành phố Hạ Long, '
[2022-05-24 02:54:28,784] {subprocess.py:92} INFO -                   'Tỉnh Quảng Ninh, Việt Nam, 200000',
[2022-05-24 02:54:28,784] {subprocess.py:92} INFO -  'hotel_name': 'Du thuyền An Nam Junk 3',
[2022-05-24 02:54:28,785] {subprocess.py:92} INFO -  'hotel_point_review': '8.3',
[2022-05-24 02:54:28,785] {subprocess.py:92} INFO -  'hotel_rating': '3',
[2022-05-24 02:54:28,785] {subprocess.py:92} INFO -  'hotel_sum_review': '41',
[2022-05-24 02:54:28,785] {subprocess.py:92} INFO -  'hotel_url': 'https://www.traveloka.com/vi-vn/hotel/vietnam/an-nam-junk-3-3000010036826'}
[2022-05-24 02:54:28,786] {subprocess.py:92} INFO - 2022-05-24 02:54:28 [scrapy.core.scraper] DEBUG: Scraped from <200 https://www.traveloka.com/vi-vn/hotel/vietnam/landmark/bai-chay-lighthouse-91566910108689>
[2022-05-24 02:54:28,786] {subprocess.py:92} INFO - {'hotel_address': '2 Hạ Long, Bãi Cháy, phường Bãi Cháy, Thành phố Hạ Long, '
[2022-05-24 02:54:28,786] {subprocess.py:92} INFO -                   'Tỉnh Quảng Ninh, Việt Nam, 200000',
[2022-05-24 02:54:28,786] {subprocess.py:92} INFO -  'hotel_name': 'Du thuyền Pegasus',
[2022-05-24 02:54:28,787] {subprocess.py:92} INFO -  'hotel_point_review': '8.8',
[2022-05-24 02:54:28,787] {subprocess.py:92} INFO -  'hotel_rating': '3',
[2022-05-24 02:54:28,787] {subprocess.py:92} INFO -  'hotel_sum_review': '97',
[2022-05-24 02:54:28,787] {subprocess.py:92} INFO -  'hotel_url': 'https://www.traveloka.com/vi-vn/hotel/vietnam/pegasus-cruise--3000010036747'}
[2022-05-24 02:54:28,788] {subprocess.py:92} INFO - 2022-05-24 02:54:28 [scrapy.core.scraper] DEBUG: Scraped from <200 https://www.traveloka.com/vi-vn/hotel/vietnam/landmark/bai-chay-lighthouse-91566910108689>
[2022-05-24 02:54:28,788] {subprocess.py:92} INFO - {'hotel_address': '2 Hạ Long, Bãi Cháy, phường Bãi Cháy, Thành phố Hạ Long, '
[2022-05-24 02:54:28,788] {subprocess.py:92} INFO -                   'Tỉnh Quảng Ninh, Việt Nam, 200000',
[2022-05-24 02:54:28,789] {subprocess.py:92} INFO -  'hotel_name': 'Du thuyền An Nam Junk 3',
[2022-05-24 02:54:28,789] {subprocess.py:92} INFO -  'hotel_point_review': '8.3',
[2022-05-24 02:54:28,789] {subprocess.py:92} INFO -  'hotel_rating': '3',
[2022-05-24 02:54:28,789] {subprocess.py:92} INFO -  'hotel_sum_review': '43',
[2022-05-24 02:54:28,789] {subprocess.py:92} INFO -  'hotel_url': 'https://www.traveloka.com/vi-vn/hotel/vietnam/an-nam-junk-2-3000010036798'}
[2022-05-24 02:54:28,790] {subprocess.py:92} INFO - 2022-05-24 02:54:28 [scrapy.core.scraper] DEBUG: Scraped from <200 https://www.traveloka.com/vi-vn/hotel/vietnam/landmark/bai-chay-lighthouse-91566910108689>
[2022-05-24 02:54:28,791] {subprocess.py:92} INFO - {'hotel_address': 'Số 12 Đường Hạ Long, Phường Bãi Cháy, phường Bãi Cháy, '
[2022-05-24 02:54:28,791] {subprocess.py:92} INFO -                   'Thành phố Hạ Long, Tỉnh Quảng Ninh, Việt Nam, 200000',
[2022-05-24 02:54:28,791] {subprocess.py:92} INFO -  'hotel_name': 'Wyndham Legend Halong Hotel',
[2022-05-24 02:54:28,791] {subprocess.py:92} INFO -  'hotel_point_review': '7.1',
[2022-05-24 02:54:28,791] {subprocess.py:92} INFO -  'hotel_rating': '5',
[2022-05-24 02:54:28,791] {subprocess.py:92} INFO -  'hotel_sum_review': '7',
[2022-05-24 02:54:28,791] {subprocess.py:92} INFO -  'hotel_url': 'https://www.traveloka.com/vi-vn/hotel/vietnam/wyndham-legend-halong-hotel-1000000620395'}
[2022-05-24 02:54:28,793] {subprocess.py:92} INFO - 2022-05-24 02:54:28 [scrapy.core.scraper] DEBUG: Scraped from <200 https://www.traveloka.com/vi-vn/hotel/vietnam/landmark/bai-chay-lighthouse-91566910108689>
[2022-05-24 02:54:28,793] {subprocess.py:92} INFO - {'hotel_address': '08 Ha Long Road, phường Bãi Cháy, Thành phố Hạ Long, Tỉnh '
[2022-05-24 02:54:28,793] {subprocess.py:92} INFO -                   'Quảng Ninh, Việt Nam, 200000',
[2022-05-24 02:54:28,793] {subprocess.py:92} INFO -  'hotel_name': 'Syrena Cruises',
[2022-05-24 02:54:28,793] {subprocess.py:92} INFO -  'hotel_point_review': '7.8',
[2022-05-24 02:54:28,793] {subprocess.py:92} INFO -  'hotel_rating': '5',
[2022-05-24 02:54:28,793] {subprocess.py:92} INFO -  'hotel_sum_review': '7',
[2022-05-24 02:54:28,793] {subprocess.py:92} INFO -  'hotel_url': 'https://www.traveloka.com/vi-vn/hotel/vietnam/syrena-cruises-9000000760010'}
[2022-05-24 02:54:28,794] {subprocess.py:92} INFO - 2022-05-24 02:54:28 [root] ERROR: [Failure instance: Traceback: <class 'MySQLdb._exceptions.OperationalError'>: (2003, "Can't connect to MySQL server on '127.20.0.1:3306' (111)")
[2022-05-24 02:54:28,794] {subprocess.py:92} INFO - /usr/local/lib/python3.7/threading.py:926:_bootstrap_inner
[2022-05-24 02:54:28,794] {subprocess.py:92} INFO - /usr/local/lib/python3.7/threading.py:870:run
[2022-05-24 02:54:28,794] {subprocess.py:92} INFO - /home/***/.local/lib/python3.7/site-packages/twisted/_threads/_threadworker.py:47:work
[2022-05-24 02:54:28,794] {subprocess.py:92} INFO - /home/***/.local/lib/python3.7/site-packages/twisted/_threads/_team.py:182:doWork
[2022-05-24 02:54:28,794] {subprocess.py:92} INFO - --- <exception caught here> ---
[2022-05-24 02:54:28,794] {subprocess.py:92} INFO - /home/***/.local/lib/python3.7/site-packages/twisted/python/threadpool.py:244:inContext
[2022-05-24 02:54:28,794] {subprocess.py:92} INFO - /home/***/.local/lib/python3.7/site-packages/twisted/python/threadpool.py:261:<lambda>
[2022-05-24 02:54:28,794] {subprocess.py:92} INFO - /home/***/.local/lib/python3.7/site-packages/twisted/python/context.py:117:callWithContext
[2022-05-24 02:54:28,795] {subprocess.py:92} INFO - /home/***/.local/lib/python3.7/site-packages/twisted/python/context.py:82:callWithContext
[2022-05-24 02:54:28,795] {subprocess.py:92} INFO - /home/***/.local/lib/python3.7/site-packages/twisted/enterprise/adbapi.py:440:_runInteraction
[2022-05-24 02:54:28,795] {subprocess.py:92} INFO - /home/***/.local/lib/python3.7/site-packages/twisted/enterprise/adbapi.py:34:__init__
[2022-05-24 02:54:28,795] {subprocess.py:92} INFO - /home/***/.local/lib/python3.7/site-packages/twisted/enterprise/adbapi.py:71:reconnect
[2022-05-24 02:54:28,795] {subprocess.py:92} INFO - /home/***/.local/lib/python3.7/site-packages/twisted/enterprise/adbapi.py:410:connect
[2022-05-24 02:54:28,795] {subprocess.py:92} INFO - /home/***/.local/lib/python3.7/site-packages/MySQLdb/__init__.py:123:Connect
[2022-05-24 02:54:28,795] {subprocess.py:92} INFO - /home/***/.local/lib/python3.7/site-packages/MySQLdb/connections.py:185:__init__
[2022-05-24 02:54:28,795] {subprocess.py:92} INFO - ]
[2022-05-24 02:54:28,795] {subprocess.py:92} INFO - 2022-05-24 02:54:28 [scrapy.core.scraper] DEBUG: Scraped from <200 https://www.traveloka.com/vi-vn/hotel/vietnam/landmark/bai-chay-lighthouse-91566910108689>
[2022-05-24 02:54:28,796] {subprocess.py:92} INFO - {'hotel_address': 'Đường Hạ Long, Phường Bãi Cháy\t\t, phường Bãi Cháy, Thành '
[2022-05-24 02:54:28,796] {subprocess.py:92} INFO -                   'phố Hạ Long, Tỉnh Quảng Ninh, Việt Nam, 200000',
[2022-05-24 02:54:28,796] {subprocess.py:92} INFO -  'hotel_name': 'Khách sạn Grand Ha Long',
[2022-05-24 02:54:28,796] {subprocess.py:92} INFO -  'hotel_point_review': '6.7',
[2022-05-24 02:54:28,796] {subprocess.py:92} INFO -  'hotel_rating': '4',
[2022-05-24 02:54:28,796] {subprocess.py:92} INFO -  'hotel_sum_review': '10',
[2022-05-24 02:54:28,796] {subprocess.py:92} INFO -  'hotel_url': 'https://www.traveloka.com/vi-vn/hotel/vietnam/grand-ha-long-hotel-1000000324620'}
[2022-05-24 02:54:28,797] {subprocess.py:92} INFO - 2022-05-24 02:54:28 [scrapy.core.scraper] DEBUG: Scraped from <200 https://www.traveloka.com/vi-vn/hotel/vietnam/landmark/bai-chay-lighthouse-91566910108689>
[2022-05-24 02:54:28,797] {subprocess.py:92} INFO - {'hotel_address': 'Số 8 Đường Hạ Long, Phường Bãi Cháy, phường Bãi Cháy, Thành '
[2022-05-24 02:54:28,797] {subprocess.py:92} INFO -                   'phố Hạ Long, Tỉnh Quảng Ninh, Việt Nam, 200000',
[2022-05-24 02:54:28,797] {subprocess.py:92} INFO -  'hotel_name': 'Khách sạn Ha Long Plaza',
[2022-05-24 02:54:28,798] {subprocess.py:92} INFO -  'hotel_point_review': '8.4',
[2022-05-24 02:54:28,798] {subprocess.py:92} INFO -  'hotel_rating': '4',
[2022-05-24 02:54:28,798] {subprocess.py:92} INFO -  'hotel_sum_review': '28',
[2022-05-24 02:54:28,798] {subprocess.py:92} INFO -  'hotel_url': 'https://www.traveloka.com/vi-vn/hotel/vietnam/halong-plaza-hotel-1000000255551'}
[2022-05-24 02:54:28,800] {subprocess.py:92} INFO - 2022-05-24 02:54:28 [scrapy.core.scraper] DEBUG: Scraped from <200 https://www.traveloka.com/vi-vn/hotel/vietnam/landmark/bai-chay-lighthouse-91566910108689>
[2022-05-24 02:54:28,800] {subprocess.py:92} INFO - {'hotel_address': '25 Hạ Long, phường Bãi Cháy, Thành phố Hạ Long, Tỉnh Quảng '
[2022-05-24 02:54:28,800] {subprocess.py:92} INFO -                   'Ninh, Việt Nam, 200000',
[2022-05-24 02:54:28,800] {subprocess.py:92} INFO -  'hotel_name': 'Bamboo Hotel & Apartment',
[2022-05-24 02:54:28,800] {subprocess.py:92} INFO -  'hotel_point_review': '8.5',
[2022-05-24 02:54:28,800] {subprocess.py:92} INFO -  'hotel_rating': '2',
[2022-05-24 02:54:28,800] {subprocess.py:92} INFO -  'hotel_sum_review': '13',
[2022-05-24 02:54:28,800] {subprocess.py:92} INFO -  'hotel_url': 'https://www.traveloka.com/vi-vn/hotel/vietnam/bamboo-hotel--apartment-3000020012558'}
[2022-05-24 02:54:28,803] {subprocess.py:92} INFO - 2022-05-24 02:54:28 [root] ERROR: [Failure instance: Traceback: <class 'MySQLdb._exceptions.OperationalError'>: (2003, "Can't connect to MySQL server on '127.20.0.1:3306' (111)")
[2022-05-24 02:54:28,804] {subprocess.py:92} INFO - /usr/local/lib/python3.7/threading.py:926:_bootstrap_inner
[2022-05-24 02:54:28,804] {subprocess.py:92} INFO - /usr/local/lib/python3.7/threading.py:870:run
[2022-05-24 02:54:28,804] {subprocess.py:92} INFO - /home/***/.local/lib/python3.7/site-packages/twisted/_threads/_threadworker.py:47:work
[2022-05-24 02:54:28,804] {subprocess.py:92} INFO - /home/***/.local/lib/python3.7/site-packages/twisted/_threads/_team.py:182:doWork
[2022-05-24 02:54:28,804] {subprocess.py:92} INFO - --- <exception caught here> ---
[2022-05-24 02:54:28,804] {subprocess.py:92} INFO - /home/***/.local/lib/python3.7/site-packages/twisted/python/threadpool.py:244:inContext
[2022-05-24 02:54:28,804] {subprocess.py:92} INFO - /home/***/.local/lib/python3.7/site-packages/twisted/python/threadpool.py:261:<lambda>
[2022-05-24 02:54:28,804] {subprocess.py:92} INFO - /home/***/.local/lib/python3.7/site-packages/twisted/python/context.py:117:callWithContext
[2022-05-24 02:54:28,804] {subprocess.py:92} INFO - /home/***/.local/lib/python3.7/site-packages/twisted/python/context.py:82:callWithContext
[2022-05-24 02:54:28,804] {subprocess.py:92} INFO - /home/***/.local/lib/python3.7/site-packages/twisted/enterprise/adbapi.py:440:_runInteraction
[2022-05-24 02:54:28,804] {subprocess.py:92} INFO - /home/***/.local/lib/python3.7/site-packages/twisted/enterprise/adbapi.py:34:__init__
[2022-05-24 02:54:28,804] {subprocess.py:92} INFO - /home/***/.local/lib/python3.7/site-packages/twisted/enterprise/adbapi.py:71:reconnect
[2022-05-24 02:54:28,805] {subprocess.py:92} INFO - /home/***/.local/lib/python3.7/site-packages/twisted/enterprise/adbapi.py:410:connect
[2022-05-24 02:54:28,805] {subprocess.py:92} INFO - /home/***/.local/lib/python3.7/site-packages/MySQLdb/__init__.py:123:Connect
[2022-05-24 02:54:28,805] {subprocess.py:92} INFO - /home/***/.local/lib/python3.7/site-packages/MySQLdb/connections.py:185:__init__
[2022-05-24 02:54:28,805] {subprocess.py:92} INFO - ]
[2022-05-24 02:54:28,805] {subprocess.py:92} INFO - 2022-05-24 02:54:28 [root] ERROR: [Failure instance: Traceback: <class 'MySQLdb._exceptions.OperationalError'>: (2003, "Can't connect to MySQL server on '127.20.0.1:3306' (111)")
[2022-05-24 02:54:28,805] {subprocess.py:92} INFO - /usr/local/lib/python3.7/threading.py:926:_bootstrap_inner
[2022-05-24 02:54:28,805] {subprocess.py:92} INFO - /usr/local/lib/python3.7/threading.py:870:run
[2022-05-24 02:54:28,805] {subprocess.py:92} INFO - /home/***/.local/lib/python3.7/site-packages/twisted/_threads/_threadworker.py:47:work
[2022-05-24 02:54:28,805] {subprocess.py:92} INFO - /home/***/.local/lib/python3.7/site-packages/twisted/_threads/_team.py:182:doWork
[2022-05-24 02:54:28,805] {subprocess.py:92} INFO - --- <exception caught here> ---
[2022-05-24 02:54:28,805] {subprocess.py:92} INFO - /home/***/.local/lib/python3.7/site-packages/twisted/python/threadpool.py:244:inContext
[2022-05-24 02:54:28,805] {subprocess.py:92} INFO - /home/***/.local/lib/python3.7/site-packages/twisted/python/threadpool.py:261:<lambda>
[2022-05-24 02:54:28,806] {subprocess.py:92} INFO - /home/***/.local/lib/python3.7/site-packages/twisted/python/context.py:117:callWithContext
[2022-05-24 02:54:28,806] {subprocess.py:92} INFO - /home/***/.local/lib/python3.7/site-packages/twisted/python/context.py:82:callWithContext
[2022-05-24 02:54:28,806] {subprocess.py:92} INFO - /home/***/.local/lib/python3.7/site-packages/twisted/enterprise/adbapi.py:440:_runInteraction
[2022-05-24 02:54:28,806] {subprocess.py:92} INFO - /home/***/.local/lib/python3.7/site-packages/twisted/enterprise/adbapi.py:34:__init__
[2022-05-24 02:54:28,806] {subprocess.py:92} INFO - /home/***/.local/lib/python3.7/site-packages/twisted/enterprise/adbapi.py:71:reconnect
[2022-05-24 02:54:28,806] {subprocess.py:92} INFO - /home/***/.local/lib/python3.7/site-packages/twisted/enterprise/adbapi.py:410:connect
[2022-05-24 02:54:28,806] {subprocess.py:92} INFO - /home/***/.local/lib/python3.7/site-packages/MySQLdb/__init__.py:123:Connect
[2022-05-24 02:54:28,806] {subprocess.py:92} INFO - /home/***/.local/lib/python3.7/site-packages/MySQLdb/connections.py:185:__init__
[2022-05-24 02:54:28,806] {subprocess.py:92} INFO - ]
[2022-05-24 02:54:28,806] {subprocess.py:92} INFO - 2022-05-24 02:54:28 [root] ERROR: [Failure instance: Traceback: <class 'MySQLdb._exceptions.OperationalError'>: (2003, "Can't connect to MySQL server on '127.20.0.1:3306' (111)")
[2022-05-24 02:54:28,806] {subprocess.py:92} INFO - /usr/local/lib/python3.7/threading.py:926:_bootstrap_inner
[2022-05-24 02:54:28,806] {subprocess.py:92} INFO - /usr/local/lib/python3.7/threading.py:870:run
[2022-05-24 02:54:28,806] {subprocess.py:92} INFO - /home/***/.local/lib/python3.7/site-packages/twisted/_threads/_threadworker.py:47:work
[2022-05-24 02:54:28,806] {subprocess.py:92} INFO - /home/***/.local/lib/python3.7/site-packages/twisted/_threads/_team.py:182:doWork
[2022-05-24 02:54:28,807] {subprocess.py:92} INFO - --- <exception caught here> ---
[2022-05-24 02:54:28,807] {subprocess.py:92} INFO - /home/***/.local/lib/python3.7/site-packages/twisted/python/threadpool.py:244:inContext
[2022-05-24 02:54:28,807] {subprocess.py:92} INFO - /home/***/.local/lib/python3.7/site-packages/twisted/python/threadpool.py:261:<lambda>
[2022-05-24 02:54:28,807] {subprocess.py:92} INFO - /home/***/.local/lib/python3.7/site-packages/twisted/python/context.py:117:callWithContext
[2022-05-24 02:54:28,807] {subprocess.py:92} INFO - /home/***/.local/lib/python3.7/site-packages/twisted/python/context.py:82:callWithContext
[2022-05-24 02:54:28,807] {subprocess.py:92} INFO - /home/***/.local/lib/python3.7/site-packages/twisted/enterprise/adbapi.py:440:_runInteraction
[2022-05-24 02:54:28,807] {subprocess.py:92} INFO - /home/***/.local/lib/python3.7/site-packages/twisted/enterprise/adbapi.py:34:__init__
[2022-05-24 02:54:28,807] {subprocess.py:92} INFO - /home/***/.local/lib/python3.7/site-packages/twisted/enterprise/adbapi.py:71:reconnect
[2022-05-24 02:54:28,807] {subprocess.py:92} INFO - /home/***/.local/lib/python3.7/site-packages/twisted/enterprise/adbapi.py:410:connect
[2022-05-24 02:54:28,807] {subprocess.py:92} INFO - /home/***/.local/lib/python3.7/site-packages/MySQLdb/__init__.py:123:Connect
[2022-05-24 02:54:28,807] {subprocess.py:92} INFO - /home/***/.local/lib/python3.7/site-packages/MySQLdb/connections.py:185:__init__
[2022-05-24 02:54:28,808] {subprocess.py:92} INFO - ]
[2022-05-24 02:54:28,808] {subprocess.py:92} INFO - 2022-05-24 02:54:28 [root] ERROR: [Failure instance: Traceback: <class 'MySQLdb._exceptions.OperationalError'>: (2003, "Can't connect to MySQL server on '127.20.0.1:3306' (111)")
[2022-05-24 02:54:28,808] {subprocess.py:92} INFO - /usr/local/lib/python3.7/threading.py:926:_bootstrap_inner
[2022-05-24 02:54:28,808] {subprocess.py:92} INFO - /usr/local/lib/python3.7/threading.py:870:run
[2022-05-24 02:54:28,808] {subprocess.py:92} INFO - /home/***/.local/lib/python3.7/site-packages/twisted/_threads/_threadworker.py:47:work
[2022-05-24 02:54:28,808] {subprocess.py:92} INFO - /home/***/.local/lib/python3.7/site-packages/twisted/_threads/_team.py:182:doWork
[2022-05-24 02:54:28,808] {subprocess.py:92} INFO - --- <exception caught here> ---
[2022-05-24 02:54:28,808] {subprocess.py:92} INFO - /home/***/.local/lib/python3.7/site-packages/twisted/python/threadpool.py:244:inContext
[2022-05-24 02:54:28,808] {subprocess.py:92} INFO - /home/***/.local/lib/python3.7/site-packages/twisted/python/threadpool.py:261:<lambda>
[2022-05-24 02:54:28,808] {subprocess.py:92} INFO - /home/***/.local/lib/python3.7/site-packages/twisted/python/context.py:117:callWithContext
[2022-05-24 02:54:28,808] {subprocess.py:92} INFO - /home/***/.local/lib/python3.7/site-packages/twisted/python/context.py:82:callWithContext
[2022-05-24 02:54:28,808] {subprocess.py:92} INFO - /home/***/.local/lib/python3.7/site-packages/twisted/enterprise/adbapi.py:440:_runInteraction
[2022-05-24 02:54:28,808] {subprocess.py:92} INFO - /home/***/.local/lib/python3.7/site-packages/twisted/enterprise/adbapi.py:34:__init__
[2022-05-24 02:54:28,808] {subprocess.py:92} INFO - /home/***/.local/lib/python3.7/site-packages/twisted/enterprise/adbapi.py:71:reconnect
[2022-05-24 02:54:28,809] {subprocess.py:92} INFO - /home/***/.local/lib/python3.7/site-packages/twisted/enterprise/adbapi.py:410:connect
[2022-05-24 02:54:28,809] {subprocess.py:92} INFO - /home/***/.local/lib/python3.7/site-packages/MySQLdb/__init__.py:123:Connect
[2022-05-24 02:54:28,809] {subprocess.py:92} INFO - /home/***/.local/lib/python3.7/site-packages/MySQLdb/connections.py:185:__init__
[2022-05-24 02:54:28,809] {subprocess.py:92} INFO - ]
[2022-05-24 02:54:28,809] {subprocess.py:92} INFO - 2022-05-24 02:54:28 [root] ERROR: [Failure instance: Traceback: <class 'MySQLdb._exceptions.OperationalError'>: (2003, "Can't connect to MySQL server on '127.20.0.1:3306' (111)")
[2022-05-24 02:54:28,809] {subprocess.py:92} INFO - /usr/local/lib/python3.7/threading.py:926:_bootstrap_inner
[2022-05-24 02:54:28,809] {subprocess.py:92} INFO - /usr/local/lib/python3.7/threading.py:870:run
[2022-05-24 02:54:28,809] {subprocess.py:92} INFO - /home/***/.local/lib/python3.7/site-packages/twisted/_threads/_threadworker.py:47:work
[2022-05-24 02:54:28,809] {subprocess.py:92} INFO - /home/***/.local/lib/python3.7/site-packages/twisted/_threads/_team.py:182:doWork
[2022-05-24 02:54:28,809] {subprocess.py:92} INFO - --- <exception caught here> ---
[2022-05-24 02:54:28,809] {subprocess.py:92} INFO - /home/***/.local/lib/python3.7/site-packages/twisted/python/threadpool.py:244:inContext
[2022-05-24 02:54:28,809] {subprocess.py:92} INFO - /home/***/.local/lib/python3.7/site-packages/twisted/python/threadpool.py:261:<lambda>
[2022-05-24 02:54:28,809] {subprocess.py:92} INFO - /home/***/.local/lib/python3.7/site-packages/twisted/python/context.py:117:callWithContext
[2022-05-24 02:54:28,809] {subprocess.py:92} INFO - /home/***/.local/lib/python3.7/site-packages/twisted/python/context.py:82:callWithContext
[2022-05-24 02:54:28,810] {subprocess.py:92} INFO - /home/***/.local/lib/python3.7/site-packages/twisted/enterprise/adbapi.py:440:_runInteraction
[2022-05-24 02:54:28,810] {subprocess.py:92} INFO - /home/***/.local/lib/python3.7/site-packages/twisted/enterprise/adbapi.py:34:__init__
[2022-05-24 02:54:28,810] {subprocess.py:92} INFO - /home/***/.local/lib/python3.7/site-packages/twisted/enterprise/adbapi.py:71:reconnect
[2022-05-24 02:54:28,810] {subprocess.py:92} INFO - /home/***/.local/lib/python3.7/site-packages/twisted/enterprise/adbapi.py:410:connect
[2022-05-24 02:54:28,810] {subprocess.py:92} INFO - /home/***/.local/lib/python3.7/site-packages/MySQLdb/__init__.py:123:Connect
[2022-05-24 02:54:28,810] {subprocess.py:92} INFO - /home/***/.local/lib/python3.7/site-packages/MySQLdb/connections.py:185:__init__
[2022-05-24 02:54:28,810] {subprocess.py:92} INFO - ]
[2022-05-24 02:54:28,810] {subprocess.py:92} INFO - 2022-05-24 02:54:28 [root] ERROR: [Failure instance: Traceback: <class 'MySQLdb._exceptions.OperationalError'>: (2003, "Can't connect to MySQL server on '127.20.0.1:3306' (111)")
[2022-05-24 02:54:28,810] {subprocess.py:92} INFO - /usr/local/lib/python3.7/threading.py:926:_bootstrap_inner
[2022-05-24 02:54:28,810] {subprocess.py:92} INFO - /usr/local/lib/python3.7/threading.py:870:run
[2022-05-24 02:54:28,810] {subprocess.py:92} INFO - /home/***/.local/lib/python3.7/site-packages/twisted/_threads/_threadworker.py:47:work
[2022-05-24 02:54:28,810] {subprocess.py:92} INFO - /home/***/.local/lib/python3.7/site-packages/twisted/_threads/_team.py:182:doWork
[2022-05-24 02:54:28,810] {subprocess.py:92} INFO - --- <exception caught here> ---
[2022-05-24 02:54:28,810] {subprocess.py:92} INFO - /home/***/.local/lib/python3.7/site-packages/twisted/python/threadpool.py:244:inContext
[2022-05-24 02:54:28,811] {subprocess.py:92} INFO - /home/***/.local/lib/python3.7/site-packages/twisted/python/threadpool.py:261:<lambda>
[2022-05-24 02:54:28,811] {subprocess.py:92} INFO - /home/***/.local/lib/python3.7/site-packages/twisted/python/context.py:117:callWithContext
[2022-05-24 02:54:28,811] {subprocess.py:92} INFO - /home/***/.local/lib/python3.7/site-packages/twisted/python/context.py:82:callWithContext
[2022-05-24 02:54:28,811] {subprocess.py:92} INFO - /home/***/.local/lib/python3.7/site-packages/twisted/enterprise/adbapi.py:440:_runInteraction
[2022-05-24 02:54:28,811] {subprocess.py:92} INFO - /home/***/.local/lib/python3.7/site-packages/twisted/enterprise/adbapi.py:34:__init__
[2022-05-24 02:54:28,811] {subprocess.py:92} INFO - /home/***/.local/lib/python3.7/site-packages/twisted/enterprise/adbapi.py:71:reconnect
[2022-05-24 02:54:28,811] {subprocess.py:92} INFO - /home/***/.local/lib/python3.7/site-packages/twisted/enterprise/adbapi.py:410:connect
[2022-05-24 02:54:28,811] {subprocess.py:92} INFO - /home/***/.local/lib/python3.7/site-packages/MySQLdb/__init__.py:123:Connect
[2022-05-24 02:54:28,811] {subprocess.py:92} INFO - /home/***/.local/lib/python3.7/site-packages/MySQLdb/connections.py:185:__init__
[2022-05-24 02:54:28,811] {subprocess.py:92} INFO - ]
[2022-05-24 02:54:28,811] {subprocess.py:92} INFO - 2022-05-24 02:54:28 [root] ERROR: [Failure instance: Traceback: <class 'MySQLdb._exceptions.OperationalError'>: (2003, "Can't connect to MySQL server on '127.20.0.1:3306' (111)")
[2022-05-24 02:54:28,811] {subprocess.py:92} INFO - /usr/local/lib/python3.7/threading.py:926:_bootstrap_inner
[2022-05-24 02:54:28,811] {subprocess.py:92} INFO - /usr/local/lib/python3.7/threading.py:870:run
[2022-05-24 02:54:28,811] {subprocess.py:92} INFO - /home/***/.local/lib/python3.7/site-packages/twisted/_threads/_threadworker.py:47:work
[2022-05-24 02:54:28,811] {subprocess.py:92} INFO - /home/***/.local/lib/python3.7/site-packages/twisted/_threads/_team.py:182:doWork
[2022-05-24 02:54:28,812] {subprocess.py:92} INFO - --- <exception caught here> ---
[2022-05-24 02:54:28,812] {subprocess.py:92} INFO - /home/***/.local/lib/python3.7/site-packages/twisted/python/threadpool.py:244:inContext
[2022-05-24 02:54:28,812] {subprocess.py:92} INFO - /home/***/.local/lib/python3.7/site-packages/twisted/python/threadpool.py:261:<lambda>
[2022-05-24 02:54:28,812] {subprocess.py:92} INFO - /home/***/.local/lib/python3.7/site-packages/twisted/python/context.py:117:callWithContext
[2022-05-24 02:54:28,812] {subprocess.py:92} INFO - /home/***/.local/lib/python3.7/site-packages/twisted/python/context.py:82:callWithContext
[2022-05-24 02:54:28,812] {subprocess.py:92} INFO - /home/***/.local/lib/python3.7/site-packages/twisted/enterprise/adbapi.py:440:_runInteraction
[2022-05-24 02:54:28,812] {subprocess.py:92} INFO - /home/***/.local/lib/python3.7/site-packages/twisted/enterprise/adbapi.py:34:__init__
[2022-05-24 02:54:28,812] {subprocess.py:92} INFO - /home/***/.local/lib/python3.7/site-packages/twisted/enterprise/adbapi.py:71:reconnect
[2022-05-24 02:54:28,812] {subprocess.py:92} INFO - /home/***/.local/lib/python3.7/site-packages/twisted/enterprise/adbapi.py:410:connect
[2022-05-24 02:54:28,812] {subprocess.py:92} INFO - /home/***/.local/lib/python3.7/site-packages/MySQLdb/__init__.py:123:Connect
[2022-05-24 02:54:28,812] {subprocess.py:92} INFO - /home/***/.local/lib/python3.7/site-packages/MySQLdb/connections.py:185:__init__
[2022-05-24 02:54:28,812] {subprocess.py:92} INFO - ]
[2022-05-24 02:54:28,812] {subprocess.py:92} INFO - 2022-05-24 02:54:28 [root] ERROR: [Failure instance: Traceback: <class 'MySQLdb._exceptions.OperationalError'>: (2003, "Can't connect to MySQL server on '127.20.0.1:3306' (111)")
[2022-05-24 02:54:28,812] {subprocess.py:92} INFO - /usr/local/lib/python3.7/threading.py:926:_bootstrap_inner
[2022-05-24 02:54:28,813] {subprocess.py:92} INFO - /usr/local/lib/python3.7/threading.py:870:run
[2022-05-24 02:54:28,813] {subprocess.py:92} INFO - /home/***/.local/lib/python3.7/site-packages/twisted/_threads/_threadworker.py:47:work
[2022-05-24 02:54:28,813] {subprocess.py:92} INFO - /home/***/.local/lib/python3.7/site-packages/twisted/_threads/_team.py:182:doWork
[2022-05-24 02:54:28,813] {subprocess.py:92} INFO - --- <exception caught here> ---
[2022-05-24 02:54:28,813] {subprocess.py:92} INFO - /home/***/.local/lib/python3.7/site-packages/twisted/python/threadpool.py:244:inContext
[2022-05-24 02:54:28,813] {subprocess.py:92} INFO - /home/***/.local/lib/python3.7/site-packages/twisted/python/threadpool.py:261:<lambda>
[2022-05-24 02:54:28,813] {subprocess.py:92} INFO - /home/***/.local/lib/python3.7/site-packages/twisted/python/context.py:117:callWithContext
[2022-05-24 02:54:28,813] {subprocess.py:92} INFO - /home/***/.local/lib/python3.7/site-packages/twisted/python/context.py:82:callWithContext
[2022-05-24 02:54:28,813] {subprocess.py:92} INFO - /home/***/.local/lib/python3.7/site-packages/twisted/enterprise/adbapi.py:440:_runInteraction
[2022-05-24 02:54:28,813] {subprocess.py:92} INFO - /home/***/.local/lib/python3.7/site-packages/twisted/enterprise/adbapi.py:34:__init__
[2022-05-24 02:54:28,813] {subprocess.py:92} INFO - /home/***/.local/lib/python3.7/site-packages/twisted/enterprise/adbapi.py:71:reconnect
[2022-05-24 02:54:28,813] {subprocess.py:92} INFO - /home/***/.local/lib/python3.7/site-packages/twisted/enterprise/adbapi.py:410:connect
[2022-05-24 02:54:28,813] {subprocess.py:92} INFO - /home/***/.local/lib/python3.7/site-packages/MySQLdb/__init__.py:123:Connect
[2022-05-24 02:54:28,813] {subprocess.py:92} INFO - /home/***/.local/lib/python3.7/site-packages/MySQLdb/connections.py:185:__init__
[2022-05-24 02:54:28,813] {subprocess.py:92} INFO - ]
[2022-05-24 02:54:33,866] {subprocess.py:92} INFO - 2022-05-24 02:54:33 [scrapy.core.engine] DEBUG: Crawled (200) <GET https://www.traveloka.com/vi-vn/hotel/vietnam/landmark/ci-dm-market-91566985926868> (referer: https://www.traveloka.com/vi-vn/hotel/vietnam/city/ha-long-city-30010278)
[2022-05-24 02:54:33,996] {subprocess.py:92} INFO - 2022-05-24 02:54:33 [scrapy.core.scraper] DEBUG: Scraped from <200 https://www.traveloka.com/vi-vn/hotel/vietnam/landmark/ci-dm-market-91566985926868>
[2022-05-24 02:54:33,996] {subprocess.py:92} INFO - {'hotel_address': 'Tien Ong, Bai Chay Ward, phường Bãi Cháy, Thành phố Hạ '
[2022-05-24 02:54:33,996] {subprocess.py:92} INFO -                   'Long, Tỉnh Quảng Ninh, Việt Nam, 200000',
[2022-05-24 02:54:33,996] {subprocess.py:92} INFO -  'hotel_name': 'Khách sạn Song Loc Luxury Ha Long',
[2022-05-24 02:54:33,996] {subprocess.py:92} INFO -  'hotel_point_review': '8.7',
[2022-05-24 02:54:33,996] {subprocess.py:92} INFO -  'hotel_rating': '4',
[2022-05-24 02:54:33,996] {subprocess.py:92} INFO -  'hotel_sum_review': '70',
[2022-05-24 02:54:33,996] {subprocess.py:92} INFO -  'hotel_url': 'https://www.traveloka.com/vi-vn/hotel/vietnam/song-loc-luxury-ha-long-3000020003910'}
[2022-05-24 02:54:33,997] {subprocess.py:92} INFO - 2022-05-24 02:54:33 [scrapy.core.scraper] DEBUG: Scraped from <200 https://www.traveloka.com/vi-vn/hotel/vietnam/landmark/ci-dm-market-91566985926868>
[2022-05-24 02:54:33,997] {subprocess.py:92} INFO - {'hotel_address': 'Số 3, Phan Bội Châu, Phường Bãi Cháy, phường Bãi Cháy, '
[2022-05-24 02:54:33,997] {subprocess.py:92} INFO -                   'Thành phố Hạ Long, Tỉnh Quảng Ninh, Việt Nam, 200000',
[2022-05-24 02:54:33,998] {subprocess.py:92} INFO -  'hotel_name': 'Khách sạn Halong Seoul',
[2022-05-24 02:54:33,998] {subprocess.py:92} INFO -  'hotel_point_review': '8.4',
[2022-05-24 02:54:33,998] {subprocess.py:92} INFO -  'hotel_rating': '3',
[2022-05-24 02:54:33,998] {subprocess.py:92} INFO -  'hotel_sum_review': '51',
[2022-05-24 02:54:33,998] {subprocess.py:92} INFO -  'hotel_url': 'https://www.traveloka.com/vi-vn/hotel/vietnam/halong-seoul-hotel-3000020000814'}
[2022-05-24 02:54:33,999] {subprocess.py:92} INFO - 2022-05-24 02:54:33 [scrapy.core.scraper] DEBUG: Scraped from <200 https://www.traveloka.com/vi-vn/hotel/vietnam/landmark/ci-dm-market-91566985926868>
[2022-05-24 02:54:33,999] {subprocess.py:92} INFO - {'hotel_address': 'Đông Hùng Thắng, Bãi Cháy, phường Bãi Cháy, Thành phố Hạ '
[2022-05-24 02:54:33,999] {subprocess.py:92} INFO -                   'Long, Tỉnh Quảng Ninh, Việt Nam, 200000',
[2022-05-24 02:54:33,999] {subprocess.py:92} INFO -  'hotel_name': 'Crown Hotel',
[2022-05-24 02:54:33,999] {subprocess.py:92} INFO -  'hotel_point_review': '7.4',
[2022-05-24 02:54:33,999] {subprocess.py:92} INFO -  'hotel_rating': '3',
[2022-05-24 02:54:33,999] {subprocess.py:92} INFO -  'hotel_sum_review': '58',
[2022-05-24 02:54:33,999] {subprocess.py:92} INFO -  'hotel_url': 'https://www.traveloka.com/vi-vn/hotel/vietnam/crown-hotel-1000000553995'}
[2022-05-24 02:54:34,000] {subprocess.py:92} INFO - 2022-05-24 02:54:34 [scrapy.core.scraper] DEBUG: Scraped from <200 https://www.traveloka.com/vi-vn/hotel/vietnam/landmark/ci-dm-market-91566985926868>
[2022-05-24 02:54:34,000] {subprocess.py:92} INFO - {'hotel_address': 'No 17 Tien Ong Street, Bai Chay Ward, phường Bãi Cháy, '
[2022-05-24 02:54:34,000] {subprocess.py:92} INFO -                   'Thành phố Hạ Long, Tỉnh Quảng Ninh, Việt Nam, 01119',
[2022-05-24 02:54:34,000] {subprocess.py:92} INFO -  'hotel_name': 'Moon Hotel',
[2022-05-24 02:54:34,001] {subprocess.py:92} INFO -  'hotel_point_review': '7.9',
[2022-05-24 02:54:34,001] {subprocess.py:92} INFO -  'hotel_rating': '3.5',
[2022-05-24 02:54:34,001] {subprocess.py:92} INFO -  'hotel_sum_review': '137',
[2022-05-24 02:54:34,001] {subprocess.py:92} INFO -  'hotel_url': 'https://www.traveloka.com/vi-vn/hotel/vietnam/moon-hotel-9000000547889'}
[2022-05-24 02:54:34,001] {subprocess.py:92} INFO - 2022-05-24 02:54:34 [scrapy.core.scraper] DEBUG: Scraped from <200 https://www.traveloka.com/vi-vn/hotel/vietnam/landmark/ci-dm-market-91566985926868>
[2022-05-24 02:54:34,002] {subprocess.py:92} INFO - {'hotel_address': 'Số 15 Tiên Ông, phường Bãi Cháy, Thành phố Hạ Long, Tỉnh '
[2022-05-24 02:54:34,002] {subprocess.py:92} INFO -                   'Quảng Ninh, Việt Nam, 200000',
[2022-05-24 02:54:34,002] {subprocess.py:92} INFO -  'hotel_name': 'Khách sạn Galaxy Hạ Long',
[2022-05-24 02:54:34,002] {subprocess.py:92} INFO -  'hotel_point_review': '8.3',
[2022-05-24 02:54:34,002] {subprocess.py:92} INFO -  'hotel_rating': '4',
[2022-05-24 02:54:34,002] {subprocess.py:92} INFO -  'hotel_sum_review': '43',
[2022-05-24 02:54:34,002] {subprocess.py:92} INFO -  'hotel_url': 'https://www.traveloka.com/vi-vn/hotel/vietnam/galaxy-halong-hotel-1000000922289'}
[2022-05-24 02:54:34,003] {subprocess.py:92} INFO - 2022-05-24 02:54:34 [scrapy.core.scraper] DEBUG: Scraped from <200 https://www.traveloka.com/vi-vn/hotel/vietnam/landmark/ci-dm-market-91566985926868>
[2022-05-24 02:54:34,003] {subprocess.py:92} INFO - {'hotel_address': 'Số 5, Lô 20, Đường Hoàng Quốc Việt, QH Khu Dân Cư Du Lịch '
[2022-05-24 02:54:34,003] {subprocess.py:92} INFO -                   'Đông Hùng Thắng, phường Bãi Cháy, Thành phố Hạ Long, Tỉnh '
[2022-05-24 02:54:34,003] {subprocess.py:92} INFO -                   'Quảng Ninh, Việt Nam, 200000',
[2022-05-24 02:54:34,003] {subprocess.py:92} INFO -  'hotel_name': 'Khách Sạn Ha Long Marina',
[2022-05-24 02:54:34,003] {subprocess.py:92} INFO -  'hotel_point_review': '8.4',
[2022-05-24 02:54:34,003] {subprocess.py:92} INFO -  'hotel_rating': '4',
[2022-05-24 02:54:34,003] {subprocess.py:92} INFO -  'hotel_sum_review': '19',
[2022-05-24 02:54:34,003] {subprocess.py:92} INFO -  'hotel_url': 'https://www.traveloka.com/vi-vn/hotel/vietnam/ha-long-marina-hotel-1000001791455'}
[2022-05-24 02:54:34,004] {subprocess.py:92} INFO - 2022-05-24 02:54:34 [scrapy.core.scraper] DEBUG: Scraped from <200 https://www.traveloka.com/vi-vn/hotel/vietnam/landmark/ci-dm-market-91566985926868>
[2022-05-24 02:54:34,005] {subprocess.py:92} INFO - {'hotel_address': 'Số 01, Phan Bội Châu, tổ 5, khu 9, Bãi Cháy, phường Bãi '
[2022-05-24 02:54:34,005] {subprocess.py:92} INFO -                   'Cháy, Thành phố Hạ Long, Tỉnh Quảng Ninh, Việt Nam, 200000',
[2022-05-24 02:54:34,005] {subprocess.py:92} INFO -  'hotel_name': 'Khách sạn Phoenix Hạ Long',
[2022-05-24 02:54:34,005] {subprocess.py:92} INFO -  'hotel_point_review': '9.1',
[2022-05-24 02:54:34,005] {subprocess.py:92} INFO -  'hotel_rating': '3',
[2022-05-24 02:54:34,005] {subprocess.py:92} INFO -  'hotel_sum_review': '15',
[2022-05-24 02:54:34,005] {subprocess.py:92} INFO -  'hotel_url': 'https://www.traveloka.com/vi-vn/hotel/vietnam/phoenix-hotel-ha-long-9000000986831'}
[2022-05-24 02:54:34,007] {subprocess.py:92} INFO - 2022-05-24 02:54:34 [root] ERROR: [Failure instance: Traceback: <class 'MySQLdb._exceptions.OperationalError'>: (2003, "Can't connect to MySQL server on '127.20.0.1:3306' (111)")
[2022-05-24 02:54:34,007] {subprocess.py:92} INFO - /usr/local/lib/python3.7/threading.py:926:_bootstrap_inner
[2022-05-24 02:54:34,007] {subprocess.py:92} INFO - /usr/local/lib/python3.7/threading.py:870:run
[2022-05-24 02:54:34,007] {subprocess.py:92} INFO - /home/***/.local/lib/python3.7/site-packages/twisted/_threads/_threadworker.py:47:work
[2022-05-24 02:54:34,007] {subprocess.py:92} INFO - /home/***/.local/lib/python3.7/site-packages/twisted/_threads/_team.py:182:doWork
[2022-05-24 02:54:34,007] {subprocess.py:92} INFO - --- <exception caught here> ---
[2022-05-24 02:54:34,007] {subprocess.py:92} INFO - /home/***/.local/lib/python3.7/site-packages/twisted/python/threadpool.py:244:inContext
[2022-05-24 02:54:34,008] {subprocess.py:92} INFO - /home/***/.local/lib/python3.7/site-packages/twisted/python/threadpool.py:261:<lambda>
[2022-05-24 02:54:34,008] {subprocess.py:92} INFO - /home/***/.local/lib/python3.7/site-packages/twisted/python/context.py:117:callWithContext
[2022-05-24 02:54:34,008] {subprocess.py:92} INFO - /home/***/.local/lib/python3.7/site-packages/twisted/python/context.py:82:callWithContext
[2022-05-24 02:54:34,008] {subprocess.py:92} INFO - /home/***/.local/lib/python3.7/site-packages/twisted/enterprise/adbapi.py:440:_runInteraction
[2022-05-24 02:54:34,008] {subprocess.py:92} INFO - /home/***/.local/lib/python3.7/site-packages/twisted/enterprise/adbapi.py:34:__init__
[2022-05-24 02:54:34,008] {subprocess.py:92} INFO - /home/***/.local/lib/python3.7/site-packages/twisted/enterprise/adbapi.py:71:reconnect
[2022-05-24 02:54:34,008] {subprocess.py:92} INFO - /home/***/.local/lib/python3.7/site-packages/twisted/enterprise/adbapi.py:410:connect
[2022-05-24 02:54:34,008] {subprocess.py:92} INFO - /home/***/.local/lib/python3.7/site-packages/MySQLdb/__init__.py:123:Connect
[2022-05-24 02:54:34,008] {subprocess.py:92} INFO - /home/***/.local/lib/python3.7/site-packages/MySQLdb/connections.py:185:__init__
[2022-05-24 02:54:34,008] {subprocess.py:92} INFO - ]
[2022-05-24 02:54:34,008] {subprocess.py:92} INFO - 2022-05-24 02:54:34 [root] ERROR: [Failure instance: Traceback: <class 'MySQLdb._exceptions.OperationalError'>: (2003, "Can't connect to MySQL server on '127.20.0.1:3306' (111)")
[2022-05-24 02:54:34,008] {subprocess.py:92} INFO - /usr/local/lib/python3.7/threading.py:926:_bootstrap_inner
[2022-05-24 02:54:34,008] {subprocess.py:92} INFO - /usr/local/lib/python3.7/threading.py:870:run
[2022-05-24 02:54:34,008] {subprocess.py:92} INFO - /home/***/.local/lib/python3.7/site-packages/twisted/_threads/_threadworker.py:47:work
[2022-05-24 02:54:34,009] {subprocess.py:92} INFO - /home/***/.local/lib/python3.7/site-packages/twisted/_threads/_team.py:182:doWork
[2022-05-24 02:54:34,009] {subprocess.py:92} INFO - --- <exception caught here> ---
[2022-05-24 02:54:34,009] {subprocess.py:92} INFO - /home/***/.local/lib/python3.7/site-packages/twisted/python/threadpool.py:244:inContext
[2022-05-24 02:54:34,009] {subprocess.py:92} INFO - /home/***/.local/lib/python3.7/site-packages/twisted/python/threadpool.py:261:<lambda>
[2022-05-24 02:54:34,009] {subprocess.py:92} INFO - /home/***/.local/lib/python3.7/site-packages/twisted/python/context.py:117:callWithContext
[2022-05-24 02:54:34,009] {subprocess.py:92} INFO - /home/***/.local/lib/python3.7/site-packages/twisted/python/context.py:82:callWithContext
[2022-05-24 02:54:34,009] {subprocess.py:92} INFO - /home/***/.local/lib/python3.7/site-packages/twisted/enterprise/adbapi.py:440:_runInteraction
[2022-05-24 02:54:34,009] {subprocess.py:92} INFO - /home/***/.local/lib/python3.7/site-packages/twisted/enterprise/adbapi.py:34:__init__
[2022-05-24 02:54:34,009] {subprocess.py:92} INFO - /home/***/.local/lib/python3.7/site-packages/twisted/enterprise/adbapi.py:71:reconnect
[2022-05-24 02:54:34,009] {subprocess.py:92} INFO - /home/***/.local/lib/python3.7/site-packages/twisted/enterprise/adbapi.py:410:connect
[2022-05-24 02:54:34,009] {subprocess.py:92} INFO - /home/***/.local/lib/python3.7/site-packages/MySQLdb/__init__.py:123:Connect
[2022-05-24 02:54:34,009] {subprocess.py:92} INFO - /home/***/.local/lib/python3.7/site-packages/MySQLdb/connections.py:185:__init__
[2022-05-24 02:54:34,009] {subprocess.py:92} INFO - ]
[2022-05-24 02:54:34,010] {subprocess.py:92} INFO - 2022-05-24 02:54:34 [root] ERROR: [Failure instance: Traceback: <class 'MySQLdb._exceptions.OperationalError'>: (2003, "Can't connect to MySQL server on '127.20.0.1:3306' (111)")
[2022-05-24 02:54:34,010] {subprocess.py:92} INFO - /usr/local/lib/python3.7/threading.py:926:_bootstrap_inner
[2022-05-24 02:54:34,010] {subprocess.py:92} INFO - /usr/local/lib/python3.7/threading.py:870:run
[2022-05-24 02:54:34,010] {subprocess.py:92} INFO - /home/***/.local/lib/python3.7/site-packages/twisted/_threads/_threadworker.py:47:work
[2022-05-24 02:54:34,010] {subprocess.py:92} INFO - /home/***/.local/lib/python3.7/site-packages/twisted/_threads/_team.py:182:doWork
[2022-05-24 02:54:34,010] {subprocess.py:92} INFO - --- <exception caught here> ---
[2022-05-24 02:54:34,010] {subprocess.py:92} INFO - /home/***/.local/lib/python3.7/site-packages/twisted/python/threadpool.py:244:inContext
[2022-05-24 02:54:34,010] {subprocess.py:92} INFO - /home/***/.local/lib/python3.7/site-packages/twisted/python/threadpool.py:261:<lambda>
[2022-05-24 02:54:34,010] {subprocess.py:92} INFO - /home/***/.local/lib/python3.7/site-packages/twisted/python/context.py:117:callWithContext
[2022-05-24 02:54:34,010] {subprocess.py:92} INFO - /home/***/.local/lib/python3.7/site-packages/twisted/python/context.py:82:callWithContext
[2022-05-24 02:54:34,010] {subprocess.py:92} INFO - /home/***/.local/lib/python3.7/site-packages/twisted/enterprise/adbapi.py:440:_runInteraction
[2022-05-24 02:54:34,010] {subprocess.py:92} INFO - /home/***/.local/lib/python3.7/site-packages/twisted/enterprise/adbapi.py:34:__init__
[2022-05-24 02:54:34,010] {subprocess.py:92} INFO - /home/***/.local/lib/python3.7/site-packages/twisted/enterprise/adbapi.py:71:reconnect
[2022-05-24 02:54:34,010] {subprocess.py:92} INFO - /home/***/.local/lib/python3.7/site-packages/twisted/enterprise/adbapi.py:410:connect
[2022-05-24 02:54:34,011] {subprocess.py:92} INFO - /home/***/.local/lib/python3.7/site-packages/MySQLdb/__init__.py:123:Connect
[2022-05-24 02:54:34,011] {subprocess.py:92} INFO - /home/***/.local/lib/python3.7/site-packages/MySQLdb/connections.py:185:__init__
[2022-05-24 02:54:34,011] {subprocess.py:92} INFO - ]
[2022-05-24 02:54:34,011] {subprocess.py:92} INFO - 2022-05-24 02:54:34 [root] ERROR: [Failure instance: Traceback: <class 'MySQLdb._exceptions.OperationalError'>: (2003, "Can't connect to MySQL server on '127.20.0.1:3306' (111)")
[2022-05-24 02:54:34,011] {subprocess.py:92} INFO - /usr/local/lib/python3.7/threading.py:926:_bootstrap_inner
[2022-05-24 02:54:34,011] {subprocess.py:92} INFO - /usr/local/lib/python3.7/threading.py:870:run
[2022-05-24 02:54:34,011] {subprocess.py:92} INFO - /home/***/.local/lib/python3.7/site-packages/twisted/_threads/_threadworker.py:47:work
[2022-05-24 02:54:34,011] {subprocess.py:92} INFO - /home/***/.local/lib/python3.7/site-packages/twisted/_threads/_team.py:182:doWork
[2022-05-24 02:54:34,011] {subprocess.py:92} INFO - --- <exception caught here> ---
[2022-05-24 02:54:34,011] {subprocess.py:92} INFO - /home/***/.local/lib/python3.7/site-packages/twisted/python/threadpool.py:244:inContext
[2022-05-24 02:54:34,011] {subprocess.py:92} INFO - /home/***/.local/lib/python3.7/site-packages/twisted/python/threadpool.py:261:<lambda>
[2022-05-24 02:54:34,011] {subprocess.py:92} INFO - /home/***/.local/lib/python3.7/site-packages/twisted/python/context.py:117:callWithContext
[2022-05-24 02:54:34,011] {subprocess.py:92} INFO - /home/***/.local/lib/python3.7/site-packages/twisted/python/context.py:82:callWithContext
[2022-05-24 02:54:34,011] {subprocess.py:92} INFO - /home/***/.local/lib/python3.7/site-packages/twisted/enterprise/adbapi.py:440:_runInteraction
[2022-05-24 02:54:34,011] {subprocess.py:92} INFO - /home/***/.local/lib/python3.7/site-packages/twisted/enterprise/adbapi.py:34:__init__
[2022-05-24 02:54:34,011] {subprocess.py:92} INFO - /home/***/.local/lib/python3.7/site-packages/twisted/enterprise/adbapi.py:71:reconnect
[2022-05-24 02:54:34,012] {subprocess.py:92} INFO - /home/***/.local/lib/python3.7/site-packages/twisted/enterprise/adbapi.py:410:connect
[2022-05-24 02:54:34,012] {subprocess.py:92} INFO - /home/***/.local/lib/python3.7/site-packages/MySQLdb/__init__.py:123:Connect
[2022-05-24 02:54:34,012] {subprocess.py:92} INFO - /home/***/.local/lib/python3.7/site-packages/MySQLdb/connections.py:185:__init__
[2022-05-24 02:54:34,012] {subprocess.py:92} INFO - ]
[2022-05-24 02:54:34,012] {subprocess.py:92} INFO - 2022-05-24 02:54:34 [root] ERROR: [Failure instance: Traceback: <class 'MySQLdb._exceptions.OperationalError'>: (2003, "Can't connect to MySQL server on '127.20.0.1:3306' (111)")
[2022-05-24 02:54:34,012] {subprocess.py:92} INFO - /usr/local/lib/python3.7/threading.py:926:_bootstrap_inner
[2022-05-24 02:54:34,012] {subprocess.py:92} INFO - /usr/local/lib/python3.7/threading.py:870:run
[2022-05-24 02:54:34,012] {subprocess.py:92} INFO - /home/***/.local/lib/python3.7/site-packages/twisted/_threads/_threadworker.py:47:work
[2022-05-24 02:54:34,012] {subprocess.py:92} INFO - /home/***/.local/lib/python3.7/site-packages/twisted/_threads/_team.py:182:doWork
[2022-05-24 02:54:34,012] {subprocess.py:92} INFO - --- <exception caught here> ---
[2022-05-24 02:54:34,012] {subprocess.py:92} INFO - /home/***/.local/lib/python3.7/site-packages/twisted/python/threadpool.py:244:inContext
[2022-05-24 02:54:34,012] {subprocess.py:92} INFO - /home/***/.local/lib/python3.7/site-packages/twisted/python/threadpool.py:261:<lambda>
[2022-05-24 02:54:34,012] {subprocess.py:92} INFO - /home/***/.local/lib/python3.7/site-packages/twisted/python/context.py:117:callWithContext
[2022-05-24 02:54:34,012] {subprocess.py:92} INFO - /home/***/.local/lib/python3.7/site-packages/twisted/python/context.py:82:callWithContext
[2022-05-24 02:54:34,012] {subprocess.py:92} INFO - /home/***/.local/lib/python3.7/site-packages/twisted/enterprise/adbapi.py:440:_runInteraction
[2022-05-24 02:54:34,012] {subprocess.py:92} INFO - /home/***/.local/lib/python3.7/site-packages/twisted/enterprise/adbapi.py:34:__init__
[2022-05-24 02:54:34,013] {subprocess.py:92} INFO - /home/***/.local/lib/python3.7/site-packages/twisted/enterprise/adbapi.py:71:reconnect
[2022-05-24 02:54:34,013] {subprocess.py:92} INFO - /home/***/.local/lib/python3.7/site-packages/twisted/enterprise/adbapi.py:410:connect
[2022-05-24 02:54:34,013] {subprocess.py:92} INFO - /home/***/.local/lib/python3.7/site-packages/MySQLdb/__init__.py:123:Connect
[2022-05-24 02:54:34,013] {subprocess.py:92} INFO - /home/***/.local/lib/python3.7/site-packages/MySQLdb/connections.py:185:__init__
[2022-05-24 02:54:34,013] {subprocess.py:92} INFO - ]
[2022-05-24 02:54:34,013] {subprocess.py:92} INFO - 2022-05-24 02:54:34 [root] ERROR: [Failure instance: Traceback: <class 'MySQLdb._exceptions.OperationalError'>: (2003, "Can't connect to MySQL server on '127.20.0.1:3306' (111)")
[2022-05-24 02:54:34,013] {subprocess.py:92} INFO - /usr/local/lib/python3.7/threading.py:926:_bootstrap_inner
[2022-05-24 02:54:34,013] {subprocess.py:92} INFO - /usr/local/lib/python3.7/threading.py:870:run
[2022-05-24 02:54:34,013] {subprocess.py:92} INFO - /home/***/.local/lib/python3.7/site-packages/twisted/_threads/_threadworker.py:47:work
[2022-05-24 02:54:34,013] {subprocess.py:92} INFO - /home/***/.local/lib/python3.7/site-packages/twisted/_threads/_team.py:182:doWork
[2022-05-24 02:54:34,013] {subprocess.py:92} INFO - --- <exception caught here> ---
[2022-05-24 02:54:34,013] {subprocess.py:92} INFO - /home/***/.local/lib/python3.7/site-packages/twisted/python/threadpool.py:244:inContext
[2022-05-24 02:54:34,013] {subprocess.py:92} INFO - /home/***/.local/lib/python3.7/site-packages/twisted/python/threadpool.py:261:<lambda>
[2022-05-24 02:54:34,013] {subprocess.py:92} INFO - /home/***/.local/lib/python3.7/site-packages/twisted/python/context.py:117:callWithContext
[2022-05-24 02:54:34,013] {subprocess.py:92} INFO - /home/***/.local/lib/python3.7/site-packages/twisted/python/context.py:82:callWithContext
[2022-05-24 02:54:34,014] {subprocess.py:92} INFO - /home/***/.local/lib/python3.7/site-packages/twisted/enterprise/adbapi.py:440:_runInteraction
[2022-05-24 02:54:34,014] {subprocess.py:92} INFO - /home/***/.local/lib/python3.7/site-packages/twisted/enterprise/adbapi.py:34:__init__
[2022-05-24 02:54:34,014] {subprocess.py:92} INFO - /home/***/.local/lib/python3.7/site-packages/twisted/enterprise/adbapi.py:71:reconnect
[2022-05-24 02:54:34,014] {subprocess.py:92} INFO - /home/***/.local/lib/python3.7/site-packages/twisted/enterprise/adbapi.py:410:connect
[2022-05-24 02:54:34,014] {subprocess.py:92} INFO - /home/***/.local/lib/python3.7/site-packages/MySQLdb/__init__.py:123:Connect
[2022-05-24 02:54:34,014] {subprocess.py:92} INFO - /home/***/.local/lib/python3.7/site-packages/MySQLdb/connections.py:185:__init__
[2022-05-24 02:54:34,014] {subprocess.py:92} INFO - ]
[2022-05-24 02:54:34,014] {subprocess.py:92} INFO - 2022-05-24 02:54:34 [root] ERROR: [Failure instance: Traceback: <class 'MySQLdb._exceptions.OperationalError'>: (2003, "Can't connect to MySQL server on '127.20.0.1:3306' (111)")
[2022-05-24 02:54:34,014] {subprocess.py:92} INFO - /usr/local/lib/python3.7/threading.py:926:_bootstrap_inner
[2022-05-24 02:54:34,014] {subprocess.py:92} INFO - /usr/local/lib/python3.7/threading.py:870:run
[2022-05-24 02:54:34,014] {subprocess.py:92} INFO - /home/***/.local/lib/python3.7/site-packages/twisted/_threads/_threadworker.py:47:work
[2022-05-24 02:54:34,014] {subprocess.py:92} INFO - /home/***/.local/lib/python3.7/site-packages/twisted/_threads/_team.py:182:doWork
[2022-05-24 02:54:34,014] {subprocess.py:92} INFO - --- <exception caught here> ---
[2022-05-24 02:54:34,014] {subprocess.py:92} INFO - /home/***/.local/lib/python3.7/site-packages/twisted/python/threadpool.py:244:inContext
[2022-05-24 02:54:34,014] {subprocess.py:92} INFO - /home/***/.local/lib/python3.7/site-packages/twisted/python/threadpool.py:261:<lambda>
[2022-05-24 02:54:34,014] {subprocess.py:92} INFO - /home/***/.local/lib/python3.7/site-packages/twisted/python/context.py:117:callWithContext
[2022-05-24 02:54:34,015] {subprocess.py:92} INFO - /home/***/.local/lib/python3.7/site-packages/twisted/python/context.py:82:callWithContext
[2022-05-24 02:54:34,015] {subprocess.py:92} INFO - /home/***/.local/lib/python3.7/site-packages/twisted/enterprise/adbapi.py:440:_runInteraction
[2022-05-24 02:54:34,015] {subprocess.py:92} INFO - /home/***/.local/lib/python3.7/site-packages/twisted/enterprise/adbapi.py:34:__init__
[2022-05-24 02:54:34,015] {subprocess.py:92} INFO - /home/***/.local/lib/python3.7/site-packages/twisted/enterprise/adbapi.py:71:reconnect
[2022-05-24 02:54:34,015] {subprocess.py:92} INFO - /home/***/.local/lib/python3.7/site-packages/twisted/enterprise/adbapi.py:410:connect
[2022-05-24 02:54:34,015] {subprocess.py:92} INFO - /home/***/.local/lib/python3.7/site-packages/MySQLdb/__init__.py:123:Connect
[2022-05-24 02:54:34,015] {subprocess.py:92} INFO - /home/***/.local/lib/python3.7/site-packages/MySQLdb/connections.py:185:__init__
[2022-05-24 02:54:34,015] {subprocess.py:92} INFO - ]
[2022-05-24 02:54:41,187] {subprocess.py:92} INFO - 2022-05-24 02:54:41 [scrapy.core.engine] DEBUG: Crawled (200) <GET https://www.traveloka.com/vi-vn/hotel/vietnam/landmark/halong-ecolodge-view-tower-91566976858734> (referer: https://www.traveloka.com/vi-vn/hotel/vietnam/city/ha-long-city-30010278)
[2022-05-24 02:54:41,335] {subprocess.py:92} INFO - 2022-05-24 02:54:41 [scrapy.core.scraper] DEBUG: Scraped from <200 https://www.traveloka.com/vi-vn/hotel/vietnam/landmark/halong-ecolodge-view-tower-91566976858734>
[2022-05-24 02:54:41,335] {subprocess.py:92} INFO - {'hotel_address': 'Số 37. Dốc Hàn Quốc, Tổ 4, Khu 4, Đường Hậu Cần, phường Bãi '
[2022-05-24 02:54:41,335] {subprocess.py:92} INFO -                   'Cháy, Thành phố Hạ Long, Tỉnh Quảng Ninh, Việt Nam, 200000',
[2022-05-24 02:54:41,335] {subprocess.py:92} INFO -  'hotel_name': 'Oreka Homestay Halong',
[2022-05-24 02:54:41,335] {subprocess.py:92} INFO -  'hotel_point_review': '9.0',
[2022-05-24 02:54:41,336] {subprocess.py:92} INFO -  'hotel_rating': '2',
[2022-05-24 02:54:41,336] {subprocess.py:92} INFO -  'hotel_sum_review': '14',
[2022-05-24 02:54:41,336] {subprocess.py:92} INFO -  'hotel_url': 'https://www.traveloka.com/vi-vn/hotel/vietnam/orestay-halong-3000020016239'}
[2022-05-24 02:54:41,337] {subprocess.py:92} INFO - 2022-05-24 02:54:41 [scrapy.core.scraper] DEBUG: Scraped from <200 https://www.traveloka.com/vi-vn/hotel/vietnam/landmark/halong-ecolodge-view-tower-91566976858734>
[2022-05-24 02:54:41,337] {subprocess.py:92} INFO - {'hotel_address': '9b Suoi Mo street, Bai Chay, Halong, Quang Ninh, Vietnam, '
[2022-05-24 02:54:41,337] {subprocess.py:92} INFO -                   'phường Bãi Cháy, Thành phố Hạ Long, Tỉnh Quảng Ninh, Việt '
[2022-05-24 02:54:41,337] {subprocess.py:92} INFO -                   'Nam, 01119',
[2022-05-24 02:54:41,337] {subprocess.py:92} INFO -  'hotel_name': 'Little Colmar Boutique Homestay',
[2022-05-24 02:54:41,337] {subprocess.py:92} INFO -  'hotel_point_review': '8.3',
[2022-05-24 02:54:41,337] {subprocess.py:92} INFO -  'hotel_rating': '2.5',
[2022-05-24 02:54:41,337] {subprocess.py:92} INFO -  'hotel_sum_review': '12',
[2022-05-24 02:54:41,337] {subprocess.py:92} INFO -  'hotel_url': 'https://www.traveloka.com/vi-vn/hotel/vietnam/little-colmar-boutique-homestay-9000000766578'}
[2022-05-24 02:54:41,338] {subprocess.py:92} INFO - 2022-05-24 02:54:41 [scrapy.core.scraper] DEBUG: Scraped from <200 https://www.traveloka.com/vi-vn/hotel/vietnam/landmark/halong-ecolodge-view-tower-91566976858734>
[2022-05-24 02:54:41,338] {subprocess.py:92} INFO - {'hotel_address': '42 Bai Chay Street, To 5, Khu 4, Bai Chay Ward, phường Bãi '
[2022-05-24 02:54:41,338] {subprocess.py:92} INFO -                   'Cháy, Thành phố Hạ Long, Tỉnh Quảng Ninh, Việt Nam',
[2022-05-24 02:54:41,338] {subprocess.py:92} INFO -  'hotel_name': 'Khách sạn Hạ Long Diamond',
[2022-05-24 02:54:41,338] {subprocess.py:92} INFO -  'hotel_point_review': '8.3',
[2022-05-24 02:54:41,338] {subprocess.py:92} INFO -  'hotel_rating': '3.5',
[2022-05-24 02:54:41,339] {subprocess.py:92} INFO -  'hotel_sum_review': '32',
[2022-05-24 02:54:41,339] {subprocess.py:92} INFO -  'hotel_url': 'https://www.traveloka.com/vi-vn/hotel/vietnam/halong-diamond-hotel-1000000765475'}
[2022-05-24 02:54:41,339] {subprocess.py:92} INFO - 2022-05-24 02:54:41 [scrapy.core.scraper] DEBUG: Scraped from <200 https://www.traveloka.com/vi-vn/hotel/vietnam/landmark/halong-ecolodge-view-tower-91566976858734>
[2022-05-24 02:54:41,340] {subprocess.py:92} INFO - {'hotel_address': '19 Bãi Cháy, phường Bãi Cháy, Thành phố Hạ Long, Tỉnh Quảng '
[2022-05-24 02:54:41,340] {subprocess.py:92} INFO -                   'Ninh, Việt Nam, 200000',
[2022-05-24 02:54:41,340] {subprocess.py:92} INFO -  'hotel_name': 'Padama Hotel',
[2022-05-24 02:54:41,340] {subprocess.py:92} INFO -  'hotel_point_review': '7.6',
[2022-05-24 02:54:41,340] {subprocess.py:92} INFO -  'hotel_rating': '2',
[2022-05-24 02:54:41,340] {subprocess.py:92} INFO -  'hotel_sum_review': '9',
[2022-05-24 02:54:41,340] {subprocess.py:92} INFO -  'hotel_url': 'https://www.traveloka.com/vi-vn/hotel/vietnam/padama-hotel-9000000120132'}
[2022-05-24 02:54:41,341] {subprocess.py:92} INFO - 2022-05-24 02:54:41 [scrapy.core.scraper] DEBUG: Scraped from <200 https://www.traveloka.com/vi-vn/hotel/vietnam/landmark/halong-ecolodge-view-tower-91566976858734>
[2022-05-24 02:54:41,341] {subprocess.py:92} INFO - {'hotel_address': 'Đường Hạ Long , Phường Bãi Cháy, phường Bãi Cháy, Thành phố '
[2022-05-24 02:54:41,341] {subprocess.py:92} INFO -                   'Hạ Long, Tỉnh Quảng Ninh, Việt Nam, 200000',
[2022-05-24 02:54:41,341] {subprocess.py:92} INFO -  'hotel_name': 'Mường Thanh Holiday Suối Mơ',
[2022-05-24 02:54:41,341] {subprocess.py:92} INFO -  'hotel_point_review': '6.9',
[2022-05-24 02:54:41,341] {subprocess.py:92} INFO -  'hotel_rating': '4',
[2022-05-24 02:54:41,341] {subprocess.py:92} INFO -  'hotel_sum_review': '12',
[2022-05-24 02:54:41,341] {subprocess.py:92} INFO -  'hotel_url': 'https://www.traveloka.com/vi-vn/hotel/vietnam/muong-thanh-holiday-suoi-mo-9000000890167'}
[2022-05-24 02:54:41,342] {subprocess.py:92} INFO - 2022-05-24 02:54:41 [scrapy.core.scraper] DEBUG: Scraped from <200 https://www.traveloka.com/vi-vn/hotel/vietnam/landmark/halong-ecolodge-view-tower-91566976858734>
[2022-05-24 02:54:41,342] {subprocess.py:92} INFO - {'hotel_address': '5 Bãi Cháy, phường Bãi Cháy, Thành phố Hạ Long, Tỉnh Quảng '
[2022-05-24 02:54:41,342] {subprocess.py:92} INFO -                   'Ninh, Việt Nam, 200000',
[2022-05-24 02:54:41,342] {subprocess.py:92} INFO -  'hotel_name': 'Du thuyền The Viet Beauty',
[2022-05-24 02:54:41,343] {subprocess.py:92} INFO -  'hotel_point_review': '7.9',
[2022-05-24 02:54:41,343] {subprocess.py:92} INFO -  'hotel_rating': '3',
[2022-05-24 02:54:41,343] {subprocess.py:92} INFO -  'hotel_sum_review': '27',
[2022-05-24 02:54:41,343] {subprocess.py:92} INFO -  'hotel_url': 'https://www.traveloka.com/vi-vn/hotel/vietnam/the-viet-beauty-cruise-3000010032867'}
[2022-05-24 02:54:41,344] {subprocess.py:92} INFO - 2022-05-24 02:54:41 [scrapy.core.scraper] DEBUG: Scraped from <200 https://www.traveloka.com/vi-vn/hotel/vietnam/landmark/halong-ecolodge-view-tower-91566976858734>
[2022-05-24 02:54:41,344] {subprocess.py:92} INFO - {'hotel_address': 'Khu Du Lịch Hùng Thắng, phường Bãi Cháy, Thành phố Hạ Long, '
[2022-05-24 02:54:41,344] {subprocess.py:92} INFO -                   'Tỉnh Quảng Ninh, Việt Nam, 200000',
[2022-05-24 02:54:41,344] {subprocess.py:92} INFO -  'hotel_name': 'Golden Halong Hotel',
[2022-05-24 02:54:41,344] {subprocess.py:92} INFO -  'hotel_point_review': '8.4',
[2022-05-24 02:54:41,344] {subprocess.py:92} INFO -  'hotel_rating': '4',
[2022-05-24 02:54:41,344] {subprocess.py:92} INFO -  'hotel_sum_review': '121',
[2022-05-24 02:54:41,344] {subprocess.py:92} INFO -  'hotel_url': 'https://www.traveloka.com/vi-vn/hotel/vietnam/golden-halong-hotel-1000000397050'}
[2022-05-24 02:54:41,346] {subprocess.py:92} INFO - 2022-05-24 02:54:41 [scrapy.core.scraper] DEBUG: Scraped from <200 https://www.traveloka.com/vi-vn/hotel/vietnam/landmark/halong-ecolodge-view-tower-91566976858734>
[2022-05-24 02:54:41,347] {subprocess.py:92} INFO - {'hotel_address': 'Sun Premier Village, TT 03 đường Thuỷ Tùng, Bãi Cháy, Thành '
[2022-05-24 02:54:41,347] {subprocess.py:92} INFO -                   'phố Hạ Long, Quảng Ninh, Vietnam, Hạ Long, Quảng '
[2022-05-24 02:54:41,347] {subprocess.py:92} INFO -                   'Ninh\t\t\t\t\t\t\t\t, phường Bãi Cháy, Thành phố Hạ Long, '
[2022-05-24 02:54:41,347] {subprocess.py:92} INFO -                   'Tỉnh Quảng Ninh, Việt Nam, 200000',
[2022-05-24 02:54:41,347] {subprocess.py:92} INFO -  'hotel_name': 'Vieng Chan Hotel',
[2022-05-24 02:54:41,347] {subprocess.py:92} INFO -  'hotel_point_review': '6.0',
[2022-05-24 02:54:41,347] {subprocess.py:92} INFO -  'hotel_rating': '2',
[2022-05-24 02:54:41,347] {subprocess.py:92} INFO -  'hotel_sum_review': '20',
[2022-05-24 02:54:41,347] {subprocess.py:92} INFO -  'hotel_url': 'https://www.traveloka.com/vi-vn/hotel/vietnam/vieng-chan-hotel-9000000337329'}
[2022-05-24 02:54:41,347] {subprocess.py:92} INFO - 2022-05-24 02:54:41 [root] ERROR: [Failure instance: Traceback: <class 'MySQLdb._exceptions.OperationalError'>: (2003, "Can't connect to MySQL server on '127.20.0.1:3306' (111)")
[2022-05-24 02:54:41,347] {subprocess.py:92} INFO - /usr/local/lib/python3.7/threading.py:926:_bootstrap_inner
[2022-05-24 02:54:41,347] {subprocess.py:92} INFO - /usr/local/lib/python3.7/threading.py:870:run
[2022-05-24 02:54:41,347] {subprocess.py:92} INFO - /home/***/.local/lib/python3.7/site-packages/twisted/_threads/_threadworker.py:47:work
[2022-05-24 02:54:41,348] {subprocess.py:92} INFO - /home/***/.local/lib/python3.7/site-packages/twisted/_threads/_team.py:182:doWork
[2022-05-24 02:54:41,348] {subprocess.py:92} INFO - --- <exception caught here> ---
[2022-05-24 02:54:41,348] {subprocess.py:92} INFO - /home/***/.local/lib/python3.7/site-packages/twisted/python/threadpool.py:244:inContext
[2022-05-24 02:54:41,348] {subprocess.py:92} INFO - /home/***/.local/lib/python3.7/site-packages/twisted/python/threadpool.py:261:<lambda>
[2022-05-24 02:54:41,348] {subprocess.py:92} INFO - /home/***/.local/lib/python3.7/site-packages/twisted/python/context.py:117:callWithContext
[2022-05-24 02:54:41,348] {subprocess.py:92} INFO - /home/***/.local/lib/python3.7/site-packages/twisted/python/context.py:82:callWithContext
[2022-05-24 02:54:41,348] {subprocess.py:92} INFO - /home/***/.local/lib/python3.7/site-packages/twisted/enterprise/adbapi.py:440:_runInteraction
[2022-05-24 02:54:41,348] {subprocess.py:92} INFO - /home/***/.local/lib/python3.7/site-packages/twisted/enterprise/adbapi.py:34:__init__
[2022-05-24 02:54:41,348] {subprocess.py:92} INFO - /home/***/.local/lib/python3.7/site-packages/twisted/enterprise/adbapi.py:71:reconnect
[2022-05-24 02:54:41,348] {subprocess.py:92} INFO - /home/***/.local/lib/python3.7/site-packages/twisted/enterprise/adbapi.py:410:connect
[2022-05-24 02:54:41,348] {subprocess.py:92} INFO - /home/***/.local/lib/python3.7/site-packages/MySQLdb/__init__.py:123:Connect
[2022-05-24 02:54:41,348] {subprocess.py:92} INFO - /home/***/.local/lib/python3.7/site-packages/MySQLdb/connections.py:185:__init__
[2022-05-24 02:54:41,348] {subprocess.py:92} INFO - ]
[2022-05-24 02:54:41,348] {subprocess.py:92} INFO - 2022-05-24 02:54:41 [root] ERROR: [Failure instance: Traceback: <class 'MySQLdb._exceptions.OperationalError'>: (2003, "Can't connect to MySQL server on '127.20.0.1:3306' (111)")
[2022-05-24 02:54:41,348] {subprocess.py:92} INFO - /usr/local/lib/python3.7/threading.py:926:_bootstrap_inner
[2022-05-24 02:54:41,349] {subprocess.py:92} INFO - /usr/local/lib/python3.7/threading.py:870:run
[2022-05-24 02:54:41,349] {subprocess.py:92} INFO - /home/***/.local/lib/python3.7/site-packages/twisted/_threads/_threadworker.py:47:work
[2022-05-24 02:54:41,349] {subprocess.py:92} INFO - /home/***/.local/lib/python3.7/site-packages/twisted/_threads/_team.py:182:doWork
[2022-05-24 02:54:41,349] {subprocess.py:92} INFO - --- <exception caught here> ---
[2022-05-24 02:54:41,349] {subprocess.py:92} INFO - /home/***/.local/lib/python3.7/site-packages/twisted/python/threadpool.py:244:inContext
[2022-05-24 02:54:41,349] {subprocess.py:92} INFO - /home/***/.local/lib/python3.7/site-packages/twisted/python/threadpool.py:261:<lambda>
[2022-05-24 02:54:41,349] {subprocess.py:92} INFO - /home/***/.local/lib/python3.7/site-packages/twisted/python/context.py:117:callWithContext
[2022-05-24 02:54:41,349] {subprocess.py:92} INFO - /home/***/.local/lib/python3.7/site-packages/twisted/python/context.py:82:callWithContext
[2022-05-24 02:54:41,349] {subprocess.py:92} INFO - /home/***/.local/lib/python3.7/site-packages/twisted/enterprise/adbapi.py:440:_runInteraction
[2022-05-24 02:54:41,349] {subprocess.py:92} INFO - /home/***/.local/lib/python3.7/site-packages/twisted/enterprise/adbapi.py:34:__init__
[2022-05-24 02:54:41,349] {subprocess.py:92} INFO - /home/***/.local/lib/python3.7/site-packages/twisted/enterprise/adbapi.py:71:reconnect
[2022-05-24 02:54:41,349] {subprocess.py:92} INFO - /home/***/.local/lib/python3.7/site-packages/twisted/enterprise/adbapi.py:410:connect
[2022-05-24 02:54:41,349] {subprocess.py:92} INFO - /home/***/.local/lib/python3.7/site-packages/MySQLdb/__init__.py:123:Connect
[2022-05-24 02:54:41,349] {subprocess.py:92} INFO - /home/***/.local/lib/python3.7/site-packages/MySQLdb/connections.py:185:__init__
[2022-05-24 02:54:41,349] {subprocess.py:92} INFO - ]
[2022-05-24 02:54:41,349] {subprocess.py:92} INFO - 2022-05-24 02:54:41 [root] ERROR: [Failure instance: Traceback: <class 'MySQLdb._exceptions.OperationalError'>: (2003, "Can't connect to MySQL server on '127.20.0.1:3306' (111)")
[2022-05-24 02:54:41,350] {subprocess.py:92} INFO - /usr/local/lib/python3.7/threading.py:926:_bootstrap_inner
[2022-05-24 02:54:41,350] {subprocess.py:92} INFO - /usr/local/lib/python3.7/threading.py:870:run
[2022-05-24 02:54:41,350] {subprocess.py:92} INFO - /home/***/.local/lib/python3.7/site-packages/twisted/_threads/_threadworker.py:47:work
[2022-05-24 02:54:41,350] {subprocess.py:92} INFO - /home/***/.local/lib/python3.7/site-packages/twisted/_threads/_team.py:182:doWork
[2022-05-24 02:54:41,350] {subprocess.py:92} INFO - --- <exception caught here> ---
[2022-05-24 02:54:41,350] {subprocess.py:92} INFO - /home/***/.local/lib/python3.7/site-packages/twisted/python/threadpool.py:244:inContext
[2022-05-24 02:54:41,350] {subprocess.py:92} INFO - /home/***/.local/lib/python3.7/site-packages/twisted/python/threadpool.py:261:<lambda>
[2022-05-24 02:54:41,350] {subprocess.py:92} INFO - /home/***/.local/lib/python3.7/site-packages/twisted/python/context.py:117:callWithContext
[2022-05-24 02:54:41,350] {subprocess.py:92} INFO - /home/***/.local/lib/python3.7/site-packages/twisted/python/context.py:82:callWithContext
[2022-05-24 02:54:41,350] {subprocess.py:92} INFO - /home/***/.local/lib/python3.7/site-packages/twisted/enterprise/adbapi.py:440:_runInteraction
[2022-05-24 02:54:41,350] {subprocess.py:92} INFO - /home/***/.local/lib/python3.7/site-packages/twisted/enterprise/adbapi.py:34:__init__
[2022-05-24 02:54:41,350] {subprocess.py:92} INFO - /home/***/.local/lib/python3.7/site-packages/twisted/enterprise/adbapi.py:71:reconnect
[2022-05-24 02:54:41,350] {subprocess.py:92} INFO - /home/***/.local/lib/python3.7/site-packages/twisted/enterprise/adbapi.py:410:connect
[2022-05-24 02:54:41,351] {subprocess.py:92} INFO - /home/***/.local/lib/python3.7/site-packages/MySQLdb/__init__.py:123:Connect
[2022-05-24 02:54:41,351] {subprocess.py:92} INFO - /home/***/.local/lib/python3.7/site-packages/MySQLdb/connections.py:185:__init__
[2022-05-24 02:54:41,351] {subprocess.py:92} INFO - ]
[2022-05-24 02:54:41,351] {subprocess.py:92} INFO - 2022-05-24 02:54:41 [root] ERROR: [Failure instance: Traceback: <class 'MySQLdb._exceptions.OperationalError'>: (2003, "Can't connect to MySQL server on '127.20.0.1:3306' (111)")
[2022-05-24 02:54:41,351] {subprocess.py:92} INFO - /usr/local/lib/python3.7/threading.py:926:_bootstrap_inner
[2022-05-24 02:54:41,351] {subprocess.py:92} INFO - /usr/local/lib/python3.7/threading.py:870:run
[2022-05-24 02:54:41,351] {subprocess.py:92} INFO - /home/***/.local/lib/python3.7/site-packages/twisted/_threads/_threadworker.py:47:work
[2022-05-24 02:54:41,351] {subprocess.py:92} INFO - /home/***/.local/lib/python3.7/site-packages/twisted/_threads/_team.py:182:doWork
[2022-05-24 02:54:41,351] {subprocess.py:92} INFO - --- <exception caught here> ---
[2022-05-24 02:54:41,351] {subprocess.py:92} INFO - /home/***/.local/lib/python3.7/site-packages/twisted/python/threadpool.py:244:inContext
[2022-05-24 02:54:41,352] {subprocess.py:92} INFO - /home/***/.local/lib/python3.7/site-packages/twisted/python/threadpool.py:261:<lambda>
[2022-05-24 02:54:41,352] {subprocess.py:92} INFO - /home/***/.local/lib/python3.7/site-packages/twisted/python/context.py:117:callWithContext
[2022-05-24 02:54:41,352] {subprocess.py:92} INFO - /home/***/.local/lib/python3.7/site-packages/twisted/python/context.py:82:callWithContext
[2022-05-24 02:54:41,352] {subprocess.py:92} INFO - /home/***/.local/lib/python3.7/site-packages/twisted/enterprise/adbapi.py:440:_runInteraction
[2022-05-24 02:54:41,352] {subprocess.py:92} INFO - /home/***/.local/lib/python3.7/site-packages/twisted/enterprise/adbapi.py:34:__init__
[2022-05-24 02:54:41,352] {subprocess.py:92} INFO - /home/***/.local/lib/python3.7/site-packages/twisted/enterprise/adbapi.py:71:reconnect
[2022-05-24 02:54:41,352] {subprocess.py:92} INFO - /home/***/.local/lib/python3.7/site-packages/twisted/enterprise/adbapi.py:410:connect
[2022-05-24 02:54:41,352] {subprocess.py:92} INFO - /home/***/.local/lib/python3.7/site-packages/MySQLdb/__init__.py:123:Connect
[2022-05-24 02:54:41,352] {subprocess.py:92} INFO - /home/***/.local/lib/python3.7/site-packages/MySQLdb/connections.py:185:__init__
[2022-05-24 02:54:41,352] {subprocess.py:92} INFO - ]
[2022-05-24 02:54:41,352] {subprocess.py:92} INFO - 2022-05-24 02:54:41 [root] ERROR: [Failure instance: Traceback: <class 'MySQLdb._exceptions.OperationalError'>: (2003, "Can't connect to MySQL server on '127.20.0.1:3306' (111)")
[2022-05-24 02:54:41,352] {subprocess.py:92} INFO - /usr/local/lib/python3.7/threading.py:926:_bootstrap_inner
[2022-05-24 02:54:41,353] {subprocess.py:92} INFO - /usr/local/lib/python3.7/threading.py:870:run
[2022-05-24 02:54:41,353] {subprocess.py:92} INFO - /home/***/.local/lib/python3.7/site-packages/twisted/_threads/_threadworker.py:47:work
[2022-05-24 02:54:41,353] {subprocess.py:92} INFO - /home/***/.local/lib/python3.7/site-packages/twisted/_threads/_team.py:182:doWork
[2022-05-24 02:54:41,353] {subprocess.py:92} INFO - --- <exception caught here> ---
[2022-05-24 02:54:41,353] {subprocess.py:92} INFO - /home/***/.local/lib/python3.7/site-packages/twisted/python/threadpool.py:244:inContext
[2022-05-24 02:54:41,353] {subprocess.py:92} INFO - /home/***/.local/lib/python3.7/site-packages/twisted/python/threadpool.py:261:<lambda>
[2022-05-24 02:54:41,353] {subprocess.py:92} INFO - /home/***/.local/lib/python3.7/site-packages/twisted/python/context.py:117:callWithContext
[2022-05-24 02:54:41,353] {subprocess.py:92} INFO - /home/***/.local/lib/python3.7/site-packages/twisted/python/context.py:82:callWithContext
[2022-05-24 02:54:41,353] {subprocess.py:92} INFO - /home/***/.local/lib/python3.7/site-packages/twisted/enterprise/adbapi.py:440:_runInteraction
[2022-05-24 02:54:41,353] {subprocess.py:92} INFO - /home/***/.local/lib/python3.7/site-packages/twisted/enterprise/adbapi.py:34:__init__
[2022-05-24 02:54:41,353] {subprocess.py:92} INFO - /home/***/.local/lib/python3.7/site-packages/twisted/enterprise/adbapi.py:71:reconnect
[2022-05-24 02:54:41,353] {subprocess.py:92} INFO - /home/***/.local/lib/python3.7/site-packages/twisted/enterprise/adbapi.py:410:connect
[2022-05-24 02:54:41,353] {subprocess.py:92} INFO - /home/***/.local/lib/python3.7/site-packages/MySQLdb/__init__.py:123:Connect
[2022-05-24 02:54:41,353] {subprocess.py:92} INFO - /home/***/.local/lib/python3.7/site-packages/MySQLdb/connections.py:185:__init__
[2022-05-24 02:54:41,354] {subprocess.py:92} INFO - ]
[2022-05-24 02:54:41,354] {subprocess.py:92} INFO - 2022-05-24 02:54:41 [root] ERROR: [Failure instance: Traceback: <class 'MySQLdb._exceptions.OperationalError'>: (2003, "Can't connect to MySQL server on '127.20.0.1:3306' (111)")
[2022-05-24 02:54:41,354] {subprocess.py:92} INFO - /usr/local/lib/python3.7/threading.py:926:_bootstrap_inner
[2022-05-24 02:54:41,354] {subprocess.py:92} INFO - /usr/local/lib/python3.7/threading.py:870:run
[2022-05-24 02:54:41,354] {subprocess.py:92} INFO - /home/***/.local/lib/python3.7/site-packages/twisted/_threads/_threadworker.py:47:work
[2022-05-24 02:54:41,354] {subprocess.py:92} INFO - /home/***/.local/lib/python3.7/site-packages/twisted/_threads/_team.py:182:doWork
[2022-05-24 02:54:41,354] {subprocess.py:92} INFO - --- <exception caught here> ---
[2022-05-24 02:54:41,354] {subprocess.py:92} INFO - /home/***/.local/lib/python3.7/site-packages/twisted/python/threadpool.py:244:inContext
[2022-05-24 02:54:41,354] {subprocess.py:92} INFO - /home/***/.local/lib/python3.7/site-packages/twisted/python/threadpool.py:261:<lambda>
[2022-05-24 02:54:41,354] {subprocess.py:92} INFO - /home/***/.local/lib/python3.7/site-packages/twisted/python/context.py:117:callWithContext
[2022-05-24 02:54:41,354] {subprocess.py:92} INFO - /home/***/.local/lib/python3.7/site-packages/twisted/python/context.py:82:callWithContext
[2022-05-24 02:54:41,354] {subprocess.py:92} INFO - /home/***/.local/lib/python3.7/site-packages/twisted/enterprise/adbapi.py:440:_runInteraction
[2022-05-24 02:54:41,354] {subprocess.py:92} INFO - /home/***/.local/lib/python3.7/site-packages/twisted/enterprise/adbapi.py:34:__init__
[2022-05-24 02:54:41,354] {subprocess.py:92} INFO - /home/***/.local/lib/python3.7/site-packages/twisted/enterprise/adbapi.py:71:reconnect
[2022-05-24 02:54:41,354] {subprocess.py:92} INFO - /home/***/.local/lib/python3.7/site-packages/twisted/enterprise/adbapi.py:410:connect
[2022-05-24 02:54:41,355] {subprocess.py:92} INFO - /home/***/.local/lib/python3.7/site-packages/MySQLdb/__init__.py:123:Connect
[2022-05-24 02:54:41,355] {subprocess.py:92} INFO - /home/***/.local/lib/python3.7/site-packages/MySQLdb/connections.py:185:__init__
[2022-05-24 02:54:41,355] {subprocess.py:92} INFO - ]
[2022-05-24 02:54:41,355] {subprocess.py:92} INFO - 2022-05-24 02:54:41 [root] ERROR: [Failure instance: Traceback: <class 'MySQLdb._exceptions.OperationalError'>: (2003, "Can't connect to MySQL server on '127.20.0.1:3306' (111)")
[2022-05-24 02:54:41,355] {subprocess.py:92} INFO - /usr/local/lib/python3.7/threading.py:926:_bootstrap_inner
[2022-05-24 02:54:41,355] {subprocess.py:92} INFO - /usr/local/lib/python3.7/threading.py:870:run
[2022-05-24 02:54:41,355] {subprocess.py:92} INFO - /home/***/.local/lib/python3.7/site-packages/twisted/_threads/_threadworker.py:47:work
[2022-05-24 02:54:41,355] {subprocess.py:92} INFO - /home/***/.local/lib/python3.7/site-packages/twisted/_threads/_team.py:182:doWork
[2022-05-24 02:54:41,355] {subprocess.py:92} INFO - --- <exception caught here> ---
[2022-05-24 02:54:41,355] {subprocess.py:92} INFO - /home/***/.local/lib/python3.7/site-packages/twisted/python/threadpool.py:244:inContext
[2022-05-24 02:54:41,355] {subprocess.py:92} INFO - /home/***/.local/lib/python3.7/site-packages/twisted/python/threadpool.py:261:<lambda>
[2022-05-24 02:54:41,355] {subprocess.py:92} INFO - /home/***/.local/lib/python3.7/site-packages/twisted/python/context.py:117:callWithContext
[2022-05-24 02:54:41,355] {subprocess.py:92} INFO - /home/***/.local/lib/python3.7/site-packages/twisted/python/context.py:82:callWithContext
[2022-05-24 02:54:41,356] {subprocess.py:92} INFO - /home/***/.local/lib/python3.7/site-packages/twisted/enterprise/adbapi.py:440:_runInteraction
[2022-05-24 02:54:41,356] {subprocess.py:92} INFO - /home/***/.local/lib/python3.7/site-packages/twisted/enterprise/adbapi.py:34:__init__
[2022-05-24 02:54:41,356] {subprocess.py:92} INFO - /home/***/.local/lib/python3.7/site-packages/twisted/enterprise/adbapi.py:71:reconnect
[2022-05-24 02:54:41,356] {subprocess.py:92} INFO - /home/***/.local/lib/python3.7/site-packages/twisted/enterprise/adbapi.py:410:connect
[2022-05-24 02:54:41,356] {subprocess.py:92} INFO - /home/***/.local/lib/python3.7/site-packages/MySQLdb/__init__.py:123:Connect
[2022-05-24 02:54:41,356] {subprocess.py:92} INFO - /home/***/.local/lib/python3.7/site-packages/MySQLdb/connections.py:185:__init__
[2022-05-24 02:54:41,356] {subprocess.py:92} INFO - ]
[2022-05-24 02:54:41,356] {subprocess.py:92} INFO - 2022-05-24 02:54:41 [scrapy.core.scraper] DEBUG: Scraped from <200 https://www.traveloka.com/vi-vn/hotel/vietnam/landmark/halong-ecolodge-view-tower-91566976858734>
[2022-05-24 02:54:41,356] {subprocess.py:92} INFO - {'hotel_address': 'Số 45 Đường Bãi Cháy, Phường  Bãi Cháy, phường Bãi Cháy, '
[2022-05-24 02:54:41,356] {subprocess.py:92} INFO -                   'Thành phố Hạ Long, Tỉnh Quảng Ninh, Việt Nam',
[2022-05-24 02:54:41,356] {subprocess.py:92} INFO -  'hotel_name': 'Khách sạn Entity Halong',
[2022-05-24 02:54:41,356] {subprocess.py:92} INFO -  'hotel_point_review': '8.6',
[2022-05-24 02:54:41,357] {subprocess.py:92} INFO -  'hotel_rating': '3.5',
[2022-05-24 02:54:41,357] {subprocess.py:92} INFO -  'hotel_sum_review': '71',
[2022-05-24 02:54:41,357] {subprocess.py:92} INFO -  'hotel_url': 'https://www.traveloka.com/vi-vn/hotel/vietnam/entity-halong-hotel-3000010024110'}
[2022-05-24 02:54:41,357] {subprocess.py:92} INFO - 2022-05-24 02:54:41 [root] ERROR: [Failure instance: Traceback: <class 'MySQLdb._exceptions.OperationalError'>: (2003, "Can't connect to MySQL server on '127.20.0.1:3306' (111)")
[2022-05-24 02:54:41,357] {subprocess.py:92} INFO - /usr/local/lib/python3.7/threading.py:926:_bootstrap_inner
[2022-05-24 02:54:41,357] {subprocess.py:92} INFO - /usr/local/lib/python3.7/threading.py:870:run
[2022-05-24 02:54:41,357] {subprocess.py:92} INFO - /home/***/.local/lib/python3.7/site-packages/twisted/_threads/_threadworker.py:47:work
[2022-05-24 02:54:41,357] {subprocess.py:92} INFO - /home/***/.local/lib/python3.7/site-packages/twisted/_threads/_team.py:182:doWork
[2022-05-24 02:54:41,357] {subprocess.py:92} INFO - --- <exception caught here> ---
[2022-05-24 02:54:41,357] {subprocess.py:92} INFO - /home/***/.local/lib/python3.7/site-packages/twisted/python/threadpool.py:244:inContext
[2022-05-24 02:54:41,357] {subprocess.py:92} INFO - /home/***/.local/lib/python3.7/site-packages/twisted/python/threadpool.py:261:<lambda>
[2022-05-24 02:54:41,357] {subprocess.py:92} INFO - /home/***/.local/lib/python3.7/site-packages/twisted/python/context.py:117:callWithContext
[2022-05-24 02:54:41,357] {subprocess.py:92} INFO - /home/***/.local/lib/python3.7/site-packages/twisted/python/context.py:82:callWithContext
[2022-05-24 02:54:41,358] {subprocess.py:92} INFO - /home/***/.local/lib/python3.7/site-packages/twisted/enterprise/adbapi.py:440:_runInteraction
[2022-05-24 02:54:41,358] {subprocess.py:92} INFO - /home/***/.local/lib/python3.7/site-packages/twisted/enterprise/adbapi.py:34:__init__
[2022-05-24 02:54:41,358] {subprocess.py:92} INFO - /home/***/.local/lib/python3.7/site-packages/twisted/enterprise/adbapi.py:71:reconnect
[2022-05-24 02:54:41,358] {subprocess.py:92} INFO - /home/***/.local/lib/python3.7/site-packages/twisted/enterprise/adbapi.py:410:connect
[2022-05-24 02:54:41,358] {subprocess.py:92} INFO - /home/***/.local/lib/python3.7/site-packages/MySQLdb/__init__.py:123:Connect
[2022-05-24 02:54:41,358] {subprocess.py:92} INFO - /home/***/.local/lib/python3.7/site-packages/MySQLdb/connections.py:185:__init__
[2022-05-24 02:54:41,358] {subprocess.py:92} INFO - ]
[2022-05-24 02:54:41,358] {subprocess.py:92} INFO - 2022-05-24 02:54:41 [root] ERROR: [Failure instance: Traceback: <class 'MySQLdb._exceptions.OperationalError'>: (2003, "Can't connect to MySQL server on '127.20.0.1:3306' (111)")
[2022-05-24 02:54:41,358] {subprocess.py:92} INFO - /usr/local/lib/python3.7/threading.py:926:_bootstrap_inner
[2022-05-24 02:54:41,358] {subprocess.py:92} INFO - /usr/local/lib/python3.7/threading.py:870:run
[2022-05-24 02:54:41,358] {subprocess.py:92} INFO - /home/***/.local/lib/python3.7/site-packages/twisted/_threads/_threadworker.py:47:work
[2022-05-24 02:54:41,358] {subprocess.py:92} INFO - /home/***/.local/lib/python3.7/site-packages/twisted/_threads/_team.py:182:doWork
[2022-05-24 02:54:41,359] {subprocess.py:92} INFO - --- <exception caught here> ---
[2022-05-24 02:54:41,359] {subprocess.py:92} INFO - /home/***/.local/lib/python3.7/site-packages/twisted/python/threadpool.py:244:inContext
[2022-05-24 02:54:41,359] {subprocess.py:92} INFO - /home/***/.local/lib/python3.7/site-packages/twisted/python/threadpool.py:261:<lambda>
[2022-05-24 02:54:41,359] {subprocess.py:92} INFO - /home/***/.local/lib/python3.7/site-packages/twisted/python/context.py:117:callWithContext
[2022-05-24 02:54:41,359] {subprocess.py:92} INFO - /home/***/.local/lib/python3.7/site-packages/twisted/python/context.py:82:callWithContext
[2022-05-24 02:54:41,359] {subprocess.py:92} INFO - /home/***/.local/lib/python3.7/site-packages/twisted/enterprise/adbapi.py:440:_runInteraction
[2022-05-24 02:54:41,359] {subprocess.py:92} INFO - /home/***/.local/lib/python3.7/site-packages/twisted/enterprise/adbapi.py:34:__init__
[2022-05-24 02:54:41,359] {subprocess.py:92} INFO - /home/***/.local/lib/python3.7/site-packages/twisted/enterprise/adbapi.py:71:reconnect
[2022-05-24 02:54:41,359] {subprocess.py:92} INFO - /home/***/.local/lib/python3.7/site-packages/twisted/enterprise/adbapi.py:410:connect
[2022-05-24 02:54:41,359] {subprocess.py:92} INFO - /home/***/.local/lib/python3.7/site-packages/MySQLdb/__init__.py:123:Connect
[2022-05-24 02:54:41,359] {subprocess.py:92} INFO - /home/***/.local/lib/python3.7/site-packages/MySQLdb/connections.py:185:__init__
[2022-05-24 02:54:41,359] {subprocess.py:92} INFO - ]
[2022-05-24 02:54:47,341] {subprocess.py:92} INFO - 2022-05-24 02:54:47 [scrapy.extensions.logstats] INFO: Crawled 14 pages (at 8 pages/min), scraped 33 items (at 33 items/min)
[2022-05-24 02:54:48,382] {subprocess.py:92} INFO - 2022-05-24 02:54:48 [scrapy.core.engine] DEBUG: Crawled (200) <GET https://www.traveloka.com/vi-vn/hotel/vietnam/landmark/cu-koi-91566975546796> (referer: https://www.traveloka.com/vi-vn/hotel/vietnam/city/ha-long-city-30010278)
[2022-05-24 02:54:51,773] {subprocess.py:92} INFO - 2022-05-24 02:54:51 [scrapy.core.engine] DEBUG: Crawled (200) <GET https://www.traveloka.com/vi-vn/hotel/vietnam/city/hai-ha-10010563> (referer: https://www.traveloka.com/vi-vn/hotel/vietnam/city/ha-long-city-30010278)
[2022-05-24 02:55:00,270] {subprocess.py:92} INFO - 2022-05-24 02:55:00 [scrapy.core.engine] DEBUG: Crawled (200) <GET https://www.traveloka.com/vi-vn/hotel/vietnam/region/ha-giang-province-10009852> (referer: https://www.traveloka.com/vi-vn/hotel/vietnam/region/ho-chi-minh-city-10009794)
[2022-05-24 02:55:00,422] {subprocess.py:92} INFO - 2022-05-24 02:55:00 [scrapy.core.scraper] DEBUG: Scraped from <200 https://www.traveloka.com/vi-vn/hotel/vietnam/region/ha-giang-province-10009852>
[2022-05-24 02:55:00,422] {subprocess.py:92} INFO - {'hotel_address': 'số nhà 47 đường 3/2, thị trấn Đồng Văn, thị trấn Đồng Văn, '
[2022-05-24 02:55:00,423] {subprocess.py:92} INFO -                   'Đồng Văn, Hà Giang, Việt Nam, 310000',
[2022-05-24 02:55:00,423] {subprocess.py:92} INFO -  'hotel_name': 'Hoang Ngoc Hotel - Ha Giang',
[2022-05-24 02:55:00,423] {subprocess.py:92} INFO -  'hotel_point_review': '8.8',
[2022-05-24 02:55:00,423] {subprocess.py:92} INFO -  'hotel_rating': '2',
[2022-05-24 02:55:00,423] {subprocess.py:92} INFO -  'hotel_sum_review': '108',
[2022-05-24 02:55:00,423] {subprocess.py:92} INFO -  'hotel_url': 'https://www.traveloka.com/vi-vn/hotel/vietnam/hoang-ngoc-hotel---ha-giang-3000010036848'}
[2022-05-24 02:55:00,424] {subprocess.py:92} INFO - 2022-05-24 02:55:00 [root] ERROR: [Failure instance: Traceback: <class 'MySQLdb._exceptions.OperationalError'>: (2003, "Can't connect to MySQL server on '127.20.0.1:3306' (111)")
[2022-05-24 02:55:00,424] {subprocess.py:92} INFO - /usr/local/lib/python3.7/threading.py:926:_bootstrap_inner
[2022-05-24 02:55:00,424] {subprocess.py:92} INFO - /usr/local/lib/python3.7/threading.py:870:run
[2022-05-24 02:55:00,424] {subprocess.py:92} INFO - /home/***/.local/lib/python3.7/site-packages/twisted/_threads/_threadworker.py:47:work
[2022-05-24 02:55:00,424] {subprocess.py:92} INFO - /home/***/.local/lib/python3.7/site-packages/twisted/_threads/_team.py:182:doWork
[2022-05-24 02:55:00,424] {subprocess.py:92} INFO - --- <exception caught here> ---
[2022-05-24 02:55:00,425] {subprocess.py:92} INFO - /home/***/.local/lib/python3.7/site-packages/twisted/python/threadpool.py:244:inContext
[2022-05-24 02:55:00,425] {subprocess.py:92} INFO - /home/***/.local/lib/python3.7/site-packages/twisted/python/threadpool.py:261:<lambda>
[2022-05-24 02:55:00,425] {subprocess.py:92} INFO - /home/***/.local/lib/python3.7/site-packages/twisted/python/context.py:117:callWithContext
[2022-05-24 02:55:00,425] {subprocess.py:92} INFO - /home/***/.local/lib/python3.7/site-packages/twisted/python/context.py:82:callWithContext
[2022-05-24 02:55:00,425] {subprocess.py:92} INFO - /home/***/.local/lib/python3.7/site-packages/twisted/enterprise/adbapi.py:440:_runInteraction
[2022-05-24 02:55:00,425] {subprocess.py:92} INFO - /home/***/.local/lib/python3.7/site-packages/twisted/enterprise/adbapi.py:34:__init__
[2022-05-24 02:55:00,425] {subprocess.py:92} INFO - /home/***/.local/lib/python3.7/site-packages/twisted/enterprise/adbapi.py:71:reconnect
[2022-05-24 02:55:00,425] {subprocess.py:92} INFO - /home/***/.local/lib/python3.7/site-packages/twisted/enterprise/adbapi.py:410:connect
[2022-05-24 02:55:00,425] {subprocess.py:92} INFO - /home/***/.local/lib/python3.7/site-packages/MySQLdb/__init__.py:123:Connect
[2022-05-24 02:55:00,425] {subprocess.py:92} INFO - /home/***/.local/lib/python3.7/site-packages/MySQLdb/connections.py:185:__init__
[2022-05-24 02:55:00,426] {subprocess.py:92} INFO - ]
[2022-05-24 02:55:00,426] {subprocess.py:92} INFO - 2022-05-24 02:55:00 [scrapy.core.scraper] DEBUG: Scraped from <200 https://www.traveloka.com/vi-vn/hotel/vietnam/region/ha-giang-province-10009852>
[2022-05-24 02:55:00,426] {subprocess.py:92} INFO - {'hotel_address': 'Tổ 1, Xã Cầu Mè, Phường Nguyễn Trãi, xã Phương Thiện, Thành '
[2022-05-24 02:55:00,426] {subprocess.py:92} INFO -                   'phố Hà Giang, Hà Giang, Việt Nam, 310000',
[2022-05-24 02:55:00,428] {subprocess.py:92} INFO -  'hotel_name': 'Khách sạn Anh Anh',
[2022-05-24 02:55:00,428] {subprocess.py:92} INFO -  'hotel_point_review': '8.2',
[2022-05-24 02:55:00,428] {subprocess.py:92} INFO -  'hotel_rating': '1',
[2022-05-24 02:55:00,428] {subprocess.py:92} INFO -  'hotel_sum_review': '5',
[2022-05-24 02:55:00,428] {subprocess.py:92} INFO -  'hotel_url': 'https://www.traveloka.com/vi-vn/hotel/vietnam/anh-anh-hotel-3000010036618'}
[2022-05-24 02:55:00,431] {subprocess.py:92} INFO - 2022-05-24 02:55:00 [scrapy.core.scraper] DEBUG: Scraped from <200 https://www.traveloka.com/vi-vn/hotel/vietnam/region/ha-giang-province-10009852>
[2022-05-24 02:55:00,431] {subprocess.py:92} INFO - {'hotel_address': 'Km 5, Nguyễn Văn Linh, phường Quang Trung, Thành phố Hà '
[2022-05-24 02:55:00,431] {subprocess.py:92} INFO -                   'Giang, Hà Giang, Việt Nam, 310000',
[2022-05-24 02:55:00,431] {subprocess.py:92} INFO -  'hotel_name': 'Resort Trường Xuân',
[2022-05-24 02:55:00,431] {subprocess.py:92} INFO -  'hotel_point_review': '8.5',
[2022-05-24 02:55:00,432] {subprocess.py:92} INFO -  'hotel_rating': '2',
[2022-05-24 02:55:00,432] {subprocess.py:92} INFO -  'hotel_sum_review': '7',
[2022-05-24 02:55:00,432] {subprocess.py:92} INFO -  'hotel_url': 'https://www.traveloka.com/vi-vn/hotel/vietnam/truong-xuan-resort-3000010036659'}
[2022-05-24 02:55:00,435] {subprocess.py:92} INFO - 2022-05-24 02:55:00 [scrapy.core.scraper] DEBUG: Scraped from <200 https://www.traveloka.com/vi-vn/hotel/vietnam/region/ha-giang-province-10009852>
[2022-05-24 02:55:00,435] {subprocess.py:92} INFO - {'hotel_address': 'Tổ 2, Mèo Vạc, thị trấn Mèo Vạc, Mèo Vạc, Hà Giang, Việt '
[2022-05-24 02:55:00,435] {subprocess.py:92} INFO -                   'Nam, 310000',
[2022-05-24 02:55:00,435] {subprocess.py:92} INFO -  'hotel_name': 'Khách sạn Huyền Lợi',
[2022-05-24 02:55:00,435] {subprocess.py:92} INFO -  'hotel_point_review': '8.1',
[2022-05-24 02:55:00,435] {subprocess.py:92} INFO -  'hotel_rating': '1.5',
[2022-05-24 02:55:00,436] {subprocess.py:92} INFO -  'hotel_sum_review': '8',
[2022-05-24 02:55:00,436] {subprocess.py:92} INFO -  'hotel_url': 'https://www.traveloka.com/vi-vn/hotel/vietnam/huyen-loi-hotel-3000010036809'}
[2022-05-24 02:55:00,436] {subprocess.py:92} INFO - 2022-05-24 02:55:00 [root] ERROR: [Failure instance: Traceback: <class 'MySQLdb._exceptions.OperationalError'>: (2003, "Can't connect to MySQL server on '127.20.0.1:3306' (111)")
[2022-05-24 02:55:00,436] {subprocess.py:92} INFO - /usr/local/lib/python3.7/threading.py:926:_bootstrap_inner
[2022-05-24 02:55:00,436] {subprocess.py:92} INFO - /usr/local/lib/python3.7/threading.py:870:run
[2022-05-24 02:55:00,436] {subprocess.py:92} INFO - /home/***/.local/lib/python3.7/site-packages/twisted/_threads/_threadworker.py:47:work
[2022-05-24 02:55:00,436] {subprocess.py:92} INFO - /home/***/.local/lib/python3.7/site-packages/twisted/_threads/_team.py:182:doWork
[2022-05-24 02:55:00,436] {subprocess.py:92} INFO - --- <exception caught here> ---
[2022-05-24 02:55:00,436] {subprocess.py:92} INFO - /home/***/.local/lib/python3.7/site-packages/twisted/python/threadpool.py:244:inContext
[2022-05-24 02:55:00,436] {subprocess.py:92} INFO - /home/***/.local/lib/python3.7/site-packages/twisted/python/threadpool.py:261:<lambda>
[2022-05-24 02:55:00,436] {subprocess.py:92} INFO - /home/***/.local/lib/python3.7/site-packages/twisted/python/context.py:117:callWithContext
[2022-05-24 02:55:00,436] {subprocess.py:92} INFO - /home/***/.local/lib/python3.7/site-packages/twisted/python/context.py:82:callWithContext
[2022-05-24 02:55:00,436] {subprocess.py:92} INFO - /home/***/.local/lib/python3.7/site-packages/twisted/enterprise/adbapi.py:440:_runInteraction
[2022-05-24 02:55:00,436] {subprocess.py:92} INFO - /home/***/.local/lib/python3.7/site-packages/twisted/enterprise/adbapi.py:34:__init__
[2022-05-24 02:55:00,436] {subprocess.py:92} INFO - /home/***/.local/lib/python3.7/site-packages/twisted/enterprise/adbapi.py:71:reconnect
[2022-05-24 02:55:00,436] {subprocess.py:92} INFO - /home/***/.local/lib/python3.7/site-packages/twisted/enterprise/adbapi.py:410:connect
[2022-05-24 02:55:00,437] {subprocess.py:92} INFO - /home/***/.local/lib/python3.7/site-packages/MySQLdb/__init__.py:123:Connect
[2022-05-24 02:55:00,437] {subprocess.py:92} INFO - /home/***/.local/lib/python3.7/site-packages/MySQLdb/connections.py:185:__init__
[2022-05-24 02:55:00,437] {subprocess.py:92} INFO - ]
[2022-05-24 02:55:00,437] {subprocess.py:92} INFO - 2022-05-24 02:55:00 [root] ERROR: [Failure instance: Traceback: <class 'MySQLdb._exceptions.OperationalError'>: (2003, "Can't connect to MySQL server on '127.20.0.1:3306' (111)")
[2022-05-24 02:55:00,437] {subprocess.py:92} INFO - /usr/local/lib/python3.7/threading.py:926:_bootstrap_inner
[2022-05-24 02:55:00,437] {subprocess.py:92} INFO - /usr/local/lib/python3.7/threading.py:870:run
[2022-05-24 02:55:00,437] {subprocess.py:92} INFO - /home/***/.local/lib/python3.7/site-packages/twisted/_threads/_threadworker.py:47:work
[2022-05-24 02:55:00,437] {subprocess.py:92} INFO - /home/***/.local/lib/python3.7/site-packages/twisted/_threads/_team.py:182:doWork
[2022-05-24 02:55:00,437] {subprocess.py:92} INFO - --- <exception caught here> ---
[2022-05-24 02:55:00,437] {subprocess.py:92} INFO - /home/***/.local/lib/python3.7/site-packages/twisted/python/threadpool.py:244:inContext
[2022-05-24 02:55:00,437] {subprocess.py:92} INFO - /home/***/.local/lib/python3.7/site-packages/twisted/python/threadpool.py:261:<lambda>
[2022-05-24 02:55:00,437] {subprocess.py:92} INFO - /home/***/.local/lib/python3.7/site-packages/twisted/python/context.py:117:callWithContext
[2022-05-24 02:55:00,437] {subprocess.py:92} INFO - /home/***/.local/lib/python3.7/site-packages/twisted/python/context.py:82:callWithContext
[2022-05-24 02:55:00,437] {subprocess.py:92} INFO - /home/***/.local/lib/python3.7/site-packages/twisted/enterprise/adbapi.py:440:_runInteraction
[2022-05-24 02:55:00,437] {subprocess.py:92} INFO - /home/***/.local/lib/python3.7/site-packages/twisted/enterprise/adbapi.py:34:__init__
[2022-05-24 02:55:00,438] {subprocess.py:92} INFO - /home/***/.local/lib/python3.7/site-packages/twisted/enterprise/adbapi.py:71:reconnect
[2022-05-24 02:55:00,438] {subprocess.py:92} INFO - /home/***/.local/lib/python3.7/site-packages/twisted/enterprise/adbapi.py:410:connect
[2022-05-24 02:55:00,438] {subprocess.py:92} INFO - /home/***/.local/lib/python3.7/site-packages/MySQLdb/__init__.py:123:Connect
[2022-05-24 02:55:00,438] {subprocess.py:92} INFO - /home/***/.local/lib/python3.7/site-packages/MySQLdb/connections.py:185:__init__
[2022-05-24 02:55:00,438] {subprocess.py:92} INFO - ]
[2022-05-24 02:55:00,438] {subprocess.py:92} INFO - 2022-05-24 02:55:00 [root] ERROR: [Failure instance: Traceback: <class 'MySQLdb._exceptions.OperationalError'>: (2003, "Can't connect to MySQL server on '127.20.0.1:3306' (111)")
[2022-05-24 02:55:00,438] {subprocess.py:92} INFO - /usr/local/lib/python3.7/threading.py:926:_bootstrap_inner
[2022-05-24 02:55:00,438] {subprocess.py:92} INFO - /usr/local/lib/python3.7/threading.py:870:run
[2022-05-24 02:55:00,438] {subprocess.py:92} INFO - /home/***/.local/lib/python3.7/site-packages/twisted/_threads/_threadworker.py:47:work
[2022-05-24 02:55:00,438] {subprocess.py:92} INFO - /home/***/.local/lib/python3.7/site-packages/twisted/_threads/_team.py:182:doWork
[2022-05-24 02:55:00,438] {subprocess.py:92} INFO - --- <exception caught here> ---
[2022-05-24 02:55:00,438] {subprocess.py:92} INFO - /home/***/.local/lib/python3.7/site-packages/twisted/python/threadpool.py:244:inContext
[2022-05-24 02:55:00,438] {subprocess.py:92} INFO - /home/***/.local/lib/python3.7/site-packages/twisted/python/threadpool.py:261:<lambda>
[2022-05-24 02:55:00,438] {subprocess.py:92} INFO - /home/***/.local/lib/python3.7/site-packages/twisted/python/context.py:117:callWithContext
[2022-05-24 02:55:00,439] {subprocess.py:92} INFO - /home/***/.local/lib/python3.7/site-packages/twisted/python/context.py:82:callWithContext
[2022-05-24 02:55:00,439] {subprocess.py:92} INFO - /home/***/.local/lib/python3.7/site-packages/twisted/enterprise/adbapi.py:440:_runInteraction
[2022-05-24 02:55:00,439] {subprocess.py:92} INFO - /home/***/.local/lib/python3.7/site-packages/twisted/enterprise/adbapi.py:34:__init__
[2022-05-24 02:55:00,439] {subprocess.py:92} INFO - /home/***/.local/lib/python3.7/site-packages/twisted/enterprise/adbapi.py:71:reconnect
[2022-05-24 02:55:00,439] {subprocess.py:92} INFO - /home/***/.local/lib/python3.7/site-packages/twisted/enterprise/adbapi.py:410:connect
[2022-05-24 02:55:00,439] {subprocess.py:92} INFO - /home/***/.local/lib/python3.7/site-packages/MySQLdb/__init__.py:123:Connect
[2022-05-24 02:55:00,439] {subprocess.py:92} INFO - /home/***/.local/lib/python3.7/site-packages/MySQLdb/connections.py:185:__init__
[2022-05-24 02:55:00,439] {subprocess.py:92} INFO - ]
[2022-05-24 02:55:00,439] {subprocess.py:92} INFO - 2022-05-24 02:55:00 [scrapy.core.scraper] DEBUG: Scraped from <200 https://www.traveloka.com/vi-vn/hotel/vietnam/region/ha-giang-province-10009852>
[2022-05-24 02:55:00,439] {subprocess.py:92} INFO - {'hotel_address': 'Phuong Thien, xã Phương Thiện, Thành phố Hà Giang, Hà '
[2022-05-24 02:55:00,439] {subprocess.py:92} INFO -                   'Giang, Việt Nam, 20000',
[2022-05-24 02:55:00,439] {subprocess.py:92} INFO -  'hotel_name': 'Hà Giang Hostel',
[2022-05-24 02:55:00,439] {subprocess.py:92} INFO -  'hotel_point_review': '7.6',
[2022-05-24 02:55:00,439] {subprocess.py:92} INFO -  'hotel_rating': '3',
[2022-05-24 02:55:00,439] {subprocess.py:92} INFO -  'hotel_sum_review': '9',
[2022-05-24 02:55:00,439] {subprocess.py:92} INFO -  'hotel_url': 'https://www.traveloka.com/vi-vn/hotel/vietnam/ha-giang-hostel-9000000553069'}
[2022-05-24 02:55:00,440] {subprocess.py:92} INFO - 2022-05-24 02:55:00 [scrapy.core.scraper] DEBUG: Scraped from <200 https://www.traveloka.com/vi-vn/hotel/vietnam/region/ha-giang-province-10009852>
[2022-05-24 02:55:00,441] {subprocess.py:92} INFO - {'hotel_address': '525 Nguyễn Trãi, phường Nguyễn Trãi, Thành phố Hà Giang, Hà '
[2022-05-24 02:55:00,441] {subprocess.py:92} INFO -                   'Giang, Việt Nam, 311001',
[2022-05-24 02:55:00,441] {subprocess.py:92} INFO -  'hotel_name': 'Nhà nghỉ Hương Trà 2',
[2022-05-24 02:55:00,441] {subprocess.py:92} INFO -  'hotel_point_review': '9.1',
[2022-05-24 02:55:00,441] {subprocess.py:92} INFO -  'hotel_rating': '1',
[2022-05-24 02:55:00,441] {subprocess.py:92} INFO -  'hotel_sum_review': '5',
[2022-05-24 02:55:00,441] {subprocess.py:92} INFO -  'hotel_url': 'https://www.traveloka.com/vi-vn/hotel/vietnam/huong-tra-guesthouse-1-3000010037412'}
[2022-05-24 02:55:00,443] {subprocess.py:92} INFO - 2022-05-24 02:55:00 [scrapy.core.scraper] DEBUG: Scraped from <200 https://www.traveloka.com/vi-vn/hotel/vietnam/region/ha-giang-province-10009852>
[2022-05-24 02:55:00,443] {subprocess.py:92} INFO - {'hotel_address': 'Tổ 7, Đồng Văn, thị trấn Đồng Văn, Đồng Văn, Hà Giang, Việt '
[2022-05-24 02:55:00,443] {subprocess.py:92} INFO -                   'Nam, 310000',
[2022-05-24 02:55:00,443] {subprocess.py:92} INFO -  'hotel_name': 'Tam Giac Mach Hotel',
[2022-05-24 02:55:00,443] {subprocess.py:92} INFO -  'hotel_point_review': '8.3',
[2022-05-24 02:55:00,443] {subprocess.py:92} INFO -  'hotel_rating': '1',
[2022-05-24 02:55:00,443] {subprocess.py:92} INFO -  'hotel_sum_review': '28',
[2022-05-24 02:55:00,444] {subprocess.py:92} INFO -  'hotel_url': 'https://www.traveloka.com/vi-vn/hotel/vietnam/tam-giac-mach-hotel-3000010036844'}
[2022-05-24 02:55:00,444] {subprocess.py:92} INFO - 2022-05-24 02:55:00 [scrapy.core.scraper] DEBUG: Scraped from <200 https://www.traveloka.com/vi-vn/hotel/vietnam/region/ha-giang-province-10009852>
[2022-05-24 02:55:00,445] {subprocess.py:92} INFO - {'hotel_address': '85 Minh Khai, phường Minh Khai, Thành phố Hà Giang, Hà '
[2022-05-24 02:55:00,445] {subprocess.py:92} INFO -                   'Giang, Việt Nam, 311021',
[2022-05-24 02:55:00,445] {subprocess.py:92} INFO -  'hotel_name': '10am Hostel',
[2022-05-24 02:55:00,445] {subprocess.py:92} INFO -  'hotel_point_review': '8.8',
[2022-05-24 02:55:00,445] {subprocess.py:92} INFO -  'hotel_rating': '1',
[2022-05-24 02:55:00,445] {subprocess.py:92} INFO -  'hotel_sum_review': '7',
[2022-05-24 02:55:00,445] {subprocess.py:92} INFO -  'hotel_url': 'https://www.traveloka.com/vi-vn/hotel/vietnam/10am-hostel-3000010037804'}
[2022-05-24 02:55:00,446] {subprocess.py:92} INFO - 2022-05-24 02:55:00 [scrapy.core.scraper] DEBUG: Scraped from <200 https://www.traveloka.com/vi-vn/hotel/vietnam/region/ha-giang-province-10009852>
[2022-05-24 02:55:00,446] {subprocess.py:92} INFO - {'hotel_address': '529A Nguyễn Văn Linh, phường Quang Trung, Thành phố Hà '
[2022-05-24 02:55:00,446] {subprocess.py:92} INFO -                   'Giang, Hà Giang, Việt Nam, 310000',
[2022-05-24 02:55:00,446] {subprocess.py:92} INFO -  'hotel_name': 'Green Hill Hostel',
[2022-05-24 02:55:00,446] {subprocess.py:92} INFO -  'hotel_point_review': '7.9',
[2022-05-24 02:55:00,447] {subprocess.py:92} INFO -  'hotel_rating': '2',
[2022-05-24 02:55:00,447] {subprocess.py:92} INFO -  'hotel_sum_review': '31',
[2022-05-24 02:55:00,447] {subprocess.py:92} INFO -  'hotel_url': 'https://www.traveloka.com/vi-vn/hotel/vietnam/green-hill-hostel-3000020006053'}
[2022-05-24 02:55:00,447] {subprocess.py:92} INFO - 2022-05-24 02:55:00 [root] ERROR: [Failure instance: Traceback: <class 'MySQLdb._exceptions.OperationalError'>: (2003, "Can't connect to MySQL server on '127.20.0.1:3306' (111)")
[2022-05-24 02:55:00,447] {subprocess.py:92} INFO - /usr/local/lib/python3.7/threading.py:926:_bootstrap_inner
[2022-05-24 02:55:00,447] {subprocess.py:92} INFO - /usr/local/lib/python3.7/threading.py:870:run
[2022-05-24 02:55:00,447] {subprocess.py:92} INFO - /home/***/.local/lib/python3.7/site-packages/twisted/_threads/_threadworker.py:47:work
[2022-05-24 02:55:00,447] {subprocess.py:92} INFO - /home/***/.local/lib/python3.7/site-packages/twisted/_threads/_team.py:182:doWork
[2022-05-24 02:55:00,447] {subprocess.py:92} INFO - --- <exception caught here> ---
[2022-05-24 02:55:00,447] {subprocess.py:92} INFO - /home/***/.local/lib/python3.7/site-packages/twisted/python/threadpool.py:244:inContext
[2022-05-24 02:55:00,448] {subprocess.py:92} INFO - /home/***/.local/lib/python3.7/site-packages/twisted/python/threadpool.py:261:<lambda>
[2022-05-24 02:55:00,448] {subprocess.py:92} INFO - /home/***/.local/lib/python3.7/site-packages/twisted/python/context.py:117:callWithContext
[2022-05-24 02:55:00,448] {subprocess.py:92} INFO - /home/***/.local/lib/python3.7/site-packages/twisted/python/context.py:82:callWithContext
[2022-05-24 02:55:00,448] {subprocess.py:92} INFO - /home/***/.local/lib/python3.7/site-packages/twisted/enterprise/adbapi.py:440:_runInteraction
[2022-05-24 02:55:00,448] {subprocess.py:92} INFO - /home/***/.local/lib/python3.7/site-packages/twisted/enterprise/adbapi.py:34:__init__
[2022-05-24 02:55:00,448] {subprocess.py:92} INFO - /home/***/.local/lib/python3.7/site-packages/twisted/enterprise/adbapi.py:71:reconnect
[2022-05-24 02:55:00,448] {subprocess.py:92} INFO - /home/***/.local/lib/python3.7/site-packages/twisted/enterprise/adbapi.py:410:connect
[2022-05-24 02:55:00,448] {subprocess.py:92} INFO - /home/***/.local/lib/python3.7/site-packages/MySQLdb/__init__.py:123:Connect
[2022-05-24 02:55:00,448] {subprocess.py:92} INFO - /home/***/.local/lib/python3.7/site-packages/MySQLdb/connections.py:185:__init__
[2022-05-24 02:55:00,448] {subprocess.py:92} INFO - ]
[2022-05-24 02:55:00,448] {subprocess.py:92} INFO - 2022-05-24 02:55:00 [root] ERROR: [Failure instance: Traceback: <class 'MySQLdb._exceptions.OperationalError'>: (2003, "Can't connect to MySQL server on '127.20.0.1:3306' (111)")
[2022-05-24 02:55:00,449] {subprocess.py:92} INFO - /usr/local/lib/python3.7/threading.py:926:_bootstrap_inner
[2022-05-24 02:55:00,449] {subprocess.py:92} INFO - /usr/local/lib/python3.7/threading.py:870:run
[2022-05-24 02:55:00,449] {subprocess.py:92} INFO - /home/***/.local/lib/python3.7/site-packages/twisted/_threads/_threadworker.py:47:work
[2022-05-24 02:55:00,449] {subprocess.py:92} INFO - /home/***/.local/lib/python3.7/site-packages/twisted/_threads/_team.py:182:doWork
[2022-05-24 02:55:00,449] {subprocess.py:92} INFO - --- <exception caught here> ---
[2022-05-24 02:55:00,449] {subprocess.py:92} INFO - /home/***/.local/lib/python3.7/site-packages/twisted/python/threadpool.py:244:inContext
[2022-05-24 02:55:00,449] {subprocess.py:92} INFO - /home/***/.local/lib/python3.7/site-packages/twisted/python/threadpool.py:261:<lambda>
[2022-05-24 02:55:00,449] {subprocess.py:92} INFO - /home/***/.local/lib/python3.7/site-packages/twisted/python/context.py:117:callWithContext
[2022-05-24 02:55:00,449] {subprocess.py:92} INFO - /home/***/.local/lib/python3.7/site-packages/twisted/python/context.py:82:callWithContext
[2022-05-24 02:55:00,449] {subprocess.py:92} INFO - /home/***/.local/lib/python3.7/site-packages/twisted/enterprise/adbapi.py:440:_runInteraction
[2022-05-24 02:55:00,449] {subprocess.py:92} INFO - /home/***/.local/lib/python3.7/site-packages/twisted/enterprise/adbapi.py:34:__init__
[2022-05-24 02:55:00,449] {subprocess.py:92} INFO - /home/***/.local/lib/python3.7/site-packages/twisted/enterprise/adbapi.py:71:reconnect
[2022-05-24 02:55:00,450] {subprocess.py:92} INFO - /home/***/.local/lib/python3.7/site-packages/twisted/enterprise/adbapi.py:410:connect
[2022-05-24 02:55:00,450] {subprocess.py:92} INFO - /home/***/.local/lib/python3.7/site-packages/MySQLdb/__init__.py:123:Connect
[2022-05-24 02:55:00,450] {subprocess.py:92} INFO - /home/***/.local/lib/python3.7/site-packages/MySQLdb/connections.py:185:__init__
[2022-05-24 02:55:00,450] {subprocess.py:92} INFO - ]
[2022-05-24 02:55:00,450] {subprocess.py:92} INFO - 2022-05-24 02:55:00 [scrapy.core.scraper] DEBUG: Scraped from <200 https://www.traveloka.com/vi-vn/hotel/vietnam/region/ha-giang-province-10009852>
[2022-05-24 02:55:00,450] {subprocess.py:92} INFO - {'hotel_address': '228 Ly Tu Trong Street, phường Trần Phú, Thành phố Hà '
[2022-05-24 02:55:00,450] {subprocess.py:92} INFO -                   'Giang, Hà Giang, Việt Nam, 70000',
[2022-05-24 02:55:00,450] {subprocess.py:92} INFO -  'hotel_name': 'Khách sạn Tam Giác Mạch - Hà Giang',
[2022-05-24 02:55:00,450] {subprocess.py:92} INFO -  'hotel_point_review': '9.0',
[2022-05-24 02:55:00,450] {subprocess.py:92} INFO -  'hotel_rating': '1',
[2022-05-24 02:55:00,450] {subprocess.py:92} INFO -  'hotel_sum_review': '6',
[2022-05-24 02:55:00,451] {subprocess.py:92} INFO -  'hotel_url': 'https://www.traveloka.com/vi-vn/hotel/vietnam/tam-giac-mach-hotel-ha-giang-3000010042023'}
[2022-05-24 02:55:00,451] {subprocess.py:92} INFO - 2022-05-24 02:55:00 [root] ERROR: [Failure instance: Traceback: <class 'MySQLdb._exceptions.OperationalError'>: (2003, "Can't connect to MySQL server on '127.20.0.1:3306' (111)")
[2022-05-24 02:55:00,451] {subprocess.py:92} INFO - /usr/local/lib/python3.7/threading.py:926:_bootstrap_inner
[2022-05-24 02:55:00,451] {subprocess.py:92} INFO - /usr/local/lib/python3.7/threading.py:870:run
[2022-05-24 02:55:00,452] {subprocess.py:92} INFO - /home/***/.local/lib/python3.7/site-packages/twisted/_threads/_threadworker.py:47:work
[2022-05-24 02:55:00,452] {subprocess.py:92} INFO - /home/***/.local/lib/python3.7/site-packages/twisted/_threads/_team.py:182:doWork
[2022-05-24 02:55:00,452] {subprocess.py:92} INFO - --- <exception caught here> ---
[2022-05-24 02:55:00,452] {subprocess.py:92} INFO - /home/***/.local/lib/python3.7/site-packages/twisted/python/threadpool.py:244:inContext
[2022-05-24 02:55:00,452] {subprocess.py:92} INFO - /home/***/.local/lib/python3.7/site-packages/twisted/python/threadpool.py:261:<lambda>
[2022-05-24 02:55:00,452] {subprocess.py:92} INFO - /home/***/.local/lib/python3.7/site-packages/twisted/python/context.py:117:callWithContext
[2022-05-24 02:55:00,452] {subprocess.py:92} INFO - /home/***/.local/lib/python3.7/site-packages/twisted/python/context.py:82:callWithContext
[2022-05-24 02:55:00,452] {subprocess.py:92} INFO - /home/***/.local/lib/python3.7/site-packages/twisted/enterprise/adbapi.py:440:_runInteraction
[2022-05-24 02:55:00,452] {subprocess.py:92} INFO - /home/***/.local/lib/python3.7/site-packages/twisted/enterprise/adbapi.py:34:__init__
[2022-05-24 02:55:00,452] {subprocess.py:92} INFO - /home/***/.local/lib/python3.7/site-packages/twisted/enterprise/adbapi.py:71:reconnect
[2022-05-24 02:55:00,452] {subprocess.py:92} INFO - /home/***/.local/lib/python3.7/site-packages/twisted/enterprise/adbapi.py:410:connect
[2022-05-24 02:55:00,452] {subprocess.py:92} INFO - /home/***/.local/lib/python3.7/site-packages/MySQLdb/__init__.py:123:Connect
[2022-05-24 02:55:00,452] {subprocess.py:92} INFO - /home/***/.local/lib/python3.7/site-packages/MySQLdb/connections.py:185:__init__
[2022-05-24 02:55:00,452] {subprocess.py:92} INFO - ]
[2022-05-24 02:55:00,453] {subprocess.py:92} INFO - 2022-05-24 02:55:00 [root] ERROR: [Failure instance: Traceback: <class 'MySQLdb._exceptions.OperationalError'>: (2003, "Can't connect to MySQL server on '127.20.0.1:3306' (111)")
[2022-05-24 02:55:00,453] {subprocess.py:92} INFO - /usr/local/lib/python3.7/threading.py:926:_bootstrap_inner
[2022-05-24 02:55:00,453] {subprocess.py:92} INFO - /usr/local/lib/python3.7/threading.py:870:run
[2022-05-24 02:55:00,453] {subprocess.py:92} INFO - /home/***/.local/lib/python3.7/site-packages/twisted/_threads/_threadworker.py:47:work
[2022-05-24 02:55:00,453] {subprocess.py:92} INFO - /home/***/.local/lib/python3.7/site-packages/twisted/_threads/_team.py:182:doWork
[2022-05-24 02:55:00,453] {subprocess.py:92} INFO - --- <exception caught here> ---
[2022-05-24 02:55:00,453] {subprocess.py:92} INFO - /home/***/.local/lib/python3.7/site-packages/twisted/python/threadpool.py:244:inContext
[2022-05-24 02:55:00,453] {subprocess.py:92} INFO - /home/***/.local/lib/python3.7/site-packages/twisted/python/threadpool.py:261:<lambda>
[2022-05-24 02:55:00,453] {subprocess.py:92} INFO - /home/***/.local/lib/python3.7/site-packages/twisted/python/context.py:117:callWithContext
[2022-05-24 02:55:00,453] {subprocess.py:92} INFO - /home/***/.local/lib/python3.7/site-packages/twisted/python/context.py:82:callWithContext
[2022-05-24 02:55:00,453] {subprocess.py:92} INFO - /home/***/.local/lib/python3.7/site-packages/twisted/enterprise/adbapi.py:440:_runInteraction
[2022-05-24 02:55:00,454] {subprocess.py:92} INFO - /home/***/.local/lib/python3.7/site-packages/twisted/enterprise/adbapi.py:34:__init__
[2022-05-24 02:55:00,454] {subprocess.py:92} INFO - /home/***/.local/lib/python3.7/site-packages/twisted/enterprise/adbapi.py:71:reconnect
[2022-05-24 02:55:00,454] {subprocess.py:92} INFO - /home/***/.local/lib/python3.7/site-packages/twisted/enterprise/adbapi.py:410:connect
[2022-05-24 02:55:00,454] {subprocess.py:92} INFO - /home/***/.local/lib/python3.7/site-packages/MySQLdb/__init__.py:123:Connect
[2022-05-24 02:55:00,454] {subprocess.py:92} INFO - /home/***/.local/lib/python3.7/site-packages/MySQLdb/connections.py:185:__init__
[2022-05-24 02:55:00,454] {subprocess.py:92} INFO - ]
[2022-05-24 02:55:00,454] {subprocess.py:92} INFO - 2022-05-24 02:55:00 [root] ERROR: [Failure instance: Traceback: <class 'MySQLdb._exceptions.OperationalError'>: (2003, "Can't connect to MySQL server on '127.20.0.1:3306' (111)")
[2022-05-24 02:55:00,454] {subprocess.py:92} INFO - /usr/local/lib/python3.7/threading.py:926:_bootstrap_inner
[2022-05-24 02:55:00,454] {subprocess.py:92} INFO - /usr/local/lib/python3.7/threading.py:870:run
[2022-05-24 02:55:00,454] {subprocess.py:92} INFO - /home/***/.local/lib/python3.7/site-packages/twisted/_threads/_threadworker.py:47:work
[2022-05-24 02:55:00,454] {subprocess.py:92} INFO - /home/***/.local/lib/python3.7/site-packages/twisted/_threads/_team.py:182:doWork
[2022-05-24 02:55:00,454] {subprocess.py:92} INFO - --- <exception caught here> ---
[2022-05-24 02:55:00,454] {subprocess.py:92} INFO - /home/***/.local/lib/python3.7/site-packages/twisted/python/threadpool.py:244:inContext
[2022-05-24 02:55:00,454] {subprocess.py:92} INFO - /home/***/.local/lib/python3.7/site-packages/twisted/python/threadpool.py:261:<lambda>
[2022-05-24 02:55:00,454] {subprocess.py:92} INFO - /home/***/.local/lib/python3.7/site-packages/twisted/python/context.py:117:callWithContext
[2022-05-24 02:55:00,454] {subprocess.py:92} INFO - /home/***/.local/lib/python3.7/site-packages/twisted/python/context.py:82:callWithContext
[2022-05-24 02:55:00,455] {subprocess.py:92} INFO - /home/***/.local/lib/python3.7/site-packages/twisted/enterprise/adbapi.py:440:_runInteraction
[2022-05-24 02:55:00,455] {subprocess.py:92} INFO - /home/***/.local/lib/python3.7/site-packages/twisted/enterprise/adbapi.py:34:__init__
[2022-05-24 02:55:00,455] {subprocess.py:92} INFO - /home/***/.local/lib/python3.7/site-packages/twisted/enterprise/adbapi.py:71:reconnect
[2022-05-24 02:55:00,455] {subprocess.py:92} INFO - /home/***/.local/lib/python3.7/site-packages/twisted/enterprise/adbapi.py:410:connect
[2022-05-24 02:55:00,455] {subprocess.py:92} INFO - /home/***/.local/lib/python3.7/site-packages/MySQLdb/__init__.py:123:Connect
[2022-05-24 02:55:00,455] {subprocess.py:92} INFO - /home/***/.local/lib/python3.7/site-packages/MySQLdb/connections.py:185:__init__
[2022-05-24 02:55:00,455] {subprocess.py:92} INFO - ]
[2022-05-24 02:55:00,455] {subprocess.py:92} INFO - 2022-05-24 02:55:00 [root] ERROR: [Failure instance: Traceback: <class 'MySQLdb._exceptions.OperationalError'>: (2003, "Can't connect to MySQL server on '127.20.0.1:3306' (111)")
[2022-05-24 02:55:00,455] {subprocess.py:92} INFO - /usr/local/lib/python3.7/threading.py:926:_bootstrap_inner
[2022-05-24 02:55:00,455] {subprocess.py:92} INFO - /usr/local/lib/python3.7/threading.py:870:run
[2022-05-24 02:55:00,455] {subprocess.py:92} INFO - /home/***/.local/lib/python3.7/site-packages/twisted/_threads/_threadworker.py:47:work
[2022-05-24 02:55:00,455] {subprocess.py:92} INFO - /home/***/.local/lib/python3.7/site-packages/twisted/_threads/_team.py:182:doWork
[2022-05-24 02:55:00,455] {subprocess.py:92} INFO - --- <exception caught here> ---
[2022-05-24 02:55:00,455] {subprocess.py:92} INFO - /home/***/.local/lib/python3.7/site-packages/twisted/python/threadpool.py:244:inContext
[2022-05-24 02:55:00,456] {subprocess.py:92} INFO - /home/***/.local/lib/python3.7/site-packages/twisted/python/threadpool.py:261:<lambda>
[2022-05-24 02:55:00,456] {subprocess.py:92} INFO - /home/***/.local/lib/python3.7/site-packages/twisted/python/context.py:117:callWithContext
[2022-05-24 02:55:00,456] {subprocess.py:92} INFO - /home/***/.local/lib/python3.7/site-packages/twisted/python/context.py:82:callWithContext
[2022-05-24 02:55:00,456] {subprocess.py:92} INFO - /home/***/.local/lib/python3.7/site-packages/twisted/enterprise/adbapi.py:440:_runInteraction
[2022-05-24 02:55:00,456] {subprocess.py:92} INFO - /home/***/.local/lib/python3.7/site-packages/twisted/enterprise/adbapi.py:34:__init__
[2022-05-24 02:55:00,456] {subprocess.py:92} INFO - /home/***/.local/lib/python3.7/site-packages/twisted/enterprise/adbapi.py:71:reconnect
[2022-05-24 02:55:00,456] {subprocess.py:92} INFO - /home/***/.local/lib/python3.7/site-packages/twisted/enterprise/adbapi.py:410:connect
[2022-05-24 02:55:00,456] {subprocess.py:92} INFO - /home/***/.local/lib/python3.7/site-packages/MySQLdb/__init__.py:123:Connect
[2022-05-24 02:55:00,456] {subprocess.py:92} INFO - /home/***/.local/lib/python3.7/site-packages/MySQLdb/connections.py:185:__init__
[2022-05-24 02:55:00,456] {subprocess.py:92} INFO - ]
[2022-05-24 02:55:05,291] {subprocess.py:92} INFO - 2022-05-24 02:55:05 [scrapy.core.engine] DEBUG: Crawled (200) <GET https://www.traveloka.com/vi-vn/hotel/vietnam/city/quang-dien-10010568> (referer: https://www.traveloka.com/vi-vn/hotel/vietnam/city/hue-city-10010311)
[2022-05-24 02:55:11,404] {subprocess.py:92} INFO - 2022-05-24 02:55:11 [scrapy.core.engine] DEBUG: Crawled (200) <GET https://www.traveloka.com/vi-vn/hotel/vietnam/city/tay-son-district-10010656> (referer: https://www.traveloka.com/vi-vn/hotel/vietnam/city/quy-nhon-city-10009975)
[2022-05-24 02:55:14,809] {subprocess.py:92} INFO - 2022-05-24 02:55:14 [scrapy.core.engine] DEBUG: Crawled (200) <GET https://www.traveloka.com/vi-vn/hotel/vietnam/city/hoi-an-10010308> (referer: https://www.traveloka.com/vi-vn/hotel)
[2022-05-24 02:55:15,477] {local_task_job.py:221} WARNING - State of this instance has been externally set to None. Terminating instance.
[2022-05-24 02:55:15,483] {process_utils.py:129} INFO - Sending Signals.SIGTERM to group 175. PIDs of all processes in the group: [176, 175]
[2022-05-24 02:55:15,483] {process_utils.py:80} INFO - Sending the signal Signals.SIGTERM to group 175
[2022-05-24 02:55:15,484] {taskinstance.py:1541} ERROR - Received SIGTERM. Terminating subprocesses.
[2022-05-24 02:55:15,484] {subprocess.py:103} INFO - Sending SIGTERM signal to process group
[2022-05-24 02:55:15,506] {taskinstance.py:1889} ERROR - Task failed with exception
Traceback (most recent call last):
  File "/home/airflow/.local/lib/python3.7/site-packages/airflow/operators/bash.py", line 189, in execute
    cwd=self.cwd,
  File "/home/airflow/.local/lib/python3.7/site-packages/airflow/hooks/subprocess.py", line 90, in run_command
    for raw_line in iter(self.sub_process.stdout.readline, b''):
  File "/home/airflow/.local/lib/python3.7/site-packages/airflow/models/taskinstance.py", line 1543, in signal_handler
    raise AirflowException("Task received SIGTERM signal")
airflow.exceptions.AirflowException: Task received SIGTERM signal
[2022-05-24 02:55:15,512] {taskinstance.py:1400} INFO - Marking task as FAILED. dag_id=TRAVELOKA_V1, task_id=crawl_data, execution_date=20220524T025208, start_date=20220524T025217, end_date=20220524T025515
[2022-05-24 02:55:15,710] {standard_task_runner.py:97} ERROR - Failed to execute job 49 for task crawl_data ((psycopg2.errors.ForeignKeyViolation) insert or update on table "task_fail" violates foreign key constraint "task_fail_ti_fkey"
DETAIL:  Key (dag_id, task_id, run_id, map_index)=(TRAVELOKA_V1, crawl_data, manual__2022-05-24T02:52:08.173537+00:00, -1) is not present in table "task_instance".

[SQL: INSERT INTO task_fail (task_id, dag_id, run_id, map_index, start_date, end_date, duration) VALUES (%(task_id)s, %(dag_id)s, %(run_id)s, %(map_index)s, %(start_date)s, %(end_date)s, %(duration)s) RETURNING task_fail.id]
[parameters: {'task_id': 'crawl_data', 'dag_id': 'TRAVELOKA_V1', 'run_id': 'manual__2022-05-24T02:52:08.173537+00:00', 'map_index': -1, 'start_date': datetime.datetime(2022, 5, 24, 2, 52, 17, 54441, tzinfo=Timezone('UTC')), 'end_date': datetime.datetime(2022, 5, 24, 2, 55, 15, 512129, tzinfo=Timezone('UTC')), 'duration': 178}]
(Background on this error at: http://sqlalche.me/e/14/gkpj); 175)
[2022-05-24 02:55:16,018] {process_utils.py:75} INFO - Process psutil.Process(pid=175, status='terminated', exitcode=1, started='02:52:17') (175) terminated with exit code 1
[2022-05-24 02:56:15,512] {process_utils.py:143} WARNING - process psutil.Process(pid=176, name='scrapy', status='sleeping', started='02:52:23') did not respond to SIGTERM. Trying SIGKILL
[2022-05-24 02:56:15,513] {process_utils.py:80} INFO - Sending the signal Signals.SIGKILL to group 175
[2022-05-24 02:56:15,514] {process_utils.py:95} INFO - Sending the signal Signals.SIGKILL to process 175 as process group is missing.
